Workbook

Sheet 首页
C4: NGFW V6R01C01 日志中心特性测试用例
C15: 拟定 | D15: 赵海波 | F15: 日期 | G15: 45575
C17: 审核 | F17: 日期 | G17: XXXX/XX/XX
C19: 批准 | F19: 日期
E23: 修订记录
C25: 日期 | D25: 修订版本 | E25: 修改记录 | I25: 修改人
C26: 44764 | D26: V1.0 | E26: 初稿输出 | I26: 赵海波

Sheet 测试点分析
A1: 四级目录 | B1: 五级目录 | C1: 测试点 | D1: 测试设计方法 | E1: 适用场景 | F1: 用例规模（个） | G1: 测试数据
A2: 配置管理
B3: 日志服务器配置
B4: 日志过滤配置
B5: 日志备份配置
B6: 日志归并配置
B7: 调试日志配置
B8: 信息收集配置
B9: 异常信息导出配置
B10: 防火墙日志管理配置
A11: 日志管理
B12: 防火墙日志
C13: 验证日志查询功能 | D13: 等价类划分&数据组合 | F13: 17 | G13: 1、系统日志、操作日志、入侵防御日志、防病毒日志、内容过滤日志、文件过滤日志、URL过滤日志、WEB防护日志、防暴力破解日志、弱密码日志、控制策略阻断日志、单包防护日志、Flood攻击日志、黑白名单日志、EDR推广日志、IPSecVPN日志的模糊查询和高级查询功能（清除条件、刷新）
C14: 验证日志高级精确过滤功能 | D14: 等价类划分&数据组合 | F14: 17 | G14: 1、系统日志、操作日志、入侵防御日志、防病毒日志、内容过滤日志、文件过滤日志、URL过滤日志、WEB防护日志、防暴力破解日志、弱密码日志、控制策略阻断日志、单包防护日志、Flood攻击日志、黑白名单日志、EDR推广日志、IPSecVPN日志的模糊查询和高级查询功能（清除条件、刷新）
C15: 验证日志查询模糊过滤功能 | D15: 等价类划分&数据组合 | F15: 17 | G15: 1、系统日志、操作日志、入侵防御日志、防病毒日志、内容过滤日志、文件过滤日志、URL过滤日志、WEB防护日志、防暴力破解日志、弱密码日志、控制策略阻断日志、单包防护日志、Flood攻击日志、黑白名单日志、EDR推广日志、IPSecVPN日志的模糊查询和高级查询功能（清除条件、刷新）
C16: 日志查询时间测试 | D16: 等价类划分&数据组合 | F16: 2 | G16: 时间,修改系统时间
C17: 日志管理功能 | D17: 直接分析 | F17: 16 | G17: 日志清除
B18: 日志归并
C19: 日志归并功能测试 | D19: 直接分析 | F19: 9 | G19: 日志归并开启（入侵防御、防病毒、内容过滤、文件过滤、URL过滤、Web防护、防暴力破解、弱密码）、关闭。
C20: 日志归并周期测试 | D20: 等价类划分&数据组合 | F20: 3 | G20: 最大值，最小值，典型值
C21: 验证多种日志的归并相互不影响 | D21: 直接分析 | F21: 1
C22: 日志归并是修改配置测试 | D22: 直接分析 | F22: 1
B23: 日志清理
C24: 日志容量清理功能 | D24: 直接分析 | F24: 16 | G24: 系统日志、操作日志、入侵防御日志、防病毒日志、内容过滤日志、文件过滤日志、URL过滤日志、WEB防护日志、防暴力破解日志、弱密码日志、控制策略阻断日志、单包防护日志、Flood攻击日志、黑白名单日志、EDR推广日志、IPSecVPN日志
C25: 日志清除功能 | D25: 直接分析 | F25: 16 | G25: 支持的日志：系统日志、入侵防御日志、防病毒日志、内容过滤日志、文件过滤日志、URL过滤日志、WEB防护日志、防暴力破解日志、弱密码日志、控制策略阻断日志、单包防护日志、Flood攻击日志、黑白名单日志、EDR推广日志、IPSecVPN日志 不支持的日志:操作日志
C26: 日志容量清理时的归并功能测试 | D26: 直接分析 | F26: 1 | G26: 不需要设计用例，没有影响
B27: 日志备份
C28: 日志备份文件前端管理功能 | D28: 直接分析 | F28: 3 | G28: 前端查看，条件筛选、下载
C29: 日志备份文件后台管理功能 | D29: 直接分析 | F29: 2 | G29: 有盘设备、无盘设备
C30: 日志自动备份功能测试 | D30: 直接分析 | F30: 2 | G30: 有备份文件，无备份文件 系统日志、操作日志、入侵防御日志、防病毒日志、内容过滤日志、文件过滤日志、URL过滤日志、WEB防护日志、防暴力破解日志、弱密码日志、控制策略阻断日志、单包防护日志、Flood攻击日志、黑白名单日志、EDR推广日志、IPSecVPN日志按天备份功能和超规格备份功能，观察备份文件名称和时间
C31: 日志超规格备份功能测试 | D31: 直接分析 | F31: 17 | G31: 有备份文件，无备份文件？ 系统日志、操作日志、入侵防御日志、防病毒日志、内容过滤日志、文件过滤日志、URL过滤日志、WEB防护日志、防暴力破解日志、弱密码日志、控制策略阻断日志、单包防护日志、Flood攻击日志、黑白名单日志、EDR推广日志、IPSecVPN日志按天备份功能和超规格备份功能，观察备份文件名称和时间
C32: 日志备份文件清理功能测试 | D32: 直接分析 | F32: 3 | G32: 备份周期（最大值、最小值、典型值）、备份周内的文件不删除，超过周期的文件会删除
C33: 日志备份周期修改测试 | D33: 直接分析 | F33: 1 | G33: 备份周期凌晨2点生效测试
C34: 日志归并时的日志备份测试 | D34: 直接分析 | F34: 1
C35: 日志清理后的日志备份测试 | D35: 直接分析 | F35: 1
C36: 磁盘空间满时的日志备份测试 | D36: 直接分析 | F36: 1
B37: 日志导入导出
C38: 日志导出功能测试 | D38: 直接分析 | F38: 16 | G38: 系统日志、操作日志、入侵防御日志、防病毒日志、内容过滤日志、文件过滤日志、URL过滤日志、WEB防护日志、防暴力破解日志、弱密码日志、控制策略阻断日志、单包防护日志、Flood攻击日志、黑白名单日志、EDR推广日志、IPSecVPN日志导出日志的字段正确，文件名称正确
C39: 最大数量的日志导出功能测试 | D39: 直接分析 | F39: 1
C40: 修改系统时间对日志导出的影响 | D40: 直接分析 | F40: 1
...

Sheet 测试组网设计
A1: 名称 | B1: NE1_link0
A2: 组网图
A23: 名称 | B23: NE1_ins
A24: 组网图
A45: 名称 | B45: NE1_link4_ins
A46: 组网图
A67: 名称 | B67: NE4_link5_ins
A68: 组网图

Sheet 防火墙日志管理
A1: 测试点汇总 | B1: 测试点 | C1: 测试设计方法 | D1: 适用场景 | E1: 用例规模（个） | F1: 测试数据
B2: 验证日志查询功能 | C2: 等价类划分&数据组合 | E2: 17 | F2: 1、系统日志、操作日志、入侵防御日志、防病毒日志、内容过滤日志、文件过滤日志、URL过滤日志、WEB防护日志、防暴力破解日志、弱密码日志、控制策略阻断日志、单包防护日志、Flood攻击日志、黑白名单日志、EDR推广日志、IPSecVPN日志的模糊查询和高级查询功能（清除条件、刷新）
B3: 验证日志高级精确过滤功能 | C3: 等价类划分&数据组合 | E3: 17 | F3: 1、系统日志、操作日志、入侵防御日志、防病毒日志、内容过滤日志、文件过滤日志、URL过滤日志、WEB防护日志、防暴力破解日志、弱密码日志、控制策略阻断日志、单包防护日志、Flood攻击日志、黑白名单日志、EDR推广日志、IPSecVPN日志的模糊查询和高级查询功能（清除条件、刷新）
B4: 验证日志查询模糊过滤功能 | C4: 等价类划分&数据组合 | E4: 17 | F4: 1、系统日志、操作日志、入侵防御日志、防病毒日志、内容过滤日志、文件过滤日志、URL过滤日志、WEB防护日志、防暴力破解日志、弱密码日志、控制策略阻断日志、单包防护日志、Flood攻击日志、黑白名单日志、EDR推广日志、IPSecVPN日志的模糊查询和高级查询功能（清除条件、刷新）
B5: 日志查询时间测试 | C5: 直接分析 | E5: 2 | F5: 时间,修改系统时间
B6: 日志清理功能 | C6: 直接分析 | E6: 16 | F6: 日志清除（放到日志清理中）
A7: 验证日志查询功能 | B7: 【设计方法】等价类划分&数据组合
B8: 步骤1:等价类划分
B9: 等价类划分 | C9: 测试数据 | D9: 有效类 | E9: 无效类 | F9: 选取策略 | G9: 选取结果
C10: 系统日志 | D10: 时间 | F10: 数据名称和分类独立 | G10: 数据名称=系统日志;有效值=时间,日志级别,日志描述
D11: 日志级别
D12: 日志描述
C13: 操作日志 | D13: 时间 | F13: 数据名称和分类独立 | G13: 数据名称=操作日志;有效值=时间,日志级别,管理员,管理员角色,管理员IP,日志描述
D14: 日志级别
D15: 管理员
D16: 管理员角色
D17: 管理员IP
D18: 日志描述
C19: 入侵防御日志 | D19: 时间 | F19: 数据名称和分类独立 | G19: 数据名称=入侵防御日志;有效值=时间,日志级别,源地址,源端口,目的地址,目的端口,协议,策略ID,规则名称,规则类型,攻击次数,命中配置,告警周期,动作
D20: 日志级别
D21: 源地址
D22: 源端口
D23: 目的地址
D24: 目的端口
D25: 协议
D26: 策略ID
D27: 规则名称
D28: 规则类型
D29: 攻击次数
D30: 命中配置
D31: 告警周期
D32: 动作
C33: 防病毒日志 | D33: 时间 | F33: 数据名称和分类独立 | G33: 数据名称=防病毒日志;有效值=时间,日志级别,源地址,源端口,目的地址,目的端口,协议,策略ID,攻击次数,应用类型,文件名,文件大小,病毒类型,动作,来源
D34: 日志级别
D35: 源地址
D36: 源端口
D37: 目的地址
D38: 目的端口
D39: 协议
D40: 策略ID
...

Sheet 日志归并
A1: 测试点汇总 | B1: 测试点 | C1: 测试设计方法 | D1: 适用场景 | E1: 用例规模（个） | F1: 测试数据
B2: 日志归并功能测试 | C2: 等价类划分&数据组合 | E2: 9 | F2: 日志归并开启（入侵防御、防病毒、内容过滤、文件过滤、URL过滤、Web防护、防暴力破解、弱密码）、关闭。
B3: 日志归并周期测试 | C3: 等价类划分&数据组合 | E3: 3 | F3: 最大值，最小值，典型值
B4: 修改系统时间后的日志归并 | C4: 直接分析 | E4: 1 | F4: 入侵防御日志,防病毒日志,内容过滤日志,URL过滤日志,文件过滤日志,WEB防护日志,弱密码日志,防暴力破解日志,单包防护日志,Flood攻击日志
B5: 多种日志的归并相互不影响 | C5: 直接分析 | E5: 1 | F5: 入侵防御日志,防病毒日志,内容过滤日志,URL过滤日志,文件过滤日志,WEB防护日志,弱密码日志,防暴力破解日志,单包防护日志,Flood攻击日志
B6: 日志归并开关关闭功能 | C6: 直接分析 | E6: 1 | F6: 入侵防御日志,防病毒日志,内容过滤日志,URL过滤日志,文件过滤日志,WEB防护日志,弱密码日志,防暴力破解日志,单包防护日志,Flood攻击日志
B7: 日志归并是修改配置疲劳测试 | C7: 直接分析 | E7: 1 | F7: 反复修改
A8: 验证日志查询功能 | B8: 【设计方法】等价类划分&数据组合
B9: 步骤1:等价类划分
B10: 等价类划分 | C10: 测试数据 | D10: 有效类 | E10: 无效类 | F10: 选取策略 | G10: 选取结果
C11: 日志类型 | D11: 入侵防御日志 | F11: 数据名称和分类合并 | G11: 有效日志类型=入侵防御日志,防病毒日志,内容过滤日志,URL过滤日志,文件过滤日志,WEB防护日志,弱密码日志,防暴力破解日志,单包防护日志,Flood攻击日志
D12: 防病毒日志
D13: 内容过滤日志
D14: URL过滤日志
D15: 文件过滤日志
D16: WEB防护日志
D17: 弱密码日志
D18: 防暴力破解日志
D19: 单包防护日志
D20: Flood攻击日志
B21: 步骤2:数据组合
B22: 数据组合 | C22: 测试数据 | D22: 数据取值 | E22: 组合数据分析 | F22: 约束条件和组合策略 | G22: 组合结果
C23: 所有数据不组合 | D23: 每种日志一个用例
B24: 步骤3:逻辑用例设计
B25: 逻辑用例编号 | C25: 测试用例描述 | F25: 覆盖的测试数据 | G25: 测试数据选取结果
B26: log.logmng.merge | C26: 验证${有效日志类型}写入时的日志归并功能 | F26: 数据名称 | G26: 有效日志类型=入侵防御日志,防病毒日志,内容过滤日志,URL过滤日志,文件过滤日志,WEB防护日志,弱密码日志,防暴力破解日志,单包防护日志,Flood攻击日志
B27: 步骤4:物理用例设计
B28: 逻辑用例编号 | C28: 用例标题 | D28: 测试数据 | E28: 预置条件 | F28: 测试步骤 | G28: 预期结果 | H28: 优先级 | I28: 测试类型 | J28: 自动化
B29: log.logmng.merge | C29: 验证${有效日志类型}写入时的日志归并功能 | D29: 有效日志类型=入侵防御日志,防病毒日志,内容过滤日志,URL过滤日志,文件过滤日志,WEB防护日志,弱密码日志,防暴力破解日志,单包防护日志,Flood攻击日志 | E29: 1、网元正常启动 | F29: 1、开启日志归并，配置日志归并时间为10~60之间的随机值t秒 2、清空${有效日志类型}，并查询日志。【check1】 3、在t秒时间内向防火墙的日志侦听端口写入2~200之间任意值n条${有效日志类型}，日志除了时间其他内容完全相同 4、使用接口查询${有效日志类型}【check2】 | G29: 1、【check1】查询到的日志为空 2、【check2】仅查询到1条${有效日志类型}，该日志的攻击次数或者出现次数为n | H29: P2 | I29: 功能测试 | J29: 待实现
A30: 日志归并周期测试 | B30: 【设计方法】等价类划分&数据组合
B31: 步骤1:等价类划分
B32: 等价类划分 | C32: 测试数据 | D32: 有效类 | E32: 无效类 | F32: 选取策略 | G32: 选取结果
C33: 日志类型 | D33: 入侵防御日志 | F33: 数据名称和分类合并 | G33: 有效日志类型=入侵防御日志,防病毒日志,内容过滤日志,URL过滤日志,文件过滤日志,WEB防护日志,弱密码日志,防暴力破解日志,单包防护日志,Flood攻击日志
D34: 防病毒日志
D35: 内容过滤日志
D36: URL过滤日志
D37: 文件过滤日志
D38: WEB防护日志
D39: 弱密码日志
D40: 防暴力破解日志
...

Sheet 日志清理
A1: 测试点汇总 | B1: 测试点 | C1: 测试设计方法 | D1: 适用场景 | E1: 用例规模（个） | F1: 测试数据
B2: 日志容量清理功能 | C2: 等价类划分&数据组合 | E2: 16 | F2: 系统日志、操作日志、入侵防御日志、防病毒日志、内容过滤日志、文件过滤日志、URL过滤日志、WEB防护日志、防暴力破解日志、弱密码日志、控制策略阻断日志、单包防护日志、Flood攻击日志、黑白名单日志、EDR推广日志、IPSecVPN日志
B3: 日志清除功能 | C3: 直接分析 | E3: 16 | F3: /deletelog?logtype=filefilterlog,operationlog,systemlog 支持的日志：系统日志、入侵防御日志、防病毒日志、内容过滤日志、文件过滤日志、URL过滤日志、WEB防护日志、防暴力破解日志、弱密码日志、控制策略阻断日志、单包防护日志、Flood攻击日志、黑白名单日志、EDR推广日志、IPSecVPN日志 不支持的日志:操作日志
B4: 日志容量清理时的归并功能测试 | C4: 直接分析 | E4: 1 | F4: 不需要设计用例，没有影响
A5: 日志容量清理功能 | B5: 【设计方法】等价类划分&数据组合
B6: 步骤1:等价类划分
B7: 等价类划分 | C7: 测试数据 | D7: 有效类 | E7: 无效类 | F7: 选取策略 | G7: 选取结果
C8: 日志类型 | D8: 系统日志 | F8: 数据名称和分类合并 | G8: 有效日志类型=系统日志,操作日志,入侵防御日志,防病毒日志,内容过滤日志,文件过滤日志,URL过滤日志,WEB防护日志,防暴力破解日志,弱密码日志,控制策略阻断日志,本地控制策略日志,单包防护日志,Flood攻击日志,黑白名单日志,EDR推广日志,IPSecVPN日志
D9: 操作日志
D10: 入侵防御日志
D11: 防病毒日志
D12: 内容过滤日志
D13: 文件过滤日志
D14: URL过滤日志
D15: WEB防护日志
D16: 防暴力破解日志
D17: 弱密码日志
D18: 控制策略阻断日志
D19: 本地控制策略日志
D20: 单包防护日志
... D24: IPSecVPN日志
C25: 清理动作 | D25: 清理日志 | F25: 数据名称和分类合并
D26: 清理且备份日志
D27: 清理且追加日志
B28: 步骤2:数据组合
B29: 数据组合 | C29: 测试数据 | D29: 数据取值 | E29: 组合数据分析 | F29: 约束条件和组合策略 | G29: 组合结果
C30: 日志类型 | D30: 系统日志 | E30: 清理日志 | F30: 日志类型与清理动作交叉覆盖 | G30: 日志类型=系统日志;清理动作=清理日志 日志类型=防病毒日志;清理动作=清理日志 日志类型=URL过滤日志;清理动作=清理日志 日志类型=弱密码日志;清理动作=清理日志 日志类型=单包防护日志;清理动作=清理日志 日志类型=EDR推广日志;清理动作=清理日志 日志类型=操作日志;清理动作=清理且备份日志 日志类型=内容过滤日志;清理动作=清理且备份日志 日志类型=WEB防护日志;清理动作=清理且备份日志 日志类型=Flood攻击日志;清理动作=清理且备份日志 日志类型=控制策略阻断日志;清理动作=清理且备份日志 日志类型=IPSecVPN日志;清理动作=清理且备份日志 日志类型=入侵防御日志;清理动作=清理且追加日志 日志类型=文件过滤日志;清理动作=清理且追加日志 日志类型=防暴力破解日志;清理动作=清理且追加日志 日志类型=本地控制策略日志;清理动作=清理且追加日志 日志类型=黑白名单日志;清理动作=清理且追加日志
D31: 操作日志 | E31: 清理且备份日志
D32: 入侵防御日志 | E32: 清理日志
D33: 防病毒日志 | E33: 清理且备份日志
D34: 内容过滤日志 | E34: 清理且追加日志
D35: 文件过滤日志 | E35: 清理日志
D36: URL过滤日志 | E36: 清理且备份日志
D37: WEB防护日志 | E37: 清理且追加日志
D38: 防暴力破解日志 | E38: 清理日志
D39: 弱密码日志 | E39: 清理且备份日志
D40: 控制策略阻断日志 | E40: 清理且追加日志
D41: 本地控制策略日志 | E41: 清理日志
D42: 单包防护日志 | E42: 清理且备份日志
... D46: IPSecVPN日志 | E46: 清理且追加日志
...

Sheet 日志备份
A1: 测试点汇总 | B1: 测试点 | C1: 测试设计方法 | D1: 适用场景 | E1: 用例规模（个） | F1: 测试数据
B3: 日志自动备份功能测试 | C3: 等价类划分&数据组合 | E3: 17 | F3: 有备份文件，无备份文件 系统日志、操作日志、入侵防御日志、防病毒日志、内容过滤日志、文件过滤日志、URL过滤日志、WEB防护日志、防暴力破解日志、弱密码日志、控制策略阻断日志、单包防护日志、Flood攻击日志、黑白名单日志、EDR推广日志、IPSecVPN日志按天备份功能和超规格备份功能，观察备份文件名称和时间
B4: 日志备份支持设备形态测试 | C4: 直接分析 | E4: 2 | F4: 有盘设备、无盘设备
B5: 日志超规格备份功能测试 | C5: 直接分析 | E5: 17 | F5: 有备份文件，无备份文件？在日志超规格清理已设计 系统日志、操作日志、入侵防御日志、防病毒日志、内容过滤日志、文件过滤日志、URL过滤日志、WEB防护日志、防暴力破解日志、弱密码日志、控制策略阻断日志、单包防护日志、Flood攻击日志、黑白名单日志、EDR推广日志、IPSecVPN日志按天备份功能和超规格备份功能，观察备份文件名称和时间
B6: 日志备份文件管理 | C6: 直接分析 | E6: 1
B7: 日志备份有效期测试 | C7: 直接分析 | E7: 3 | F7: 备份周期（最大值、最小值、典型值）、备份周内的文件不删除，超过周期的文件会删除
B8: 日志备份周期修改测试 | C8: 直接分析 | E8: 1 | F8: 备份周期凌晨2点生效测试在日志自动备份中已覆盖
B9: 日志归并时的日志备份测试 | C9: 直接分析 | E9: 1 | F9: 不需要测试
B10: 日志清理后的日志备份测试 | C10: 直接分析 | E10: 1 | F10: 不需要测试
B11: 最大数量的日志备份功能 | C11: 直接分析 | E11: 1
B12: 磁盘空间满时的日志备份测试 | C12: 直接分析 | E12: 1
A13: 日志自动备份功能测试 | B13: 【设计方法】等价类划分&数据组合
B14: 步骤1:等价类划分
B15: 等价类划分 | C15: 测试数据 | D15: 有效类 | E15: 无效类 | F15: 选取策略 | G15: 选取结果
C16: 日志类型 | D16: 系统日志 | F16: 数据名称和分类合并 | G16: 有效日志类型=系统日志,操作日志,入侵防御日志,防病毒日志,内容过滤日志,文件过滤日志,URL过滤日志,WEB防护日志,防暴力破解日志,弱密码日志,控制策略阻断日志,本地控制策略日志,单包防护日志,Flood攻击日志,黑白名单日志,EDR推广日志,IPSecVPN日志
D17: 操作日志
D18: 入侵防御日志
D19: 防病毒日志
D20: 内容过滤日志
D21: 文件过滤日志
D22: URL过滤日志
D23: WEB防护日志
D24: 防暴力破解日志
D25: 弱密码日志
D26: 控制策略阻断日志
D27: 本地控制策略日志
D28: 单包防护日志
... D32: IPSecVPN日志
C33: 清理动作 | D33: 追加 | F33: 数据名称和分类合并 | G33: 有效清理动作=追加,备份
D34: 备份
B35: 步骤2:数据组合
B36: 数据组合 | C36: 测试数据 | D36: 数据取值 | E36: 组合数据分析 | F36: 约束条件和组合策略 | G36: 组合结果
C37: 日志类型 | D37: 系统日志 | F37: 日志类型与清理动作交叉覆盖 | G37: 日志类型=系统日志;动作=追加 日志类型=入侵防御日志;动作=追加 日志类型=内容过滤日志;动作=追加 日志类型=URL过滤日志;动作=追加 日志类型=防暴力破解日志;动作=追加 日志类型=控制策略阻断日志;动作=追加 日志类型=单包防护日志;动作=追加 日志类型=黑白名单日志;动作=追加 日志类型=IPSecVPN日志;动作=追加
D38: 操作日志
D39: 入侵防御日志
D40: 防病毒日志
D41: 内容过滤日志
D42: 文件过滤日志
D43: URL过滤日志
D44: WEB防护日志
...

Sheet 日志导入导出
A1: 测试点汇总 | B1: 测试点 | C1: 测试设计方法 | D1: 适用场景 | E1: 用例规模（个） | F1: 测试数据
B3: 日志导出功能测试 | C3: 直接分析 | E3: 16 | F3: 系统日志、操作日志、入侵防御日志、防病毒日志、内容过滤日志、文件过滤日志、URL过滤日志、WEB防护日志、防暴力破解日志、弱密码日志、控制策略阻断日志、单包防护日志、Flood攻击日志、黑白名单日志、EDR推广日志、IPSecVPN日志导出日志的字段正确，文件名称正确
B4: 最大数量的日志导出功能测试 | C4: 直接分析 | E4: 1
B5: 日志导出时间测试 | C5: 直接分析 | E5: 6 | F5: 近1小时,近24小时,近一周,近一月，自定义，修改系统时间
A6: 日志导出功能测试 | B6: 【设计方法】等价类划分&数据组合
B7: 步骤1:等价类划分
B8: 等价类划分 | C8: 测试数据 | D8: 有效类 | E8: 无效类 | F8: 选取策略 | G8: 选取结果
C9: 日志类型 | D9: 系统日志 | F9: 数据名称和分类合并 | G9: 有效日志类型=系统日志,操作日志,入侵防御日志,防病毒日志,内容过滤日志,文件过滤日志,URL过滤日志,WEB防护日志,防暴力破解日志,弱密码日志,控制策略阻断日志,本地控制策略日志,单包防护日志,Flood攻击日志,黑白名单日志,EDR推广日志,IPSecVPN日志
D10: 操作日志
D11: 入侵防御日志
D12: 防病毒日志
D13: 内容过滤日志
D14: 文件过滤日志
D15: URL过滤日志
D16: WEB防护日志
D17: 防暴力破解日志
D18: 弱密码日志
D19: 控制策略阻断日志
D20: 本地控制策略日志
D21: 单包防护日志
... D25: IPSecVPN日志
B26: 步骤2:数据组合
B27: 数据组合 | C27: 测试数据 | D27: 数据取值 | E27: 组合数据分析 | F27: 约束条件和组合策略 | G27: 组合结果
C28: 日志类型 | D28: 所有数据不组合，一条数据一个用例 | G28: 日志类型=系统日志,操作日志,入侵防御日志,防病毒日志,内容过滤日志,文件过滤日志,URL过滤日志,WEB防护日志,防暴力破解日志,弱密码日志,控制策略阻断日志,本地控制策略日志,单包防护日志,Flood攻击日志,黑白名单日志,EDR推广日志,IPSecVPN日志
B29: 步骤3:逻辑用例设计
B30: 逻辑用例编号 | C30: 测试用例描述 | F30: 覆盖的测试数据 | G30: 测试数据选取结果
B31: log.logmng.outport | C31: 验证${日志类型}导出功能 | F31: 日志类型 | G31: 日志类型=系统日志,操作日志,入侵防御日志,防病毒日志,内容过滤日志,文件过滤日志,URL过滤日志,WEB防护日志,防暴力破解日志,弱密码日志,控制策略阻断日志,本地控制策略日志,单包防护日志,Flood攻击日志,黑白名单日志,EDR推广日志,IPSecVPN日志
B32: 步骤4:物理用例设计
B33: 逻辑用例编号 | C33: 用例标题 | D33: 测试数据 | E33: 预置条件 | F33: 测试步骤 | G33: 预期结果 | H33: 优先级 | I33: 测试类型 | J33: 自动化
B34: log.logmng.outport | C34: 验证${日志类型}导出功能 | D34: 日志类型=系统日志,操作日志,入侵防御日志,防病毒日志,内容过滤日志,文件过滤日志,URL过滤日志,WEB防护日志,防暴力破解日志,弱密码日志,控制策略阻断日志,本地控制策略日志,单包防护日志,Flood攻击日志,黑白名单日志,EDR推广日志,IPSecVPN日志 | E34: 1、网元正常启动 | F34: 1、在选择任意的一个时间范围精确到秒 2、向防火墙的日志侦听端口写入${日志类型}100条,时间任意的格式为"2024-10-17 02:00:00",级别字段为中文,IP地址包含ipv4和ipv6地址，tcpudp端口为0-65535随机数，其他没有明确要求的字段包含中文数字和特殊字符点(.)中横杠(-)和空格 3、向防火墙的日志侦听端口写入至少1条${日志类型}，时间为步骤1中选取的开始时间前1s 4、向防火墙的日志侦听端口写入至少1条${日志类型}，时间为步骤1中选取的结束时间后1s 5、导出${日志类型}，时间范围为步骤1选择的时间范围。【check1】【check2】 | G34: 1、【check1】下载的日志中包含步骤2中写入的所有日志，抽查首尾和中间任意一条日志的字段全部正确，日志的数量正确。 2、【check2】步骤3和步骤4中写入的日志不在导出的日志中 | H34: P3 | I34: 功能测试 | J34: 待实现
A35: 最大数量的日志导出功能测试 | B35: 【设计方法】直接设计法
B36: 步骤1:逻辑用例设计
B37: 逻辑用例编号 | C37: 测试用例描述 | F37: 覆盖的测试数据 | G37: 测试数据选取结果
B38: log.logmng.outport.capcity | C38: 验证最大数量的日志导出功能 | F38: 日志规格 | G38: 日志规格=最大数量
B39: 步骤2:物理用例设计
B40: 逻辑用例编号 | C40: 用例标题 | D40: 测试数据 | E40: 预置条件 | F40: 测试步骤 | G40: 预期结果 | H40: 优先级 | I40: 测试类型 | J40: 自动化
B41: log.logmng.outport.capcity | C41: 验证最大数量的日志导出功能 | D41: 日志规格=最大数量 | E41: 1、网元正常启动 | F41: 1、随机选取系统日志,操作日志,入侵防御日志,防病毒日志,内容过滤日志,文件过滤日志,URL过滤日志,WEB防护日志,防暴力破解日志,弱密码日志,控制策略阻断日志,本地控制策略日志,单包防护日志,Flood攻击日志,黑白名单日志,EDR推广日志,IPSecVPN日志中的一种日志 2、向日志侦听接口写入步骤1中选取的最大数量的日志，时间范围超出1个月。 3、导出日志，自定义时间时间范围包含所有步骤2中写入的日志。【check1】 4、检查导出的日志文件数量和内容。【check2】 | G41: 1、【check1】日志导出成功 2、【check2】导出日志的数量为正确，导出日志内容正确（检查收尾日志和中间任意一条日志） | H41: P4 | I41: 可靠性测试 | J41: 不实现
A42: 修改系统时间对日志导出的影响 | B42: 【设计方法】直接设计法
B43: 步骤1:逻辑用例设计
B44: 逻辑用例编号 | C44: 测试用例描述 | F44: 覆盖的测试数据 | G44: 测试数据选取结果
...

Sheet 日志外发
A1: 测试点汇总 | B1: 测试点 | C1: 测试设计方法 | D1: 适用场景 | E1: 用例规模（个） | F1: 测试数据
B2: 日志外发协议测试 | C2: 等价类划分&数据组合 | E2: 5 | F2: syslog（支持tcp和udp，支持加密和不加密），restAPI（加密且只支持tcp格式），tcp和udp端口边界，源IP测试
B3: 日志外发并发测试 | C3: 直接分析 | E3: 2 | F3: 多种日志，多个服务器
B4: 日志服务器连接可靠性测试 | C4: 直接分析 | E4: 5 | F4: 日志服务器地址变化（地址，端口、协议方式）、路由状态变化（策略路由、静态路由）、链路震荡，区分UDP和TCP断链
B5: 日志外发接口IP地址变化测 | C5: 直接分析 | E5: 1 | F5: 接口IP地址变化
A6: 日志外发协议测试 | B6: 【设计方法】等价类划分&数据组合
B7: 步骤1:等价类划分
B8: 等价类划分 | C8: 测试数据 | D8: 有效类 | E8: 无效类 | F8: 选取策略 | G8: 选取结果
C9: 端口 | D9: 常用端口514
D10: 常用端口1468
D11: 知名端口80
D12: 随机端口1~65535
C13: 发送方式 | D13: syslog
D14: restapi
C15: 加密 | D15: 加密
D16: 不加密
C17: 发送协议 | D17: tcp
D18: upd
D19: 默认
B20: 步骤2:数据组合
B21: 数据组合 | C21: 测试数据 | D21: 数据取值 | E21: 组合数据分析 | F21: 约束条件和组合策略 | G21: 组合结果
C22: 发送方式&发送协议 | D22: syslog | E22: tcp,udp | F22: 发送方式为syslog,发送协议可以为tcp和udp | G22: 发送方式=syslog;发送协议=tcp 发送方式=syslog;发送协议=udp
D23: restapi | E23: 默认 | F23: 发送方式为restapi,发送协议不可配为空，实际处理为tcp | G23: 发送方式=restapi;发送协议=默认
C24: 发送方式&发送协议&加密 | D24: 发送方式=syslog;发送协议=tcp | E24: 加密,不加密 | F24: 加密方式为加密和不加密 | G24: 发送方式=syslog;发送协议=tcp;加密=加密 发送方式=syslog;发送协议=tcp;加密=不加密
D25: 发送方式=syslog;发送协议=udp | E25: 不加密 | F25: 必为不加密 | G25: 发送方式=syslog;发送协议=udp;加密=不加密
D26: 发送方式=restapi;发送协议=空 | E26: 加密 | F26: 必为加密 | G26: 发送方式=restapi;发送协议=空;加密=加密
C27: 发送方式&发送协议&加密&端口 | D27: 发送方式=syslog;发送协议=tcp;加密=加密 | E27: 随机端口1~65535 | F27: 其他端口都有组合，这里选择随机端口 | G27: 发送方式=syslog;发送协议=tcp;加密=加密;端口=随机端口1~65535
D28: 发送方式=syslog;发送协议=tcp;加密=不加密 | E28: 常用端口514 | F28: tcp方式的常用端口为514 | G28: 发送方式=syslog;发送协议=tcp;加密=不加密;端口=常用端口514
D29: 发送方式=syslog;发送协议=udp;加密=不加密 | E29: 常用端口1468 | F29: udp方式的常用端口为1468 | G29: 发送方式=syslog;发送协议=udp;加密=不加密;端口=常用端口1468
D30: 发送方式=restapi;发送协议=空;加密=加密 | E30: 知名端口80 | F30: resapi常与知名端口80组合 | G30: 发送方式=restapi;发送协议=默认;加密=加密;端口=知名端口80
B31: 步骤3:逻辑用例设计
B32: 逻辑用例编号 | C32: 测试用例描述 | F32: 覆盖的测试数据 | G32: 测试数据选取结果
B33: log.logserver.send | C33: 验证日志以${发送方式}方式${发送协议}协议${加密}发送到日志服务器 | F33: 日志类型 | G33: 发送方式=syslog;发送协议=tcp;加密=加密;端口=随机端口1~65535 发送方式=syslog;发送协议=tcp;加密=不加密;端口=常用端口514 发送方式=syslog;发送协议=udp;加密=不加密;端口=常用端口1468 发送方式=restapi;发送协议=默认;加密=加密;端口=知名端口80
B34: 步骤4:物理用例设计
B35: 逻辑用例编号 | C35: 用例标题 | D35: 测试数据 | E35: 预置条件 | F35: 测试步骤 | G35: 预期结果 | H35: 优先级 | I35: 测试类型 | J35: 自动化
B36: log.logserver.send | C36: 验证日志以${发送方式}方式${发送协议}协议${加密}发送到日志服务器 | D36: 发送方式=syslog;发送协议=tcp;加密=加密;端口=随机端口1~65535 发送方式=syslog;发送协议=tcp;加密=不加密;端口=常用端口514 发送方式=syslog;发送协议=udp;加密=不加密;端口=常用端口1468 发送方式=restapi;发送协议=默认;加密=加密;端口=知名端口80 | E36: 1、网元正常启动 2、配置静态路由保证日志服务器网络可达 | F36: 1、配置开启日志服务器，配置日志服务器IP地址，端口为${端口}，发送方式为${发送方式},加密方式为${加密}，发送协议为${发送协议}。 2、配置日式过滤为发送所有日志 3、向日志侦听端口写入至少3条系统日志,操作日志,入侵防御日志,防病毒日志,内容过滤日志,文件过滤日志,URL过滤日志,WEB防护日志,防暴力破解日志,弱密码日志,控制策略阻断日志,本地控制策略日志,单包防护日志,Flood攻击日志,黑白名单日志,EDR推广日志,IPSecVPN日志中的任意日志 4、观察日志服务器上接收到的日志的数量和内容。【check1】【check2】【check3】 | G36: 1、【check1】日志服务器上接收到的日志数量和内容正确 2、【check2】日志接受到的源IP、协议、源目的端口、加密信息正确 3、【check3】接收到的日志发送方式正确 | H36: P2 | I36: 功能测试 | J36: 待实现
A37: 日志外发并发测试 | B37: 【设计方法】直接设计法
B38: 步骤1:逻辑用例设计
B39: 逻辑用例编号 | C39: 测试用例描述 | F39: 覆盖的测试数据 | G39: 测试数据选取结果
B40: log.logserver.send.concurrency | C40: 验证多种日志并行外发功能 | F40: 日志类型 | G40: 日志类型=系统日志,操作日志,入侵防御日志,防病毒日志,内容过滤日志,文件过滤日志,URL过滤日志,WEB防护日志,防暴力破解日志,弱密码日志,控制策略阻断日志,本地控制策略日志,单包防护日志,Flood攻击日志,黑白名单日志,EDR推广日志,IPSecVPN日志
...

Sheet 日志过滤
A1: 测试点汇总 | B1: 测试点 | C1: 测试设计方法 | D1: 适用场景 | E1: 用例规模（个） | F1: 测试数据
B2: 验证安全日志过滤功能 | C2: 等价类划分&数据组合 | E2: 16 | F2: 入侵防御日志、防病毒日志、内容过滤日志、文件过滤、URL过滤日志、WEB防护日志、防暴力破解日志、弱密码日志。日志级别支持信息、低危、中危、高危、严重。
B3: 验证系统日志过滤功能 | C3: 等价类划分&数据组合 | E3: 4 | F3: 系统日志、操作日志。日志级别支持调试、信息、警告、错误、致命、严重错误
B4: 验证流量日志过滤功能 | C4: 直接分析 | E4: 6 | F4: 控制策略阻断日志、允许日志，流日志，NAT日志，分解到其他特性
B5: 验证监控中心-安全日志过滤功能 | C5: 等价类划分&数据组合 | F5: 单包防护日志,Flood攻击日志,黑白名单日志,EDR推广日志,IPSecVpn日志
B6: 在线修改配置后的日志外发功能 | C6: 直接分析 | F6: 1、日志服务器、日志过滤（类型和级别），日志过滤在测试步骤中已覆盖，日志服务器修改在日志外发中已覆盖
B7: s6000和电力格式日志过滤功能 | C7: 直接分析 | E7: 4 | F7: 标准格式、电力格式，s6000_ips，s6000_fw，配置值和默认值放到日志格式中覆盖
A8: 验证安全日志过滤功能 | B8: 【设计方法】等价类划分&数据组合
B9: 步骤1:等价类划分
B10: 等价类划分 | C10: 测试数据 | D10: 有效类 | E10: 无效类 | F10: 选取策略 | G10: 选取结果
C11: 日志类型 | D11: 入侵防御日志 | F11: 数据名称和分类合并 | G11: 日志类型=入侵防御日志,防病毒日志,内容过滤日志,URL过滤日志,文件过滤日志,WEB防护日志,弱密码日志,防暴力破解日志
D12: 防病毒日志
D13: 内容过滤日志
D14: URL过滤日志
D15: 文件过滤日志
D16: WEB防护日志
D17: 弱密码日志
D18: 防暴力破解日志
C19: 过滤级别 | D19: 信息 | F19: 数据名称和分类合并 | G19: 过滤级别=信息,低危,中危,高危,严重
D20: 低危
D21: 中危
D22: 高危
D23: 严重
B24: 步骤2:数据组合
B25: 数据组合 | C25: 测试数据 | D25: 数据取值 | E25: 组合数据分析 | F25: 约束条件和组合策略 | G25: 组合结果
C26: 日志类型&过滤级别 | D26: 入侵防御日志 | E26: 过滤级别=信息,低危,中危,高危,严重 | F26: 全组合 | G26: 日志类型=入侵防御日志;过滤级别=信息,低危,中危,高危,严重 日志类型=防病毒日志;过滤级别=信息,低危,中危,高危,严重 日志类型=内容过滤日志;过滤级别=信息,低危,中危,高危,严重 日志类型=URL过滤日志;过滤级别=信息,低危,中危,高危,严重 日志类型=文件过滤日志;过滤级别=信息,低危,中危,高危,严重 日志类型=WEB防护日志;过滤级别=信息,低危,中危,高危,严重 日志类型=弱密码日志;过滤级别=信息,低危,中危,高危,严重 日志类型=防暴力破解日志;过滤级别=信息,低危,中危,高危,严重
D27: 防病毒日志 | E27: 过滤级别=信息,低危,中危,高危,严重 | F27: 全组合
D28: 内容过滤日志 | E28: 过滤级别=信息,低危,中危,高危,严重 | F28: 全组合
D29: URL过滤日志 | E29: 过滤级别=信息,低危,中危,高危,严重 | F29: 全组合
D30: 文件过滤日志 | E30: 过滤级别=信息,低危,中危,高危,严重 | F30: 全组合
D31: WEB防护日志 | E31: 过滤级别=信息,低危,中危,高危,严重 | F31: 全组合
D32: 弱密码日志 | E32: 过滤级别=信息,低危,中危,高危,严重 | F32: 全组合
D33: 防暴力破解日志 | E33: 过滤级别=信息,低危,中危,高危,严重 | F33: 全组合
B34: 步骤3:物理用例设计
B35: 逻辑用例编号 | C35: 用例标题 | D35: 测试数据 | E35: 预置条件 | F35: 测试步骤 | G35: 预期结果 | H35: 优先级 | I35: 测试类型 | J35: 自动化
B36: log.logserver.filter.sec | C36: 验证标准格式${日志类型}过滤功能 | D36: 日志类型=入侵防御日志;过滤级别=信息,低危,中危,高危,严重 日志类型=防病毒日志;过滤级别=信息,低危,中危,高危,严重 日志类型=内容过滤日志;过滤级别=信息,低危,中危,高危,严重 日志类型=URL过滤日志;过滤级别=信息,低危,中危,高危,严重 日志类型=文件过滤日志;过滤级别=信息,低危,中危,高危,严重 日志类型=WEB防护日志;过滤级别=信息,低危,中危,高危,严重 日志类型=弱密码日志;过滤级别=信息,低危,中危,高危,严重 日志类型=防暴力破解日志;过滤级别=信息,低危,中危,高危,严重 | E36: 1、网元正常启动 2、配置静态路由保证日志服务器网络可达 3、开启日志服务器 4、配置开启${日志类型}的日志过滤开关为不发送 | F36: 1、持续向日志侦听端口写入${日志类型}的日志，日志级别包含${过滤级别}所有级别，观察日志服务器的日志接收。【check1】 2、配置开启${日志类型}的日志过滤开关为发送，发送日志级别仅发送$[过滤级别]的日志，观察日志服务器接收情况。【check2】 3、配置开启${日志类型}的日志过滤开关为发送，发送日志级别仅发送所有级别的日志，观察日志服务器接收情况。【check3】 | G36: 1、【check1】日志服务器不能接收到任何${日志类型}的日志 2、【check2】日志服务器仅可以接收到该过滤级别的${日志类型}，接收到日志的所有字段与写入的字段完全相同 3、【check3】日志服务器可以接收到所有级别的${日志类型}，接收到日志的所有字段与写入的字段完全相同 | H36: P2 | I36: 功能测试 | J36: 待实现
A37: 验证系统日志过滤功能 | B37: 【设计方法】等价类划分&数据组合
B38: 步骤1:等价类划分
B39: 等价类划分 | C39: 测试数据 | D39: 有效类 | E39: 无效类 | F39: 选取策略 | G39: 选取结果
C40: 日志类型 | D40: 操作日志 | F40: 数据名称和分类合并 | G40: 日志类型=操作日志,系统日志
...

Sheet 日志格式
A1: 测试点汇总 | B1: 测试点 | C1: 测试设计方法 | D1: 适用场景 | E1: 用例规模（个） | F1: 测试数据
B2: 日志外发格式修改测试 | C2: 直接分析 | E2: 3 | F2: 不同日志外发格式修改配置测试、日志服务器、日志过滤
B3: 日志外发格式切换测试 | C3: 直接分析 | E3: 4 | F3: 标准格式、电力格式，s6000_ips，s6000_fw
B4: 验证标准格式和其他非标格式日志外发功能 | C4: 直接分析 | E4: 12 | F4: 电力格式，s6000_ips，s6000_fw，基本信息、安全策略、告警信息、心跳日志
B5: s6000_fw格式时IPv4策略内容外发功能 | C5: 等价类划分&数据组合 | E5: 20 | F5: 地址对象、服务对象、地区对象、时间对象
B6: s6000_fw格式时IPv6策略内容外发功能 | C6: 等价类划分&数据组合 | E6: 20 | F6: 地址对象、服务对象、地区对象、时间对象
B7: 该部分用例在SPC500和SPC600已重构，C01不重构

Sheet 调试日志管理
A1: 测试点汇总 | B1: 测试点 | C1: 测试设计方法 | D1: 适用场景 | E1: 用例规模（个） | F1: 测试数据
B2: 日志每分钟轮转测试 | C2: 直接分析 | E2: 2 | F2: 1、如果/trace目录占用率大于90%时，删除/trace/coredump/*，执行每小时任务 2、每分钟任务：如果/var/log目录占用大于90%时，则将/var/log目录清空truncate -s 0 /var/log/*
B3: die日志生成测试 | C3: 直接分析 | E3: 10
B4: 日志每小时轮转测试 | C4: 直接分析 | E4: 6 | F4: trace/log/*.log，/trace/log/secure，/var/log/messages，/var/log/syslog，/var/log/auth.log，/var/log/syslog进行轮转处理
B5: 调试日志开启和关闭测试 | C5: 直接分析 | E5: 3
A6: 日志每分钟轮转测试 | B6: 【设计方法】直接设计法
B7: 步骤1:逻辑用例设计
B8: 逻辑用例编号 | C8: 测试用例描述 | F8: 覆盖的测试数据 | G8: 测试数据选取结果
B9: log.devlog.debug.minute.trace | C9: 验证/trace目录每分钟清理功能 | F9: 清理目录=/trace | G9: 清理目录=/trace
B10: log.devlog.debug.minute.varlog | C10: 验证/var/log目录每分钟清理功能 | F10: 清理目录=/var/log | G10: 清理目录=/var/log
B11: 步骤2:物理用例设计
B12: 逻辑用例编号 | C12: 用例标题 | D12: 测试数据 | E12: 预置条件 | F12: 测试步骤 | G12: 预期结果
B13: log.devlog.debug.minute.trace | C13: 验证/trace目录每分钟清理功能 | D13: 清理目录=/trace | E13: 1、网元正常启动 2、在/trace目录下创建至少两个.log结尾的文件，并在/trace/coredump目录下创建至少两个文件，并保证/trace目录占用率低于90% | F13: 1、静置观察/trace和/trace/coredump目录超过1分钟【check1】 2、使用dd命令在/trace/目录下构造文件使得构造/trace目录占用率大于90%，命令参考dd if=[任意源文件] of=/trace/test.log count=任意数量 bs=xxxM 3、观察/trace目录和/trace/coredump目录【check2】【check3】 4、使用dd命令在/trace/coredump目录下构造文件使得构造/trace目录占用率大于90%，命令参考dd if=[任意源文件] of=/trace/coredump count=任意数量 bs=xxxM 5、在/trace目录下创建质量两个.log结尾的文件 6、观察/trace目录和/trace/coredump目录【check2】【check3】 | G13: 1、【check1】/trace/coredump目录不会被清空 2、【check2】/trace/coredump在1分钟内被清空 3、【check3】/trace目录下所有以.log结尾的文件全部被轮转。
B14: log.devlog.debug.minute.varlog | C14: 验证/var/log目录每分钟清理功能 | D14: 清理目录=/var/log | E14: 1、网元正常启动 2、保证/var/log目录中存在文件，且/var/log占用率低于90% | F14: 1、静置观察/var/log目录超过1分钟【check1】 2、使用dd命令在/var/log目录下构造文件使得构造/var/log目录占用率大于90%，命令参考dd if=[任意源文件] of=/var/log/test.log count=任意数量 bs=xxxM 3、观察/var/log目录【check2】 | G14: 1、【check1】/var/log目录不会被清空 2、【check1】/var/log在1分钟内被清空
A15: 日志每小时轮转测试 | B15: 【设计方法】直接设计法
B16: 步骤1:逻辑用例设计
B17: 逻辑用例编号 | C17: 测试用例描述 | F17: 覆盖的测试数据 | G17: 测试数据选取结果
B18: log.devlog.debug.hour.truncate | C18: 验证${日志类型}日志每小时轮转功能 | F18: 日志类型=trace;数量=2;磁盘容量=10M 日志类型=secure,syslog;数量=2;磁盘容量=10M 日志类型=messages,auth;数量=4;磁盘容量=30M | G18: 日志类型=trace;数量=2;磁盘容量=10M 日志类型=secure,syslog;数量=2;磁盘容量=10M 日志类型=messages,auth;数量=4;磁盘容量=30M
B19: 步骤2:物理用例设计
B20: 逻辑用例编号 | C20: 用例标题 | D20: 测试数据 | E20: 预置条件 | F20: 测试步骤 | G20: 预期结果
B21: log.devlog.debug.hour.truncate.trace | C21: 验证${日志类型}日志每小时轮转功能 | D21: 日志类型=trace;数量=2;磁盘容量=10M | E21: 1、网元正常启动 | F21: 1、构造/trace目录下vpp.log和agent.log文件大于${磁盘容量}，构造frr.log和snort.log小于${磁盘容量} 2、在整点或者修改防火墙系统时间到整点,观察/trace目录下的log文件【check1】【check2】 3、再次构造vpp.log和agent.log文件大于${磁盘容量}，重复步骤2【check2】【check3】 4、重复步骤3和步骤2大于${数量}次，观察/trace目录下的log文件和压缩文件。【check4】 | G21: 1、【check1】原vpp.log和agent.log被研所生成压缩文件 2、【check2】frr.log和snort.log不会被轮转，保持不变 3、【check3】原vpp.log和agent.log被压缩生成第二个压缩文件 4、【check4】vpp.log和agent.log最大生成${数量}个压缩文件，超过${数量}轮转时仅保留最新的${数量}个压缩文件，更早的压缩文件被删除。
B22: log.devlog.debug.hour.truncate.varlog | C22: 验证${日志类型}日志每小时轮转功能 | D22: 日志类型=secure,syslog;数量=2;磁盘容量=10M 日志类型=messages,auth.log;数量=4;磁盘容量=30M | E22: 1、网元正常启动 | F22: 1、构造/var/log目录下${日志类型}小于${磁盘容量} 2、在整点或者修改防火墙系统时间到整点,观察/var/log目录下的${日志类型}文件【check1】 3、构造/var/log目录下${日志类型}大于${磁盘容量}，重复步骤2.【check2】 3、再次构造/var/log目录下${日志类型}大于${磁盘容量}，重复步骤2。【check3】 4、重复步骤3和步骤2大于${数量}次，观察/var/log目录下的${日志类型}文件和对应的压缩文件【check4】 | G22: 1、【check1】/var/log目录下${日志类型}不会被压缩，并保持不变 2、【check2】/var/log目录下${日志类型}被压缩生成压缩文件 3、【check3】/var/log目录下${日志类型}被压缩生成第二个压缩文件 4、【check4】/var/log目录下${日志类型}最大生成${数量}个压缩文件，超过${数量}轮转时仅保留最新的${数量}个压缩文件，更早的压缩文件被删除。
A23: die日志 | B23: 【设计方法】直接设计法
B24: 步骤1:逻辑用例设计
B25: 逻辑用例编号 | C25: 测试用例描述 | F25: 覆盖的测试数据 | G25: 测试数据选取结果
B26: log.devlog.debug.die | C26: 验证${组件名称}异常重启记录die日志功能 | F26: 组件名称=vpp,agent,influxdb,瀚高,sslvpn,frr,nginx | G26: 组件名称=vpp,agent,influxdb,瀚高,sslvpn,frr,nginx
B27: 步骤2:物理用例设计
B28: 逻辑用例编号 | C28: 用例标题 | D28: 测试数据 | E28: 预置条件 | F28: 测试步骤 | G28: 预期结果
B29: log.devlog.debug.die | C29: 验证${组件名称}异常重启记录die日志功能 | D29: 组件名称=vpp,agent,influxdb,瀚高,sslvpn,frr,nginx | E29: 1、网元正常启动 | F29: 1、通过kill组件${组件名称}的进程模拟异常重启 2、观察/trace/log目录【check1】 3、30分钟内再次kill组件${组件名称}的进程模拟异常重启，观察/trace/log目录【check2】 4、超过30分钟以上再次kill组件${组件名称}的进程模拟异常重启，观察/trace/log目录【check1】 | G29: 1、【check1】生成${组件名称}对应的die日志 2、【check2】不会生成对应的die日志
A30: 调试日志开启和关闭测试 | B30: 【设计方法】直接设计法
B31: 步骤1:逻辑用例设计
B32: 逻辑用例编号 | C32: 测试用例描述 | F32: 覆盖的测试数据 | G32: 测试数据选取结果
B33: log.devlog.debug.switch | C33: 验证调试日志开启和关闭功能 | F33: 调试日志=开启,关闭 | G33: 调试日志=开启,关闭
B34: 步骤2:物理用例设计
B35: 逻辑用例编号 | C35: 用例标题 | D35: 测试数据 | E35: 预置条件 | F35: 测试步骤 | G35: 预期结果
B36: log.devlog.debug.switch.dfault | C36: 验证调试日志开关默认值和重启恢复 | D36: 调试日志=开启,关闭 | E36: 1、网元正常启动 | F36: 1、观察调试日志开关和调试日志记录情况。【check1】【check2】 2、开启调试日志，观察调试日志记录情况。【check3】 3、重启防火墙 4、防火墙启动后观察调试日志开关和调试日志记录情况。【check1】【check2】 | G36: 1、【check1】调试日志开关为关闭 2、【check2】防火墙后台目录中/appdata/etc/agentcfg/supervisor.conf描述所有进程不会记录调试日志 3、【check2】防火墙后台目录中/appdata/etc/agentcfg/supervisor.conf描述所有进程开始记录调试日志
B37: log.devlog.debug.switch | C37: 验证调试日志开启和关闭功能 | D37: 调试日志=开启,关闭 | E37: 1、网元正常启动 2、调试日志开关为关闭 | F37: 1、观察/trace/log目录。【check1】 2、开启调试日志【check2】 3、关闭调试日志【check1】【check3】 | G37: 1、【check1】防火墙后台目录中/appdata/etc/agentcfg/supervisor.conf描述所有进程不会记录调试日志 2、【check2】防火墙后台目录中/appdata/etc/agentcfg/supervisor.conf描述所有进程开始记录调试日志 3、【check3】防火墙后台目录中/userdata/userfile/gatherinfo，会生成collection_当前时间戳.zip的文件

Sheet 信息收集
A1: 测试点汇总 | B1: 测试点 | C1: 测试设计方法 | D1: 适用场景 | E1: 用例规模（个） | F1: 测试数据
B2: 异常信息收集功能 | C2: 直接分析 | E2: 2 | F2: 密码系统信息的密码是ngfw123!@#
B3: 信息收集限制测试 | C3: 直接分析 | E3: 2 | F3: etcd的配置量小于2k条
A4: 异常信息收集功能 | B4: 【设计方法】直接设计法
B5: 步骤1:逻辑用例设计
B6: 逻辑用例编号 | C6: 测试用例描述 | F6: 覆盖的测试数据 | G6: 测试数据选取结果
B7: log.devlog.gather.abnormal
B8: 步骤2:物理用例设计
B9: 逻辑用例编号 | C9: 用例标题 | D9: 测试数据 | E9: 预置条件 | F9: 测试步骤 | G9: 预期结果
B10: log.devlog.gather.abnormal | C10: 验证防火墙异常信息收集功能 | D10: 异常信息=core | E10: 1、网元正常启动 | F10: 1、使用dd命令在/trace/coredump目录下构造11个core文件，使得/trace分区使用率在85%到90%之间 2、打开异常信息收集【check1】 3、下载最大和最小的core文件【check2】 4、删除最大和最小的core文件【check3】 | G10: 1、【check1】页面可以查看到所有的core文件 2、【check2】下载成功，下载的文件与构造的文件完全一致 3、【check3】删除成功，在linux后台产看core文件被删除
A11: 信息收集限制测试 | B11: 【设计方法】直接设计法
B12: 步骤1:逻辑用例设计
B13: 逻辑用例编号 | C13: 测试用例描述 | F13: 覆盖的测试数据 | G13: 测试数据选取结果
B14: log.devlog.gather.info.manual | C14: 验证防火墙手动收集信息功能 | F14: 收集方式=手动 | G14: 收集方式=手动
B15: log.devlog.gather.info.auto | C15: 验证防火墙自动收集信息功能 | F15: 收集方式=手动 | G15: 收集方式=手动
B16: log.devlog.gather.info.limit | C16: 验证防火墙信息收集配置限制功能 | F16: 收集方式=限制 | G16: 收集方式=限制
B17: 步骤2:物理用例设计
B18: 逻辑用例编号 | C18: 用例标题 | D18: 测试数据 | E18: 预置条件 | F18: 测试步骤 | G18: 预期结果
B19: log.devlog.gather.info.manual | C19: 验证防火墙手动收集信息功能 | D19: 收集方式=手动 | E19: 1、网元正常启动 2、在防火墙上开启调试日志 | F19: 1、在防火墙发起手动收集信息，查看防火墙的信息文件列表。【check1】【check2】 2、重复发起超过3次信息收集【check1】【check2】 3、下载第一个和最后一个信息收集文件。【check3】 4、删除任意信息收集文件。【check4】 5、再次下载任意信息收集文件。【check3】 | G19: 1、【check1】防火墙的上能够查当前时刻信息收集文件 2、【check2】防火墙后台目录中/userdata/userfile/gatherinfo，会生成collection_当前时间戳.zip的文件 3、【check3】下载成功 4、【check4】删除成功
B20: log.devlog.gather.info.auto | C20: 验证防火墙自动收集信息功能 | D20: 收集方式=自动 | E20: 1、网元正常启动 2、在防火墙上开启调试日志 | F20: 1、配置信息收集方式为自动，时间为60-720s任意值x，不启用自动收集，在超过x秒周期观察信息收集文件。【check1】 2、配置防火墙自动化收集信息周期为x，状态为启用。 3、在超过11*x秒周期观察日志收集文件。【check2】 4、删除任意信息收集文件，在下一周期观察信息收集文件。【check3】 | G20: 1、【check1】防火墙前端和后台（/userdata/userfile/gatherinfo）均不会自动生成信息收集文件 2、【check2】防火墙的前台和后台会查询到10个信息收集文件。且第11个周期的文件会覆盖第一个（时间最早的）收集的文件。文件的时间戳间隔与配置的x秒相同。 3、【check3】信息收集文件在前端和后台会达到10个，不会删除任何信息收集文件。
B21: log.devlog.gather.info.auto.long | C21: 防火墙自动收集信息功能长期测试 | D21: 收集方式=自动 | E21: 1、网元正常启动 2、在防火墙上开启调试日志 | F21: 1、配置信息收集方式为自动，时间为60-720s任意值x，不启用自动收集，在超过x秒周期观察信息收集文件。【check1】【check3】 2、配置防火墙自动化收集信息周期为x，状态为启用。 3、保持防护墙开启自动化信息收集超过12小时。【check2】【check3】 | G21: 1、【check1】防火墙前端和后台（/userdata/userfile/gatherinfo）均不会自动生成信息收集文件 2、【check2】防火墙的前台和后台会查询到10个信息收集文件。文件的时间戳间隔与配置的x秒相同。 3、【check3】收集内存和cpu信息，设别无cpu和内存泄漏
B22: log.devlog.gather.info.context | C22: 验证防火墙信息收集内容正确性 | D22: 收集方式=限制 | E22: 1、网元正常启动 2、构造etcd中的配置总量低于2000 3、在防火墙上开启调试日志 | F22: 1、在防火墙发起手动收集信息 2、下载手动收集到的信息文件，解压观察收集到的信息。【check1】【check2】 3、配置防火墙为自动收集信息，且等待期完成至少1次自动化信息收。 4、下载自动收集的信息，解压观察收集到的信息。【check1】【check2】 | G22: 1、【check1】文件解压需要密码，密码为ngfw123!@# 2、【check2】收集信息包含/appdata/etc/version,/appdata/etc/ngfwfeatureinfo,/apdata/etc/license/cliclienseinfo.txt,系统时间,CPU使用率,uptime,free -lh,df -lh,ps -aux | grep /opt,top -n 3,cat /appdata/etc/agentcfg/*,etcd配置(少于2k配置),操作日志（最少1个月）,系统日志（最少1个月）,dmesg,/var/log/messages,vpp下的show logging,最近一周的CPU、内存、磁盘使用率,设备流量大小（收集当时）,每个接口的pps（收集当时）会话总数（收集当时）
B23: log.devlog.gather.info.limit.file | C23: 验证防火墙信息收集配置限制功能 | D23: 收集方式=限制 | E23: 1、网元正常启动 2、构造etcd中的配置总量低于2000 3、在防火墙上开启调试日志 | F23: 1、在防火墙发起手动或者自动收集信息 2、下载手动收集到的信息文件，解压观察收集到的信息。【check1】【check2】 3、在防火墙配置任意配置使防火墙的etcd配置草果2000个（etcdctl get --prefix / --keys-only | wc -l ）返回值大于2000 4、在防火墙发起手动或者自动收集信息【check1】【check3】 | G23: 1、【check1】文件解压需要密码，密码为ngfw123!@# 2、【check2】收集信息包含/appdata/etc/version,/appdata/etc/ngfwfeatureinfo,/apdata/etc/license/cliclienseinfo.txt,系统时间,CPU使用率,uptime,free -lh,df -lh,ps -aux | grep /opt,top -n 3,cat /appdata/etc/agentcfg/*,etcd配置(少于2k配置),操作日志（最少1个月）,系统日志（最少1个月）,dmesg,/var/log/messages,vpp下的show logging,最近一周的CPU、内存、磁盘使用率,设备流量大小（收集当时）,每个接口的pps（收集当时）会话总数（收集当时），且信息正确 3、【check3】信息收集叫check2中少了etcd配置，其他信息相同且信息正确

Sheet DFX
A1: 测试点汇总 | B1: 测试点 | C1: 测试设计方法 | D1: 适用场景 | E1: 用例规模（个） | F1: 测试数据
B2: 日志容量测试 | C2: 直接分析 | E2: 3 | F2: 整机容量测试，规格测试，满规格时的增删改查测试
B3: 日志速率测试 | C3: 直接分析 | E3: 2 | F3: 日志写入速率、日志外发速率
B4: 日志功能疲劳测试 | C4: 直接分析 | E4: 9 | F4: 反复修改日志格式，日志服务器（日志外发已覆盖），日志过滤，日志归并（已覆盖），信息收集、调试日志，反复收集日志、日志导出、查看日志，日志备份,进程重启（在进程管理中已覆盖）
B5: 日志文件容量测试 | C5: 直接分析 | E5: 3 | F5: 日志备份文件、日志收集文件、异常信息收集（在日志备份,信息收集中已覆盖）
B6: 日志配置存库测试 | C6: 直接分析 | E6: 3 | F6: 日志服务器、日志备份、日志归并，日志过滤、日志格式、信息收集配置存库测试，导入测试。
B7: 日志格式配置重置测试 | C7: 直接分析 | E7: 1 | F7: 日志格式配置重置测试
B8: 日志主备同步功能 | C8: 直接分析 | E8: 5 | F8: 日志配置主备同步功能（日志服务器、日志备份、日志归并，日志过滤、日志格式、信息收集配置），双主和主备
A9: 日志容量测试 | B9: 【设计方法】直接设计法
B10: 步骤1:逻辑用例设计
B11: 逻辑用例编号 | C11: 测试用例描述 | F11: 覆盖的测试数据 | G11: 测试数据选取结果
B12: log.dfx.capcity
B13: 步骤2:物理用例设计
B14: 逻辑用例编号 | C14: 用例标题 | D14: 测试数据 | E14: 预置条件 | F14: 测试步骤 | G14: 预期结果 | H14: 优先级 | I14: 测试类型 | J14: 自动化
B15: log.dfx.capcity | C15: 验证防火墙整机日志容量 | D15: 容量=整机容量 | E15: 1、网元正常启动 | F15: 1、向日志侦听端口写入系统日志,操作日志,入侵防御日志,防病毒日志,内容过滤日志,文件过滤日志,URL过滤日志,WEB防护日志,防暴力破解日志,弱密码日志,控制策略阻断日志,本地控制策略日志,单包防护日志,Flood攻击日志,黑白名单日志,EDR推广日志,IPSecVPN日志中任意一种日志，使其达到该种日志的最大数量-1，使用接口查询日志。【check1】 2、再向日志端口写入另外一种日志，使其达到最大规格的30%，并使用接口查询日志。【check1】 3、遍历所有日志日类型，均写入最大数量的30%，并使用接口查询日志。【check1】【check2】 | G15: 1、【check1】日志写入成功，查询日志与写入的数量和内容一致。 2、【check2】日志响应时间无明显降低 | H15: P4 | I15: 可靠性测试 | J15: 不实现
A16: 日志速率测试 | B16: 【设计方法】直接设计法
B17: 步骤1:逻辑用例设计
B18: 逻辑用例编号 | C18: 测试用例描述 | F18: 覆盖的测试数据 | G18: 测试数据选取结果
B19: log.dfx.rps
B20: 步骤2:物理用例设计
B21: 逻辑用例编号 | C21: 用例标题 | D21: 测试数据 | E21: 预置条件 | F21: 测试步骤 | G21: 预期结果 | H21: 优先级 | I21: 测试类型 | J21: 自动化
B22: log.dfx.rps | C22: 验证防火墙日志写入速率 | D22: 速率=最大速率 | E22: 1、网元正常启动 | F22: 1、选取系统日志,操作日志,入侵防御日志,防病毒日志,内容过滤日志,文件过滤日志,URL过滤日志,WEB防护日志,防暴力破解日志,弱密码日志,控制策略阻断日志,本地控制策略日志,单包防护日志,Flood攻击日志,黑白名单日志,EDR推广日志,IPSecVPN日志中任意两种以上日志。 2、持续以200条/s的速率向日志侦听端口写入步骤1中选取的日志，使用接口观察日志。【check1】 3、持续以超过1000条/s的速率向日志侦听端口写入步骤1中选取的日志，使用接口观察日志。【check2】【check3】 4、持续以超过1000条/s的速率写入日志，同时没过10s查询一次日志，持续2小时以上。【check2】【chekc3】 | G22: 1、【check1】日志写入成功，查询日志与写入的数量和内容一致。 2、【check2】部分日志会被丢弃，但是写入的日志数据正确 3、【check3】设备CPU、内容、磁盘无异常 | H22: P4 | I22: 性能测试 | J22: 不实现
B23: log.dfx.rps.send | C23: 验证防火墙日志外发速率 | D23: 速率=最大速率 | E23: 1、网元正常启动 2、开启日志服务器并配置三个日志服务器，分别以syslog tcp，syslog udp和restapi方式发送日志 3、配置日志服务器路由可达 | F23: 1、选取系统日志,操作日志,入侵防御日志,防病毒日志,内容过滤日志,文件过滤日志,URL过滤日志,WEB防护日志,防暴力破解日志,弱密码日志,控制策略阻断日志,本地控制策略日志,单包防护日志,Flood攻击日志,黑白名单日志,EDR推广日志,IPSecVPN日志中任意两种以上需要外发的日志。 2、持续以200条/s的速率向日志侦听端口写入步骤1中选取的日志，使用接口观察日志，观察日志服务器。【check1】 3、持续以超过1000条/s的速率向日志侦听端口写入步骤1中选取的日志，观察日志服务。【check2】【check3】 4、持续以超过1000条/s的速率写入日志，持续2小时以上。【check2】【chekc3】 | G23: 1、【check1】日志写入成功，查询日志与写入的数量和内容一致。 2、【check2】日志服务器只能收到部分写入的日志，接收到的部分日志内容正确 3、【check3】设备CPU、内容、磁盘无异常 | H23: P4 | I23: 性能测试 | J23: 不实现
A24: 日志功能疲劳测试 | B24: 【设计方法】直接设计法
B25: 步骤1:逻辑用例设计
B26: 逻辑用例编号 | C26: 测试用例描述 | F26: 覆盖的测试数据 | G26: 测试数据选取结果
B27: log.dfx.rps
B28: 步骤2:物理用例设计
B29: 逻辑用例编号 | C29: 用例标题 | D29: 测试数据 | E29: 预置条件 | F29: 测试步骤 | G29: 预期结果 | H29: 优先级 | I29: 测试类型 | J29: 自动化
B30: log.dfx.reliability.format | C30: 验证反复修改${操作}的日志功能 | D30: 操作=日志格式,日志过滤 | E30: 1、网元正常启动 2、开启日志服务器并配置三个日志服务器，分别以syslog tcp，syslog udp和restapi方式发送日志 3、配置日志服务器路由可达 | F30: 1、选取系统日志,操作日志,入侵防御日志,防病毒日志,内容过滤日志,文件过滤日志,URL过滤日志,WEB防护日志,防暴力破解日志,弱密码日志,控制策略阻断日志,本地控制策略日志,单包防护日志,Flood攻击日志,黑白名单日志,EDR推广日志,IPSecVPN日志中任意两种以上日志。 2、持续以200条/s的速率向日志侦听端口写入步骤1中选取的日志，使用接口观察日志。【check1】 3、反复修改${操作}持续时间2小时以上，修改次数超过200次 4、观察设备和使用接口观察日志【check1】【chekc2】 | G30: 1、【check1】日志写入成功，查询日志与写入的数量和内容一致。 2、【check2】设备CPU、内容、磁盘无异常 | H30: P4 | I30: 性能测试 | J30: 不实现
B31: log.dfx.reliability.logmng | C31: 验证反复修改${操作}的日志功能 | D31: 操作=日志导出,日志归并,日志备份, | E31: 1、网元正常启动 2、开启日志服务器并配置三个日志服务器，分别以syslog tcp，syslog udp和restapi方式发送日志 3、配置日志服务器路由可达 | F31: 1、选取系统日志,操作日志,入侵防御日志,防病毒日志,内容过滤日志,文件过滤日志,URL过滤日志,WEB防护日志,防暴力破解日志,弱密码日志,控制策略阻断日志,本地控制策略日志,单包防护日志,Flood攻击日志,黑白名单日志,EDR推广日志,IPSecVPN日志中任意两种以上日志。 2、持续以200条/s的速率向日志侦听端口写入步骤1中选取的日志，使用接口观察日志。【check1】 3、反复$修改{操作}持续时间2小时以上，修改次数超过200次 4、观察${操作}【check2】【chekc3】 | G31: 1、【check1】日志写入成功，查询日志与写入的数量和内容一致。 2、【check2】${操作}功能正常 3、【check3】设备CPU、内容、磁盘无异常 | H31: P4 | I31: 性能测试 | J31: 不实现
B32: log.dfx.reliability.log.query | C32: 验证反复${操作}的日志功能 | D32: 操作=日志查询 | E32: 1、网元正常启动 2、开启日志服务器并配置三个日志服务器，分别以syslog tcp，syslog udp和restapi方式发送日志 3、配置日志服务器路由可达 | F32: 1、选取系统日志,操作日志,入侵防御日志,防病毒日志,内容过滤日志,文件过滤日志,URL过滤日志,WEB防护日志,防暴力破解日志,弱密码日志,控制策略阻断日志,本地控制策略日志,单包防护日志,Flood攻击日志,黑白名单日志,EDR推广日志,IPSecVPN日志中任意两种以上日志。 2、持续以200条/s的速率向日志侦听端口写入步骤1中选取的日志，使用接口观察日志。【check1】 3、反复${操作}持续时间2小时以上，查询次数超过200次。【check1】【check2】 | G32: 1、【check1】日志写入成功，查询日志与写入的数量和内容一致。 2、【check2】设备CPU、内容、磁盘无异常 | H32: P4 | I32: 性能测试 | J32: 不实现
B33: log.dfx.reliability.info | C33: 验证反复修改${操作}的调试日志功能 | D33: 操作=修改信息收集,开启关闭调试日志,手动信息收集 | E33: 1、网元正常启动 2、开启调试日志 | F33: 1、检查设备调试日志和信息收集功能。【check1】 3、反复${操作}，持续2小时以上，次数超过200次 4、验证调试日志记录和信息收集功能【check1】【chekc2】 | G33: 1、【check1】调试信息记录和信息收集功能正常 3、【check2】设备CPU、内容、磁盘无异常 | H33: P4 | I33: 性能测试 | J33: 不实现
A34: 日志配置存库测试 | B34: 【设计方法】直接设计法
B35: 步骤1:逻辑用例设计
B36: 逻辑用例编号 | C36: 测试用例描述 | F36: 覆盖的测试数据 | G36: 测试数据选取结果
B37: log.dfx.capcity
B38: 步骤2:物理用例设计
B39: 逻辑用例编号 | C39: 用例标题 | D39: 测试数据 | E39: 预置条件 | F39: 测试步骤 | G39: 预期结果 | H39: 优先级 | I39: 测试类型 | J39: 自动化
B40: log.dfx.conf.recover | C40: 验证防火墙${操作}后的日志功能 | D40: 操作=命令重启,掉电重启 | E40: 1、网元正常启动 | F40: 1、配置日志服务器、日志过滤、日志备份（无盘系统不支持不需要配置），日志归并，信息收集方式、日志格式（CLI配置）与默认值不一样 2、验证反复${操作}10次以上。 3、防火墙启动后观察配置【check1】 4、验证日志查询、日志外发、日志备份、日志归并功能【chekc2】 5、验证信息收集功能【check3】 | G40: 1、【check1】日志服务器、日志过滤、日志备份（无盘系统不支持不需要配置），日志归并，信息收集方式、日志格式（CLI配置）的配置与重启前相同。 2、【check2】日志查询、日志外发、日志备份、日志归并功能正常 3、【check3】信息收集功能正常 | H40: P4 | I40: 耦合测试 | J40: 不实现
...

Sheet 日志进程管理
A1: 测试点汇总 | B1: 测试点 | C1: 测试设计方法 | D1: 适用场景 | E1: 用例规模（个） | F1: 测试数据
B2: 进程守护功能测试 | C2: 直接分析 | E2: 4 | F2: kill influxd和dbtask观察日志功能syslogd，logserver
B3: 进程启动 | C3: 直接分析 | E3: 2 | F3: 有盘，无盘
A4: 日志每分钟轮转测试 | B4: 【设计方法】直接设计法
B5: 步骤1:逻辑用例设计
B6: 逻辑用例编号 | C6: 测试用例描述 | F6: 覆盖的测试数据 | G6: 测试数据选取结果
B7: log.dfx.process.guard | C7: 验证${进程名称}进程守护功能 | F7: 进程名称=influxdb,dbtask,logservr | G7: 进程名称=influxdb,dbtask,logservr
B8: 步骤2:物理用例设计
B9: 逻辑用例编号 | C9: 用例标题 | D9: 测试数据 | E9: 预置条件 | F9: 测试步骤 | G9: 预期结果
B10: log.dfx.process.guard | C10: 验证${进程名称}进程守护功能 | D10: 进程名称=influxdb,dbtask,logservr | E10: 1、网元正常启动 | F10: 1、linux后台查看进程启动情况【check1】 2、kill -9 ${进程名称}进程对应的进程号，linux后台查看进程【check2】 3、构造产生任意操作日志，观察日志记录情况。【check3】 4、频繁kill ${进程名称}200次以上，重复步骤2和步骤3。【check2】【check3】 | G10: 1、【check1】${进程名称}进程正常启动 2、【check2】${进程名称}进程在5s内正常启动 3、【check3】操作日志正常记录
A11: 进程启动 | B11: 【设计方法】直接设计法
B12: 步骤1:逻辑用例设计
B13: 逻辑用例编号 | C13: 测试用例描述 | F13: 覆盖的测试数据 | G13: 测试数据选取结果
B14: log.dfx.process.influxdb.startup | C14: 验证influxdb组件在${存储类型}设备上的启动参数 | F14: 存储类型,启动参数,存储 | G14: 存储类型=有存储;启动参数="--bolt-path /appdata/etc/influxd.bolt --engine-path /userdata/influxdbdata/ --http-bind-address 127.0.0.1:8086 --http-idle-timeout 3m0s --http-read-timeout 10s --http-write-timeout 10s --query-memory-bytes 7730941132 --influxql-max-select-point 0";存储=存在软件链接/userdata/userfile/influxTask -> /exdisk/userfile/influxTask和/userdata/influxdbdata -> /exdisk/influxdbdata 存储类型=无存储;启动参数="--bolt-path /appdata/etc/influxd.bolt --engine-path /userdata/influxdbdata/ --http-bind-address 127.0.0.1:8086 --http-idle-timeout 3m0s --http-read-timeout 10s --http-write-timeout 10s --query-memory-bytes 1932735283 --influxql-max-select-point 0";存储=两个文件不存在软链接
B15: 步骤2:物理用例设计
B16: 逻辑用例编号 | C16: 用例标题 | D16: 测试数据 | E16: 预置条件 | F16: 测试步骤 | G16: 预期结果
B17: log.devlog.debug.hour.truncate.trace | C17: 验证influxdb组件在${存储类型}设备上的启动参数 | D17: 存储类型=有存储;启动参数="--bolt-path /appdata/etc/influxd.bolt --engine-path /userdata/influxdbdata/ --http-bind-address 127.0.0.1:8086 --http-idle-timeout 3m0s --http-read-timeout 10s --http-write-timeout 10s --query-memory-bytes 7730941132 --influxql-max-select-point 0";存储=存在软件链接/userdata/userfile/influxTask -> /exdisk/userfile/influxTask和/userdata/influxdbdata -> /exdisk/influxdbdata 存储类型=无存储;启动参数="--bolt-path /appdata/etc/influxd.bolt --engine-path /userdata/influxdbdata/ --http-bind-address 127.0.0.1:8086 --http-idle-timeout 3m0s --http-read-timeout 10s --http-write-timeout 10s --query-memory-bytes 1932735283 --influxql-max-select-point 0";存储=两个文件不存在软链接 | E17: 1、网元正常启动 | F17: 1、使用ps进程观察influxdb的启动参数【check1】 2、在/appdata/etc/agentcfg/supervisor.conf中观察influxdb的启动参数【check1】 3、使用ll观察/userdata/influxdbdata和/userdata/userfile/influxTask目录【check3】 | G17: 1、【check1】启动参数为${启动参数} 2、【check2】${存储}
B18: log.devlog.debug.hour.truncate.trace | C18: 验证瀚高组件在${存储类型}设备上的启动参数 | D18: 存储类型=有存储;启动参数="--bolt-path /appdata/etc/influxd.bolt --engine-path /userdata/influxdbdata/ --http-bind-address 127.0.0.1:8086 --http-idle-timeout 3m0s --http-read-timeout 10s --http-write-timeout 10s --query-memory-bytes 7730941132 --influxql-max-select-point 0";存储=存在软件链接/userdata/userfile/influxTask -> /exdisk/userfile/influxTask和/userdata/influxdbdata -> /exdisk/influxdbdata 存储类型=无存储;启动参数="--bolt-path /appdata/etc/influxd.bolt --engine-path /userdata/influxdbdata/ --http-bind-address 127.0.0.1:8086 --http-idle-timeout 3m0s --http-read-timeout 10s --http-write-timeout 10s --query-memory-bytes 1932735283 --influxql-max-select-point 0";存储=两个文件不存在软链接 | E18: 1、网元正常启动 | F18: 1、使用ps进程观察influxdb的启动参数【check1】 2、在/appdata/etc/agentcfg/supervisor.conf中观察influxdb的启动参数【check1】 3、使用ll观察/userdata/influxdbdata和/userdata/userfile/influxTask目录【check3】 | G18: 1、【check1】启动参数为${启动参数} 2、【check2】${存储}

Sheet 用例全集
A1: 一级目录 | B1: 二级目录 | C1: 三级目录 | D1: 四级目录 | E1: 五级目录 | F1: 用例名称* | G1: 用例编号 | H1: 用例ID* | I1: 用例级别* | J1: 组网描述* | K1: 组网约束 | L1: 预置条件 | M1: 测试步骤* | N1: 预期结果* | O1: 首次创建版本* | P1: 最后变更版本 | Q1: 设备类型* | R1: 关键词 | S1: 测试类型* | T1: 自动化* | U1: 需求编号 | V1: 备注
A2: 管理维护
B3: 监控统计
C4: 日志中心
D5: 日志管理
E6: 防火墙日志
F7: 验证系统日志的写入和查询功能 | G7: log.logmng.put.get.ptc1 | I7: P2 | L7: 网元正常启动 | M7: 1、向防火墙的日志侦听端口写入系统日志，日志中的所有字段均不相同，写入方法参考wiki中的总结文档。 2、在日志中心查询系统日志 3、对比查询到日志的时间与步骤1中写入日志内容【check1】 4、对比查询到日志的日志级别与步骤1中写入日志内容【check1】 5、对比查询到日志的日志描述与步骤1中写入日志内容【check1】 | N7: 1、【check1】查询到的数据与写入的数据完全相同 | O7: TGFW-V6R01C01 | S7: 功能测试 | T7: 待实现
F8: 验证操作日志的写入和查询功能 | G8: log.logmng.put.get.ptc2 | I8: P2 | L8: 网元正常启动 | M8: 1、向防火墙的日志侦听端口写入操作日志，日志中的所有字段均不相同，写入方法参考wiki中的总结文档。 2、在日志中心查询操作日志 3、对比查询到日志的时间与步骤1中写入日志内容【check1】 4、对比查询到日志的日志级别与步骤1中写入日志内容【check1】 5、对比查询到日志的管理员与步骤1中写入日志内容【check1】 6、对比查询到日志的管理员IP与步骤1中写入日志内容【check1】 7、对比查询到日志的日志描述与步骤1中写入日志内容【check1】 | N8: 1、【check1】查询到的数据与写入的数据完全相同 | O8: TGFW-V6R01C01 | S8: 功能测试 | T8: 待实现
F9: 验证入侵防御日志的写入和查询功能 | G9: log.logmng.put.get.ptc3 | I9: P2 | L9: 网元正常启动 | M9: 1、向防火墙的日志侦听端口写入入侵防御日志，日志中的所有字段均不相同，写入方法参考wiki中的总结文档。 2、在日志中心查询入侵防御日志 3、对比查询到日志的时间与步骤1中写入日志内容【check1】 4、对比查询到日志的日志级别与步骤1中写入日志内容【check1】 5、对比查询到日志的源地址与步骤1中写入日志内容【check1】 6、对比查询到日志的源端口与步骤1中写入日志内容【check1】 7、对比查询到日志的目的地址与步骤1中写入日志内容【check1】 8、对比查询到日志的目的端口与步骤1中写入日志内容【check1】 9、对比查询到日志的协议与步骤1中写入日志内容【check1】 10、对比查询到日志的策略ID与步骤1中写入日志内容【check1】 11、对比查询到日志的规则名称与步骤1中写入日志内容【check1】 12、对比查询到日志的命中配置与步骤1中写入日志内容【check1】 13、对比查询到日志的动作与步骤1中写入日志内容【check1】 | N9: 1、【check1】查询到的数据与写入的数据完全相同 | O9: TGFW-V6R01C01 | S9: 功能测试 | T9: 待实现
F10: 验证防病毒日志的写入和查询功能 | G10: log.logmng.put.get.ptc4 | I10: P2 | L10: 网元正常启动 | M10: 1、向防火墙的日志侦听端口写入防病毒日志，日志中的所有字段均不相同，写入方法参考wiki中的总结文档。 2、在日志中心查询防病毒日志 3、对比查询到日志的时间与步骤1中写入日志内容【check1】 4、对比查询到日志的日志级别与步骤1中写入日志内容【check1】 5、对比查询到日志的源地址与步骤1中写入日志内容【check1】 6、对比查询到日志的源端口与步骤1中写入日志内容【check1】 7、对比查询到日志的目的地址与步骤1中写入日志内容【check1】 8、对比查询到日志的目的端口与步骤1中写入日志内容【check1】 9、对比查询到日志的协议与步骤1中写入日志内容【check1】 10、对比查询到日志的策略ID与步骤1中写入日志内容【check1】 11、对比查询到日志的应用类型与步骤1中写入日志内容【check1】 12、对比查询到日志的文件名与步骤1中写入日志内容【check1】 13、对比查询到日志的病毒类型与步骤1中写入日志内容【check1】 14、对比查询到日志的动作与步骤1中写入日志内容【check1】 | N10: 1、【check1】查询到的数据与写入的数据完全相同 | O10: TGFW-V6R01C01 | S10: 功能测试 | T10: 待实现
F11: 验证内容过滤日志的写入和查询功能 | G11: log.logmng.put.get.ptc5 | I11: P2 | L11: 网元正常启动 | M11: 1、向防火墙的日志侦听端口写入内容过滤日志，日志中的所有字段均不相同，写入方法参考wiki中的总结文档。 2、在日志中心查询内容过滤日志 3、对比查询到日志的时间与步骤1中写入日志内容【check1】 4、对比查询到日志的日志级别与步骤1中写入日志内容【check1】 5、对比查询到日志的源地址与步骤1中写入日志内容【check1】 6、对比查询到日志的源端口与步骤1中写入日志内容【check1】 7、对比查询到日志的目的地址与步骤1中写入日志内容【check1】 8、对比查询到日志的目的端口与步骤1中写入日志内容【check1】 9、对比查询到日志的协议与步骤1中写入日志内容【check1】 10、对比查询到日志的策略ID与步骤1中写入日志内容【check1】 11、对比查询到日志的动作与步骤1中写入日志内容【check1】 | N11: 1、【check1】查询到的数据与写入的数据完全相同 | O11: TGFW-V6R01C01 | S11: 功能测试 | T11: 待实现
F12: 验证文件过滤日志的写入和查询功能 | G12: log.logmng.put.get.ptc6 | I12: P2 | L12: 网元正常启动 | M12: 1、向防火墙的日志侦听端口写入文件过滤日志，日志中的所有字段均不相同，写入方法参考wiki中的总结文档。 2、在日志中心查询文件过滤日志 3、对比查询到日志的时间与步骤1中写入日志内容【check1】 4、对比查询到日志的日志级别与步骤1中写入日志内容【check1】 5、对比查询到日志的源地址与步骤1中写入日志内容【check1】 6、对比查询到日志的源端口与步骤1中写入日志内容【check1】 7、对比查询到日志的目的地址与步骤1中写入日志内容【check1】 8、对比查询到日志的目的端口与步骤1中写入日志内容【check1】 9、对比查询到日志的策略ID与步骤1中写入日志内容【check1】 10、对比查询到日志的应用类型与步骤1中写入日志内容【check1】 11、对比查询到日志的文件名与步骤1中写入日志内容【check1】 12、对比查询到日志的动作与步骤1中写入日志内容【check1】 | N12: 1、【check1】查询到的数据与写入的数据完全相同 | O12: TGFW-V6R01C01 | S12: 功能测试 | T12: 待实现
F13: 验证URL过滤日志的写入和查询功能 | G13: log.logmng.put.get.ptc7 | I13: P2 | L13: 网元正常启动 | M13: 1、向防火墙的日志侦听端口写入URL过滤日志，日志中的所有字段均不相同，写入方法参考wiki中的总结文档。 2、在日志中心查询URL过滤日志 3、对比查询到日志的时间与步骤1中写入日志内容【check1】 4、对比查询到日志的日志级别与步骤1中写入日志内容【check1】 5、对比查询到日志的源地址与步骤1中写入日志内容【check1】 6、对比查询到日志的源端口与步骤1中写入日志内容【check1】 7、对比查询到日志的目的地址与步骤1中写入日志内容【check1】 8、对比查询到日志的目的端口与步骤1中写入日志内容【check1】 9、对比查询到日志的协议与步骤1中写入日志内容【check1】 10、对比查询到日志的策略ID与步骤1中写入日志内容【check1】 11、对比查询到日志的动作与步骤1中写入日志内容【check1】 12、对比查询到日志的过滤类型与步骤1中写入日志内容【check1】 | N13: 1、【check1】查询到的数据与写入的数据完全相同 | O13: TGFW-V6R01C01 | S13: 功能测试 | T13: 待实现
F14: 验证WEB防护日志的写入和查询功能 | G14: log.logmng.put.get.ptc8 | I14: P2 | L14: 网元正常启动 | M14: 1、向防火墙的日志侦听端口写入WEB防护日志，日志中的所有字段均不相同，写入方法参考wiki中的总结文档。 2、在日志中心查询WEB防护日志 3、对比查询到日志的时间与步骤1中写入日志内容【check1】 4、对比查询到日志的日志级别与步骤1中写入日志内容【check1】 5、对比查询到日志的源地址与步骤1中写入日志内容【check1】 6、对比查询到日志的源端口与步骤1中写入日志内容【check1】 7、对比查询到日志的目的地址与步骤1中写入日志内容【check1】 8、对比查询到日志的目的端口与步骤1中写入日志内容【check1】 9、对比查询到日志的协议与步骤1中写入日志内容【check1】 10、对比查询到日志的防护类型与步骤1中写入日志内容【check1】 11、对比查询到日志的攻击次数与步骤1中写入日志内容【check1】 12、对比查询到日志的动作与步骤1中写入日志内容【check1】 | N14: 1、【check1】查询到的数据与写入的数据完全相同 | O14: TGFW-V6R01C01 | S14: 功能测试 | T14: 待实现
F15: 验证防暴力破解日志的写入和查询功能 | G15: log.logmng.put.get.ptc9 | I15: P2 | L15: 网元正常启动 | M15: 1、向防火墙的日志侦听端口写入防暴力破解日志，日志中的所有字段均不相同，写入方法参考wiki中的总结文档。 2、在日志中心查询防暴力破解日志 3、对比查询到日志的时间与步骤1中写入日志内容【check1】 4、对比查询到日志的日志级别与步骤1中写入日志内容【check1】 5、对比查询到日志的源地址与步骤1中写入日志内容【check1】 6、对比查询到日志的源端口与步骤1中写入日志内容【check1】 7、对比查询到日志的目的地址与步骤1中写入日志内容【check1】 8、对比查询到日志的目的端口与步骤1中写入日志内容【check1】 9、对比查询到日志的协议与步骤1中写入日志内容【check1】 10、对比查询到日志的动作与步骤1中写入日志内容【check1】 | N15: 1、【check1】查询到的数据与写入的数据完全相同 | O15: TGFW-V6R01C01 | S15: 功能测试 | T15: 待实现
F16: 验证弱密码日志的写入和查询功能 | G16: log.logmng.put.get.ptc10 | I16: P2 | L16: 网元正常启动 | M16: 1、向防火墙的日志侦听端口写入弱密码日志，日志中的所有字段均不相同，写入方法参考wiki中的总结文档。 2、在日志中心查询弱密码日志 3、对比查询到日志的时间与步骤1中写入日志内容【check1】 4、对比查询到日志的日志级别与步骤1中写入日志内容【check1】 5、对比查询到日志的源地址与步骤1中写入日志内容【check1】 6、对比查询到日志的源端口与步骤1中写入日志内容【check1】 7、对比查询到日志的目的地址与步骤1中写入日志内容【check1】 8、对比查询到日志的目的端口与步骤1中写入日志内容【check1】 9、对比查询到日志的协议与步骤1中写入日志内容【check1】 10、对比查询到日志的策略ID与步骤1中写入日志内容【check1】 11、对比查询到日志的配置名称与步骤1中写入日志内容【check1】 12、对比查询到日志的动作与步骤1中写入日志内容【check1】 | N16: 1、【check1】查询到的数据与写入的数据完全相同 | O16: TGFW-V6R01C01 | S16: 功能测试 | T16: 待实现
F17: 验证控制策略阻断日志的写入和查询功能 | G17: log.logmng.put.get.ptc11 | I17: P2 | L17: 网元正常启动 | M17: 1、向防火墙的日志侦听端口写入控制策略阻断日志，日志中的所有字段均不相同，写入方法参考wiki中的总结文档。 2、在日志中心查询控制策略阻断日志 3、对比查询到日志的时间与步骤1中写入日志内容【check1】 4、对比查询到日志的日志级别与步骤1中写入日志内容【check1】 5、对比查询到日志的源地址与步骤1中写入日志内容【check1】 6、对比查询到日志的源端口与步骤1中写入日志内容【check1】 7、对比查询到日志的目的地址与步骤1中写入日志内容【check1】 8、对比查询到日志的目的端口与步骤1中写入日志内容【check1】 9、对比查询到日志的源安全域与步骤1中写入日志内容【check1】 10、对比查询到日志的目的安全域与步骤1中写入日志内容【check1】 11、对比查询到日志的源地区与步骤1中写入日志内容【check1】 12、对比查询到日志的目的与步骤1中写入日志内容【check1】 13、对比查询到日志的应用与步骤1中写入日志内容【check1】 14、对比查询到日志的协议号与步骤1中写入日志内容【check1】 15、对比查询到日志的策略名称与步骤1中写入日志内容【check1】 16、对比查询到日志的动作与步骤1中写入日志内容【check1】 | N17: 1、【check1】查询到的数据与写入的数据完全相同 | O17: TGFW-V6R01C01 | S17: 功能测试 | T17: 待实现
F18: 验证本地控制策略日志的写入和查询功能 | G18: log.logmng.put.get.ptc12 | I18: P2 | L18: 网元正常启动 | M18: 1、向防火墙的日志侦听端口写入本地控制策略日志，日志中的所有字段均不相同，写入方法参考wiki中的总结文档。 2、在日志中心查询本地控制策略日志 3、对比查询到日志的时间与步骤1中写入日志内容【check1】 4、对比查询到日志的日志级别与步骤1中写入日志内容【check1】 5、对比查询到日志的源地址与步骤1中写入日志内容【check1】 6、对比查询到日志的源端口与步骤1中写入日志内容【check1】 7、对比查询到日志的目的地址与步骤1中写入日志内容【check1】 8、对比查询到日志的目的端口与步骤1中写入日志内容【check1】 9、对比查询到日志的源安全域与步骤1中写入日志内容【check1】 10、对比查询到日志的目的安全域与步骤1中写入日志内容【check1】 11、对比查询到日志的源地区与步骤1中写入日志内容【check1】 12、对比查询到日志的目的与步骤1中写入日志内容【check1】 13、对比查询到日志的应用与步骤1中写入日志内容【check1】 14、对比查询到日志的协议号与步骤1中写入日志内容【check1】 15、对比查询到日志的策略名称与步骤1中写入日志内容【check1】 16、对比查询到日志的动作与步骤1中写入日志内容【check1】 | N18: 1、【check1】查询到的数据与写入的数据完全相同 | O18: TGFW-V6R01C01 | S18: 功能测试 | T18: 待实现
... F80: 验证修改系统时间后的日志查询功能 | G80: log.logmng.fliter.systime.ptc1 | I80: P3 | L80: 1、网元正常启动 | M80: 1、防火墙当前时间记为t，向防火墙日志侦听端口写入至少9条系统日志。至少3条日志在防火墙当前时间的前1小时内记为t0~1日志，至少3条仔防火墙当前时间前1~2小时内记为t1~2日志，至少3条仔防火墙当前时间前2~3小时内记为t2~3日志。 2、查询防火墙系统日志，过滤时间为1小时内【check1】【check4】 3、将防火墙的系统时间向后调整1个小时(即为t+1),查询防火墙系统日志，过滤时间为1小时内【check2】【check4】 4、将防火墙的时间向前调整2小时（防火墙时间为t-1），查询防火墙系统日志，过滤时间为1小时内【check3】【check4】 | N80: 1、【check1】防火墙只能查询到t0~1时间段的日志（1小时内的日志） 2、【check2】防火墙查询不到任何日志 3、【check3】防火墙只能查询到t1~2时间段的日志 4、【check4】查询到的日志数量正确，选取首尾和随机条的所有字段正确。 | O80: TGFW-V6R01C01 | S80: 功能测试 | T80: 待实现
E81: 日志归并
F82: 验证入侵防御日志写入时的日志归并功能 | G82: log.logmng.merge.ptc1.001 | I82: P2 | L82: 1、网元正常启动 | M82: 1、开启日志归并，配置日志归并时间为10~60之间的随机值t秒 2、清空入侵防御日志，并查询日志。【check1】 3、在t秒时间内向防火墙的日志侦听端口写入2~200之间任意值n条入侵防御日志，日志除了时间其他内容完全相同 4、使用接口查询入侵防御日志【check2】 | N82: 1、【check1】查询到的日志为空 2、【check2】仅查询到1条入侵防御日志，该日志的攻击次数或者出现次数为n | O82: TGFW-V6R01C01 | S82: 功能测试 | T82: 待实现
F83: 验证防病毒日志写入时的日志归并功能 | G83: log.logmng.merge.ptc1.002 | I83: P2 | L83: 1、网元正常启动 | M83: 1、开启日志归并，配置日志归并时间为10~60之间的随机值t秒 2、清空防病毒日志，并查询日志。【check1】 3、在t秒时间内向防火墙的日志侦听端口写入2~200之间任意值n条防病毒日志，日志除了时间其他内容完全相同 4、使用接口查询防病毒日志【check2】 | N83: 1、【check1】查询到的日志为空 2、【check2】仅查询到1条防病毒日志，该日志的攻击次数或者出现次数为n | O83: TGFW-V6R01C01 | S83: 功能测试 | T83: 待实现
F84: 验证内容过滤日志写入时的日志归并功能 | G84: log.logmng.merge.ptc1.003 | I84: P2 | L84: 1、网元正常启动 | M84: 1、开启日志归并，配置日志归并时间为10~60之间的随机值t秒 2、清空内容过滤日志，并查询日志。【check1】 3、在t秒时间内向防火墙的日志侦听端口写入2~200之间任意值n条内容过滤日志，日志除了时间其他内容完全相同 4、使用接口查询内容过滤日志【check2】 | N84: 1、【check1】查询到的日志为空 2、【check2】仅查询到1条内容过滤日志，该日志的攻击次数或者出现次数为n | O84: TGFW-V6R01C01 | S84: 功能测试 | T84: 待实现
F85: 验证URL过滤日志写入时的日志归并功能 | G85: log.logmng.merge.ptc1.004 | I85: P2 | L85: 1、网元正常启动 | M85: 1、开启日志归并，配置日志归并时间为10~60之间的随机值t秒 2、清空URL过滤日志，并查询日志。【check1】 3、在t秒时间内向防火墙的日志侦听端口写入2~200之间任意值n条URL过滤日志，日志除了时间其他内容完全相同 4、使用接口查询URL过滤日志【check2】 | N85: 1、【check1】查询到的日志为空 2、【check2】仅查询到1条URL过滤日志，该日志的攻击次数或者出现次数为n | O85: TGFW-V6R01C01 | S85: 功能测试 | T85: 待实现
F86: 验证文件过滤日志写入时的日志归并功能 | G86: log.logmng.merge.ptc1.005 | I86: P2 | L86: 1、网元正常启动 | M86: 1、开启日志归并，配置日志归并时间为10~60之间的随机值t秒 2、清空文件过滤日志，并查询日志。【check1】 3、在t秒时间内向防火墙的日志侦听端口写入2~200之间任意值n条文件过滤日志，日志除了时间其他内容完全相同 4、使用接口查询文件过滤日志【check2】 | N86: 1、【check1】查询到的日志为空 2、【check2】仅查询到1条文件过滤日志，该日志的攻击次数或者出现次数为n | O86: TGFW-V6R01C01 | S86: 功能测试 | T86: 待实现
F87: 验证WEB防护日志写入时的日志归并功能 | G87: log.logmng.merge.ptc1.006 | I87: P2 | L87: 1、网元正常启动 | M87: 1、开启日志归并，配置日志归并时间为10~60之间的随机值t秒 2、清空WEB防护日志，并查询日志。【check1】 3、在t秒时间内向防火墙的日志侦听端口写入2~200之间任意值n条WEB防护日志，日志除了时间其他内容完全相同 4、使用接口查询WEB防护日志【check2】 | N87: 1、【check1】查询到的日志为空 2、【check2】仅查询到1条WEB防护日志，该日志的攻击次数或者出现次数为n | O87: TGFW-V6R01C01 | S87: 功能测试 | T87: 待实现
F88: 验证弱密码日志写入时的日志归并功能 | G88: log.logmng.merge.ptc1.007 | I88: P2 | L88: 1、网元正常启动 | M88: 1、开启日志归并，配置日志归并时间为10~60之间的随机值t秒 2、清空弱密码日志，并查询日志。【check1】 3、在t秒时间内向防火墙的日志侦听端口写入2~200之间任意值n条弱密码日志，日志除了时间其他内容完全相同 4、使用接口查询弱密码日志【check2】 | N88: 1、【check1】查询到的日志为空 2、【check2】仅查询到1条弱密码日志，该日志的攻击次数或者出现次数为n | O88: TGFW-V6R01C01 | S88: 功能测试 | T88: 待实现
F89: 验证防暴力破解日志写入时的日志归并功能 | G89: log.logmng.merge.ptc1.008 | I89: P2 | L89: 1、网元正常启动 | M89: 1、开启日志归并，配置日志归并时间为10~60之间的随机值t秒 2、清空防暴力破解日志，并查询日志。【check1】 3、在t秒时间内向防火墙的日志侦听端口写入2~200之间任意值n条防暴力破解日志，日志除了时间其他内容完全相同 4、使用接口查询防暴力破解日志【check2】 | N89: 1、【check1】查询到的日志为空 2、【check2】仅查询到1条防暴力破解日志，该日志的攻击次数或者出现次数为n | O89: TGFW-V6R01C01 | S89: 功能测试 | T89: 待实现
F90: 验证单包防护日志写入时的日志归并功能 | G90: log.logmng.merge.ptc1.009 | I90: P2 | L90: 1、网元正常启动 | M90: 1、开启日志归并，配置日志归并时间为10~60之间的随机值t秒 2、清空单包防护日志，并查询日志。【check1】 3、在t秒时间内向防火墙的日志侦听端口写入2~200之间任意值n条单包防护日志，日志除了时间其他内容完全相同 4、使用接口查询单包防护日志【check2】 | N90: 1、【check1】查询到的日志为空 2、【check2】仅查询到1条单包防护日志，该日志的攻击次数或者出现次数为n | O90: TGFW-V6R01C01 | S90: 功能测试 | T90: 待实现
F91: 验证Flood攻击日志写入时的日志归并功能 | G91: log.logmng.merge.ptc1.010 | I91: P2 | L91: 1、网元正常启动 | M91: 1、开启日志归并，配置日志归并时间为10~60之间的随机值t秒 2、清空Flood攻击日志，并查询日志。【check1】 3、在t秒时间内向防火墙的日志侦听端口写入2~200之间任意值n条Flood攻击日志，日志除了时间其他内容完全相同 4、使用接口查询Flood攻击日志【check2】 | N91: 1、【check1】查询到的日志为空 2、【check2】仅查询到1条Flood攻击日志，该日志的攻击次数或者出现次数为n | O91: TGFW-V6R01C01 | S91: 功能测试 | T91: 待实现
F92: 验证入侵防御日志归并周期为最小值（10s）时的日志归并功能 | G92: log.logmng.merge.porid.min.ptc1.001 | I92: P2 | L92: 1、网元正常启动 | M92: 1、开启日志归并，配置日志归并时间为最小值（10s） 2、清空${有效日志类型}，并查询日志。【check1】 3、在最小值（10s）内向防火墙的日志侦听端口写入2~200之间任意值n1条入侵防御日志，日志的除了时间，其他内容完全相同。 4、使用接口查询入侵防御日志【check2】 5、等待1~3之间非整数倍的归并周期，后再最小值（10s）内向向防火墙的日志侦听端口写入2~200之间任意值n2条入侵防御日志，日志的除了时间，其他内容完全相同。【check3】 | N92: 1、【check1】查询到的日志为空 2、【check2】仅查询到1条${有效日志类型}，该日志的攻击次数或者出现次数为n1 3、【check3】仅查询到2条${有效日志类型}，第二条日志的攻击次数或者出现次数为n2 | O92: TGFW-V6R01C01 | S92: 功能测试 | T92: 待实现
F93: 验证防病毒日志归并周期为默认值（60s）时的日志归并功能 | G93: log.logmng.merge.porid.min.ptc2.001 | I93: P2 | L93: 1、网元正常启动 | M93: 1、开启日志归并，配置日志归并时间为默认值（60s） 2、清空${有效日志类型}，并查询日志。【check1】 3、在默认值（60s）内向防火墙的日志侦听端口写入2~200之间任意值n1条防病毒日志，日志的除了时间，其他内容完全相同。 4、使用接口查询防病毒日志【check2】 5、等待1~3之间非整数倍的归并周期，后再默认值（60s）内向向防火墙的日志侦听端口写入2~200之间任意值n2条防病毒日志，日志的除了时间，其他内容完全相同。【check3】 | N93: 1、【check1】查询到的日志为空 2、【check2】仅查询到1条${有效日志类型}，该日志的攻击次数或者出现次数为n1 3、【check3】仅查询到2条${有效日志类型}，第二条日志的攻击次数或者出现次数为n2 | O93: TGFW-V6R01C01 | S93: 功能测试 | T93: 待实现
... F101: 验证反复修改日志归并周期后的日志归并功能 | G101: log.logmng.merge.fatigue.porid.ptc1 | I101: P4 | L101: 1、网元正常启动 | M101: 1、向防火墙日志侦听端口持续写入入侵防御日志 2、保持日志归并开启，反复修改日志归并周期200次以上， 3、停止持续写入日志，等待日志归并周期时间，后查看入侵防御日志【check1】 4、在日志归并周期内向防火墙日志侦听端口同时写入入侵防御日志，日志数量为1~10的随机值。 5、等待日志归并周期后，查看入侵防御日志。【check2】 | N101: 1、【check1】所有日志正确记录 2、【check2】入侵防御日志的在日志归并周期内只有一条日志，日志的攻击或者出现次数与写入日志条数相同 | O101: TGFW-V6R01C01 | S101: 可靠性测试 | T101: 不实现
E102: 日志清理
F103: 验证系统日志满规格时清理日志功能 | G103: log.logmng.capacity.clear.ptc1.001 | I103: P4 | L103: 1、网元正常启动 | M103: 1、向防火墙的日志侦听端口持续系统日志，日志的产生时间为当前日期0点之前，日志数量大于日志规格的20% 2、下载最新的日志备份文件 3、向防火墙的日志侦听端口持续写入系统日志，日志的产生时间为当天，直到日志数量达到防火墙系统日志的规格。（该时间段的日志数量小于日志容量的80%） 4、使用日志接口查询系统日志，观察日志。【check1】 5、下载最新的日志备份文件，并与步骤3下载的文件对比。【check2】【check3】 | N103: 1、【check1】日志产生时间最早的20%的日志被清理掉。 2、【check2】日志备份文件没有任何变化 3、【check3】不会生成时间戳为系统时间后一天的日志备份文件 | O103: TGFW-V6R01C01 | S103: 可靠性测试 | T103: 不实现
F104: 验证防病毒日志满规格时清理日志功能 | G104: log.logmng.capacity.clear.ptc2.001 | I104: P4 | L104: 1、网元正常启动 | M104: 1、向防火墙的日志侦听端口持续防病毒日志，日志的产生时间为当前日期0点之前，日志数量大于日志规格的20% 2、下载最新的日志备份文件 3、向防火墙的日志侦听端口持续写入防病毒日志，日志的产生时间为当天，直到日志数量达到防火墙防病毒日志的规格。（该时间段的日志数量小于日志容量的80%） 4、使用日志接口查询防病毒日志，观察日志。【check1】 5、下载最新的日志备份文件，并与步骤3下载的文件对比。【check2】【check3】 | N104: 1、【check1】日志产生时间最早的20%的日志被清理掉。 2、【check2】日志备份文件没有任何变化 3、【check3】不会生成时间戳为系统时间后一天的日志备份文件 | O104: TGFW-V6R01C01 | S104: 可靠性测试 | T104: 不实现
F105: 验证URL过滤日志满规格时清理日志功能 | G105: log.logmng.capacity.clear.ptc3.001 | I105: P4 | L105: 1、网元正常启动 | M105: 1、向防火墙的日志侦听端口持续URL过滤日志，日志的产生时间为当前日期0点之前，日志数量大于日志规格的20% 2、下载最新的日志备份文件 3、向防火墙的日志侦听端口持续写入URL过滤日志，日志的产生时间为当天，直到日志数量达到防火墙URL过滤日志的规格。（该时间段的日志数量小于日志容量的80%） 4、使用日志接口查询URL过滤日志，观察日志。【check1】 5、下载最新的日志备份文件，并与步骤3下载的文件对比。【check2】【check3】 | N105: 1、【check1】日志产生时间最早的20%的日志被清理掉。 2、【check2】日志备份文件没有任何变化 3、【check3】不会生成时间戳为系统时间后一天的日志备份文件 | O105: TGFW-V6R01C01 | S105: 可靠性测试 | T105: 不实现
F106: 验证弱密码日志满规格时清理日志功能 | G106: log.logmng.capacity.clear.ptc4.001 | I106: P4 | L106: 1、网元正常启动 | M106: 1、向防火墙的日志侦听端口持续弱密码日志，日志的产生时间为当前日期0点之前，日志数量大于日志规格的20% 2、下载最新的日志备份文件 3、向防火墙的日志侦听端口持续写入弱密码日志，日志的产生时间为当天，直到日志数量达到防火墙弱密码日志的规格。（该时间段的日志数量小于日志容量的80%） 4、使用日志接口查询弱密码日志，观察日志。【check1】 5、下载最新的日志备份文件，并与步骤3下载的文件对比。【check2】【check3】 | N106: 1、【check1】日志产生时间最早的20%的日志被清理掉。 2、【check2】日志备份文件没有任何变化 3、【check3】不会生成时间戳为系统时间后一天的日志备份文件 | O106: TGFW-V6R01C01 | S106: 可靠性测试 | T106: 不实现
F107: 验证单包防护日志满规格时清理日志功能 | G107: log.logmng.capacity.clear.ptc5.001 | I107: P4 | L107: 1、网元正常启动 | M107: 1、向防火墙的日志侦听端口持续单包防护日志，日志的产生时间为当前日期0点之前，日志数量大于日志规格的20% 2、下载最新的日志备份文件 3、向防火墙的日志侦听端口持续写入单包防护日志，日志的产生时间为当天，直到日志数量达到防火墙单包防护日志的规格。（该时间段的日志数量小于日志容量的80%） 4、使用日志接口查询单包防护日志，观察日志。【check1】 5、下载最新的日志备份文件，并与步骤3下载的文件对比。【check2】【check3】 | N107: 1、【check1】日志产生时间最早的20%的日志被清理掉。 2、【check2】日志备份文件没有任何变化 3、【check3】不会生成时间戳为系统时间后一天的日志备份文件 | O107: TGFW-V6R01C01 | S107: 可靠性测试 | T107: 不实现
F108: 验证EDR推广日志满规格时清理日志功能 | G108: log.logmng.capacity.clear.ptc6.001 | I108: P4 | L108: 1、网元正常启动 | M108: 1、向防火墙的日志侦听端口持续EDR推广日志，日志的产生时间为当前日期0点之前，日志数量大于日志规格的20% 2、下载最新的日志备份文件 3、向防火墙的日志侦听端口持续写入EDR推广日志，日志的产生时间为当天，直到日志数量达到防火墙EDR推广日志的规格。（该时间段的日志数量小于日志容量的80%） 4、使用日志接口查询EDR推广日志，观察日志。【check1】 5、下载最新的日志备份文件，并与步骤3下载的文件对比。【check2】【check3】 | N108: 1、【check1】日志产生时间最早的20%的日志被清理掉。 2、【check2】日志备份文件没有任何变化 3、【check3】不会生成时间戳为系统时间后一天的日志备份文件 | O108: TGFW-V6R01C01 | S108: 可靠性测试 | T108: 不实现
...

Sheet 禅道导出
A1: 用例编号 | B1: 所属用例库 | C1: 所属模块 | D1: 相关系统需求SR | E1: 用例标题 | F1: 前置条件 | G1: 步骤 | H1: 预期 | I1: 实际情况 | J1: 关键词 | K1: 优先级 | L1: 用例类型 | M1: 适用阶段 | N1: 用例状态 | O1: 产生Bug数 | P1: 执行结果数 | Q1: 用例步骤数 | R1: 执行人 | S1: 执行时间 | T1: 结果 | U1: 由谁创建 | V1: 创建日期 | W1: 最后修改者 | X1: 修改日期 | Y1: 用例版本 | Z1: 相关用例 | AA1: 最后变更版本 | AB1: 首次创建版本 | AC1: 设备类型 | AD1: 自动化 | AE1: 子状态 | AF1: 用例编号（FSBG） | AG1: 组网编号 | AH1: 附件
A2: 254397 | B2: 明御防火墙_通用(#10) | C2: /管理维护/监控统计/日志中心/日志服务器/日志外发(#19384) | D2: (#0) | E2: 验证日志以syslog方式tcp协议加密发送到日志服务器 | F2: 1、网元正常启动 2、配置静态路由保证日志服务器网络可达 | G2: 1. 配置开启日志服务器，配置日志服务器IP地址，端口为随机端口1~65535，发送方式为syslog,加密方式为加密，发送协议为tcp。 2. 配置日式过滤为发送所有日志 3. 向日志侦听端口写入至少3条系统日志,操作日志,入侵防御日志,防病毒日志,内容过滤日志,文件过滤日志,URL过滤日志,WEB防护日志,防暴力破解日志,弱密码日志,控制策略阻断日志,本地控制策略日志,单包防护日志,Flood攻击日志,黑白名单日志,EDR推广日志,IPSecVPN日志中的任意日志 4. 观察日志服务器上接收到的日志的数量和内容。【check1】【check2】【check3】 | H2: 1. 【check1】日志服务器上接收到的日志数量和内容正确 2. 【check2】日志接受到的源IP、协议、源目的端口、加密信息正确 3. 【check3】接收到的日志发送方式正确 4. | I2: 1. 2. 3. 4. | K2: P2 | L2: 功能测试 | N2: 待评审 | O2: 0 | P2: 0 | Q2: 4 | U2: 赵海波 | V2: 2024-10-22 19:00:11 | Y2: 1 | AB2: TGFW-V6R01C01 | AD2: 待实现
A3: 254398 | B3: 明御防火墙_通用(#10) | C3: /管理维护/监控统计/日志中心/日志服务器/日志外发(#19384) | D3: (#0) | E3: 验证日志以syslog方式tcp协议不加密发送到日志服务器 | F3: 1、网元正常启动 2、配置静态路由保证日志服务器网络可达 | G3: 1. 配置开启日志服务器，配置日志服务器IP地址，端口为常用端口514，发送方式为syslog,加密方式为不加密，发送协议为tcp。 2. 配置日式过滤为发送所有日志 3. 向日志侦听端口写入至少3条系统日志,操作日志,入侵防御日志,防病毒日志,内容过滤日志,文件过滤日志,URL过滤日志,WEB防护日志,防暴力破解日志,弱密码日志,控制策略阻断日志,本地控制策略日志,单包防护日志,Flood攻击日志,黑白名单日志,EDR推广日志,IPSecVPN日志中的任意日志 4. 观察日志服务器上接收到的日志的数量和内容。【check1】【check2】【check3】 | H3: 1. 【check1】日志服务器上接收到的日志数量和内容正确 2. 【check2】日志接受到的源IP、协议、源目的端口、加密信息正确 3. 【check3】接收到的日志发送方式正确 4. | I3: 1. 2. 3. 4. | K3: P2 | L3: 功能测试 | N3: 待评审 | O3: 0 | P3: 0 | Q3: 4 | U3: 赵海波 | V3: 2024-10-22 19:00:11 | Y3: 1 | AB3: TGFW-V6R01C01 | AD3: 待实现
A4: 254399 | B4: 明御防火墙_通用(#10) | C4: /管理维护/监控统计/日志中心/日志服务器/日志外发(#19384) | D4: (#0) | E4: 验证日志以syslog方式udp协议不加密发送到日志服务器 | F4: 1、网元正常启动 2、配置静态路由保证日志服务器网络可达 | G4: 1. 配置开启日志服务器，配置日志服务器IP地址，端口为常用端口1468，发送方式为syslog,加密方式为不加密，发送协议为udp。 2. 配置日式过滤为发送所有日志 3. 向日志侦听端口写入至少3条系统日志,操作日志,入侵防御日志,防病毒日志,内容过滤日志,文件过滤日志,URL过滤日志,WEB防护日志,防暴力破解日志,弱密码日志,控制策略阻断日志,本地控制策略日志,单包防护日志,Flood攻击日志,黑白名单日志,EDR推广日志,IPSecVPN日志中的任意日志 4. 观察日志服务器上接收到的日志的数量和内容。【check1】【check2】【check3】 | H4: 1. 【check1】日志服务器上接收到的日志数量和内容正确 2. 【check2】日志接受到的源IP、协议、源目的端口、加密信息正确 3. 【check3】接收到的日志发送方式正确 4. | I4: 1. 2. 3. 4. | K4: P2 | L4: 功能测试 | N4: 待评审 | O4: 0 | P4: 0 | Q4: 4 | U4: 赵海波 | V4: 2024-10-22 19:00:11 | Y4: 1 | AB4: TGFW-V6R01C01 | AD4: 待实现
A5: 254400 | B5: 明御防火墙_通用(#10) | C5: /管理维护/监控统计/日志中心/日志服务器/日志外发(#19384) | D5: (#0) | E5: 验证日志以restapi方式默认协议加密发送到日志服务器 | F5: 1、网元正常启动 2、配置静态路由保证日志服务器网络可达 | G5: 1. 配置开启日志服务器，配置日志服务器IP地址，端口为知名端口80，发送方式为restapi,加密方式为加密，发送协议为默认。 2. 配置日式过滤为发送所有日志 3. 向日志侦听端口写入至少3条系统日志,操作日志,入侵防御日志,防病毒日志,内容过滤日志,文件过滤日志,URL过滤日志,WEB防护日志,防暴力破解日志,弱密码日志,控制策略阻断日志,本地控制策略日志,单包防护日志,Flood攻击日志,黑白名单日志,EDR推广日志,IPSecVPN日志中的任意日志 4. 观察日志服务器上接收到的日志的数量和内容。【check1】【check2】【check3】 | H5: 1. 【check1】日志服务器上接收到的日志数量和内容正确 2. 【check2】日志接受到的源IP、协议、源目的端口、加密信息正确 3. 【check3】接收到的日志发送方式正确 4. | I5: 1. 2. 3. 4. | K5: P2 | L5: 功能测试 | N5: 待评审 | O5: 0 | P5: 0 | Q5: 4 | U5: 赵海波 | V5: 2024-10-22 19:00:11 | Y5: 1 | AB5: TGFW-V6R01C01 | AD5: 待实现
A6: 254401 | B6: 明御防火墙_通用(#10) | C6: /管理维护/监控统计/日志中心/日志服务器/日志外发(#19384) | D6: (#0) | E6: 验证多种日志并行外发功能 | F6: 1、网元正常启动 2、配置静态路由保证日志服务器网络可达 | G6: 1. 配置开启日志服务器 2. 配置日式过滤为发送所有日志 3. 向日志侦听端口写入至少3条所有类型的日志（包括系统日志,操作日志,入侵防御日志,防病毒日志,内容过滤日志,文件过滤日志,URL过滤日志,WEB防护日志,防暴力破解日志,弱密码日志,控制策略阻断日志,本地控制策略日志,单包防护日志,Flood攻击日志,黑白名单日志,EDR推广日志,IPSecVPN日志） 4. 观察日志服务器上接收到的日志的数量和内容。【check1】 | H6: 1. 【check1】日志服务器上接收到的日志数量和内容正确 2. 3. 4. | I6: 1. 2. 3. 4. | K6: P3 | L6: 功能测试 | N6: 待评审 | O6: 0 | P6: 0 | Q6: 4 | U6: 赵海波 | V6: 2024-10-22 19:00:11 | Y6: 1 | AB6: TGFW-V6R01C01 | AD6: 不实现
A7: 254402 | B7: 明御防火墙_通用(#10) | C7: /管理维护/监控统计/日志中心/日志服务器/日志外发(#19384) | D7: (#0) | E7: 验证多种日志并行外发到多个服务器功能 | F7: 1、网元正常启动 2、配置静态路由保证日志服务器网络可达 | G7: 1. 配置开启日志服务器，配置三个服务器，三个服务器路由均可达，3个日志服务器发送的一个发送方式为restAPI，一个为syslog的TCP，一个为syslog的UDP方式 2. 配置日式过滤为发送所有日志 3. 向日志侦听端口写入至少3条所有类型的日志（包括系统日志,操作日志,入侵防御日志,防病毒日志,内容过滤日志,文件过滤日志,URL过滤日志,WEB防护日志,防暴力破解日志,弱密码日志,控制策略阻断日志,本地控制策略日志,单包防护日志,Flood攻击日志,黑白名单日志,EDR推广日志,IPSecVPN日志） 4. 观察日志服务器上接收到的日志的数量和内容。【check1】【check2】 | H7: 1. 【check1】三个日志服务器上接收到的日志数量和内容正确 2. 【check2】三个日志服务器上接收到日志的发送方式和协议正确 3. 4. | I7: 1. 2. 3. 4. | K7: P3 | L7: 功能测试 | N7: 待评审 | O7: 0 | P7: 0 | Q7: 4 | U7: 赵海波 | V7: 2024-10-22 19:00:11 | Y7: 1 | AB7: TGFW-V6R01C01 | AD7: 不实现
A8: 254403 | B8: 明御防火墙_通用(#10) | C8: /管理维护/监控统计/日志中心/日志服务器/日志外发(#19384) | D8: (#0) | E8: 验证日志外发服务器地址变化时的可靠性 | F8: 1、网元正常启动 2、配置静态路由保证日志服务器网络可达 | G8: 1. 配置开启日志服务器 2. 配置日式过滤为发送所有日志 3. 持续向日志侦听端口写入多种类型的日志 4. 构造${连接}大于200次，在日志服务器上观察日志接收。【check1】 | H8: 1. 【check1】日志服务器上接收到的日志数量和内容正确 2. 3. 4. | I8: 1. 2. 3. 4. | K8: P4 | L8: 可靠性测试 | N8: 待评审 | O8: 0 | P8: 0 | Q8: 4 | U8: 赵海波 | V8: 2024-10-22 19:00:11 | Y8: 1 | AB8: TGFW-V6R01C01 | AD8: 不实现
A9: 254404 | B9: 明御防火墙_通用(#10) | C9: /管理维护/监控统计/日志中心/日志服务器/日志外发(#19384) | D9: (#0) | E9: 验证日志外发路由震荡时的可靠性 | F9: 1、网元正常启动 2、配置静态路由保证日志服务器网络可达 | G9: 1. 配置开启日志服务器 2. 配置日式过滤为发送所有日志 3. 持续向日志侦听端口写入多种类型的日志 4. 构造${连接}大于200次，在日志服务器上观察日志接收。【check1】 | H9: 1. 【check1】日志服务器上接收到的日志数量和内容正确 2. 3. 4. | I9: 1. 2. 3. 4. | K9: P4 | L9: 可靠性测试 | N9: 待评审 | O9: 0 | P9: 0 | Q9: 4 | U9: 赵海波 | V9: 2024-10-22 19:00:11 | Y9: 1 | AB9: TGFW-V6R01C01 | AD9: 不实现
A10: 254405 | B10: 明御防火墙_通用(#10) | C10: /管理维护/监控统计/日志中心/日志服务器/日志外发(#19384) | D10: (#0) | E10: 验证日志外发接口禁用启用时的可靠性 | F10: 1、网元正常启动 2、配置静态路由保证日志服务器网络可达 | G10: 1. 配置开启日志服务器 2. 配置日式过滤为发送所有日志 3. 持续向日志侦听端口写入多种类型的日志 4. 构造${连接}大于200次，在日志服务器上观察日志接收。【check1】 | H10: 1. 【check1】日志服务器上接收到的日志数量和内容正确 2. 3. 4. | I10: 1. 2. 3. 4. | K10: P4 | L10: 可靠性测试 | N10: 待评审 | O10: 0 | P10: 0 | Q10: 4 | U10: 赵海波 | V10: 2024-10-22 19:00:11 | Y10: 1 | AB10: TGFW-V6R01C01 | AD10: 不实现
A11: 254406 | B11: 明御防火墙_通用(#10) | C11: /管理维护/监控统计/日志中心/日志服务器/日志外发(#19384) | D11: (#0) | E11: 验证日志外发tcp连接状态震荡时的可靠性 | F11: 1、网元正常启动 2、配置静态路由保证日志服务器网络可达 | G11: 1. 配置开启日志服务器 2. 配置日式过滤为发送所有日志 3. 持续向日志侦听端口写入多种类型的日志 4. 构造${连接}大于200次，在日志服务器上观察日志接收。【check1】 | H11: 1. 【check1】日志服务器上接收到的日志数量和内容正确 2. 3. 4. | I11: 1. 2. 3. 4. | K11: P4 | L11: 可靠性测试 | N11: 待评审 | O11: 0 | P11: 0 | Q11: 4 | U11: 赵海波 | V11: 2024-10-22 19:00:11 | Y11: 1 | AB11: TGFW-V6R01C01 | AD11: 不实现
