Workbook

Sheet 首页
C4: NGFW V60R001C00 HA特性测试用例
C15: 拟定 | D15: 赵海波 | F15: 日期 | G15: 44764
C17: 审核 | F17: 日期 | G17: XXXX/XX/XX
C19: 批准 | F19: 日期
E23: 修订记录
C25: 日期 | D25: 修订版本 | E25: 修改记录 | I25: 修改人
C26: 44764 | D26: V1.0 | E26: 初稿输出 | I26: 赵海波

Sheet 测试点分析
A1: 四级目录 | B1: 五级目录 | C1: 测试点 | D1: 测试设计方法 | E1: 适用场景 | F1: 用例规模（个） | G1: 测试数据
A2: 配置管理
B3: 接口配置
C4: 接口带宽增加测试 | D4: 等价类划分&数据组合 | F4: 4 | G4: 接口、带宽、繁忙阈值、空闲阈值
C5: 接口带宽修改测试 | D5: 等价类划分&数据组合 | F5: 4 | G5: 接口、带宽、繁忙阈值、空闲阈值
C6: 接口带宽删除和批量删除测试 | D6: 直接分析 | F6: 2 | G6: 删除、批量删除
C7: 接口带宽的查询和分页查询测试 | D7: 直接分析 | F7: 2 | G7: 查询、分页查询
C8: 接口带宽容量测试 | D8: 直接分析 | F8: 1
C9: 接口带宽的Oplog测试 | D9: 直接分析 | F9: 1
C10: 接口带宽配置限制测试 | D10: 直接分析 | F10: 5 | G10: 物理接口,子接口、聚合口、bvi接口、隧道口
C11: 接口带宽配置响应时间测试 | D11: 直接分析 | F11: 1
C12: 接口带宽校验测试 | D12: 直接分析 | F12: 5 | G12: 物理口、子接口、bvi、聚合口、隧道口
B13: 通道配置
C14: 通道增加测试 | D14: 等价类划分&数据组合 | F14: 19 | G14: 名称、模式、上行最大带宽、上行保障带宽、下行最大带宽、下行保障带宽、上行总额、下行总额、最大连接数、新建连接速率）、限流对象、单用户配置（上行最大带宽、上行保障带宽、下行最大带宽、下行保障带宽、上行总额、下行总额、最大连接数、新建连接速率）
C15: 通道修改测试 | D15: 等价类划分&数据组合 | F15: 19 | G15: 名称、模式、上行最大带宽、上行保障带宽、下行最大带宽、下行保障带宽、上行总额、下行总额、最大连接数、新建连接速率）、限流对象、单用户配置（上行最大带宽、上行保障带宽、下行最大带宽、下行保障带宽、上行总额、下行总额、最大连接数、新建连接速率）
C16: 通道删除和批量删除测试 | D16: 直接分析 | F16: 2
C17: 通道查询和分页查询测试 | D17: 直接分析 | F17: 2
C18: 通道容量测试 | D18: 直接分析 | F18: 1
C19: 通道Oplog测试 | D19: 直接分析 | F19: 1
C20: 通道配置限制测试 | D20: 直接分析 | F20: 2 | G20: 被应用和取消引用
C21: 通道配置响应时间测试 | D21: 直接分析 | F21: 1
B22: 策略配置
C23: 带宽策略增加测试 | D23: 等价类划分&数据组合 | F23: 13 | G23: 状态、名称、上行接口、下行接口、原地址、源地址组、目的地址、目的地址组、服务、服务组、时间对象、通道
C24: 带宽策略修改测试 | D24: 等价类划分&数据组合 | F24: 13 | G24: 状态、名称、上行接口、下行接口、原地址、源地址组、目的地址、目的地址组、服务、服务组、时间对象、通道
C25: 带宽策略删除和批量删除测试 | D25: 直接分析 | F25: 2
C26: 带宽策略查询和分页查询测试 | D26: 直接分析 | F26: 2
C27: 带宽策略容量测试 | D27: 直接分析 | F27: 1
C28: 带宽策略Oplog测试 | D28: 直接分析 | F28: 1
C29: 带宽策略优先级调整测试 | D29: 直接分析 | F29: 2 | G29: 被调整ID、方式、目标ID
C30: 带宽策略优先级调整Oplog | D30: 直接分析 | F30: 1
C31: 带宽策略配置限制测试 | D31: 直接分析 | F31: 6 | G31: 带宽限制（带宽和），接口限制（物理接口,子接口、聚合口、bvi接口、隧道口）
C32: 策略与对象耦合测试 | D32: 直接分析 | F32: 6 | G32: 地址、地址组、服务、服务组、时间对象、安全域
C33: 策略优先级调整限制测试 | D33: 直接分析 | F33: 1 | G33: put
C34: 策略配置响应时间测试 | D34: 直接分析 | F34: 1
C35: 接口引用测试 | D35: 直接分析 | F35: 5 | G35: 物理口、子接口、bvi、聚合口、隧道口
A36: 流量策略
B37: 策略匹配
C38: 单策略单条件匹配测试 | D38: 等价类划分&数据组合 | F38: 10 | G38: 源接口、源安全域、源地址、目的接口、目的安全与、目的地址、服务、时间、应用、用户
C39: 单策略多条件匹配测试 | D39: 等价类划分&数据组合 | F39: 5 | G39: 源接口、源安全域、源地址、目的接口、目的安全与、目的地址、服务、时间、应用、用户
C40: 多策略单条件匹配测试 | D40: 等价类划分&数据组合 | F40: 4 | G40: 包含关系、交叉关系、冲突、半闭区间（上点匹配）、完全无包含关系
...

Sheet 测试组网设计
A1: 名称 | B1: NE1_link0
A2: 组网图
A23: 名称 | B23: NE1_ins
A24: 组网图
A45: 名称 | B45: NE1_link4_ins
A46: 组网图
A67: 名称 | B67: NE4_link5_ins
A68: 组网图

Sheet 接口配置
A1: 测试点汇总 | B1: 测试点 | C1: 测试设计方法 | D1: 适用场景 | E1: 用例规模（个） | F1: 测试数据
B2: 接口带宽增加测试 | C2: 等价类划分&数据组合 | E2: 4 | F2: 接口、带宽、繁忙阈值、空闲阈值
B3: 接口带宽修改测试 | C3: 等价类划分&数据组合 | E3: 4 | F3: 接口、带宽、繁忙阈值、空闲阈值
B4: 接口带宽删除和批量删除测试 | C4: 直接分析 | E4: 2 | F4: 删除、批量删除
B5: 接口带宽的查询和分页查询测试 | C5: 直接分析 | E5: 2 | F5: 查询、分页查询
B6: 接口带宽容量测试 | C6: 直接分析 | E6: 1
B7: 接口带宽的Oplog测试 | C7: 直接分析 | E7: 1
B8: 接口带宽配置限制测试 | C8: 直接分析 | E8: 5 | F8: 物理接口,子接口、聚合口、bvi接口、隧道口
B9: 接口带宽配置响应时间测试 | C9: 直接分析 | E9: 1
B10: 接口带宽校验测试 | C10: 直接分析 | E10: 5 | F10: 物理口、子接口、bvi、聚合口、隧道口（与开发确认暂时不做）
A11: 接口带宽增加测试 | B11: 【设计方法】等价类划分&数据组合
B12: 步骤1:等价类划分
B13: 等价类划分 | C13: 测试数据 | D13: 有效类 | E13: 无效类 | F13: 选取策略 | G13: 选取结果
C14: 接口 | D14: 任意物理接口 | E14: 管理口 | F14: 数据名称和分类独立 | G14: 数据名称=接口;有效值=任意物理接口,任意聚合口;无效值=管理口,子接口,bvi口,隧道口,聚合口的成员口,任意不存在的接口名称,空
D15: 任意聚合口 | E15: 子接口
E16: bvi口
E17: 隧道口
E18: 聚合口的成员口
E19: 任意不存在的接口名称
E20: 空
C21: 总带宽 | D21: 10 | E21: 9 | F21: 数据名称和分类独立 | G21: 数据名称=总带宽;有效值=10,20000,10-20000间任意10的整数倍;无效值=9,20001,空,超长字符串,其他任意非法字符串,非数字,空
D22: 20000 | E22: 20001
D23: 10-20000间任意10的整数倍 | E23: 空
E24: 超长字符串
E25: 其他任意非法字符串
E26: 非数字
C27: 繁忙阈值 | D27: 20 | E27: 10 | F27: 数据名称和分类独立 | G27: 数据名称=繁忙阈值;有效值=20,90,20-90间任意10的整数倍;无效值=10,100,繁忙阈值小于空闲阈值,繁忙阈值等于空闲阈值,20-90间任意非10的整数倍,空,非数字
D28: 90 | E28: 100
D29: 20-90间任意10的整数倍 | E29: 繁忙阈值小于空闲阈值
E30: 繁忙阈值等于空闲阈值
E31: 20-90间任意非10的整数倍
E32: 空
E33: 非数字
C34: 空闲阈值 | D34: 10 | E34: 0 | F34: 数据名称和分类独立 | G34: 数据名称=空闲阈值;有效值=10,80,10-80间任意10的整数倍;无效值=0,90,空闲阈值大于繁忙阈值,空闲阈值等于于繁忙阈值,10-80间任意非10的整数倍,空,非数字
D35: 80 | E35: 90
D36: 10-80间任意10的整数倍 | E36: 空闲阈值大于繁忙阈值
E37: 空闲阈值等于于繁忙阈值
E38: 10-80间任意非10的整数倍
E39: 空
E40: 非数字
...

Sheet 通道配置
A1: 测试点汇总 | B1: 测试点 | C1: 测试设计方法 | D1: 适用场景 | E1: 用例规模（个） | F1: 测试数据
B2: 通道增加测试 | C2: 等价类划分&数据组合 | E2: 19 | F2: 名称、模式、上行最大带宽、上行保障带宽、下行最大带宽、下行保障带宽、上行总额、下行总额、最大连接数、新建连接速率）、限流对象、单用户配置（上行最大带宽、上行保障带宽、下行最大带宽、下行保障带宽、上行总额、下行总额、最大连接数、新建连接速率）
B3: 通道修改测试 | C3: 等价类划分&数据组合 | E3: 19 | F3: 名称、模式、上行最大带宽、上行保障带宽、下行最大带宽、下行保障带宽、上行总额、下行总额、最大连接数、新建连接速率）、限流对象、单用户配置（上行最大带宽、上行保障带宽、下行最大带宽、下行保障带宽、上行总额、下行总额、最大连接数、新建连接速率）
B4: 通道删除和批量删除测试 | C4: 直接分析 | E4: 2
B5: 通道查询和分页查询测试 | C5: 直接分析 | E5: 2
B6: 通道容量测试 | C6: 直接分析 | E6: 1
B7: 通道Oplog测试 | C7: 直接分析 | E7: 1
B8: 通道配置限制测试 | C8: 直接分析 | E8: 2 | F8: 被应用和取消引用
B9: 通道配置响应时间测试 | C9: 直接分析 | E9: 1
A10: 通道新增测试 | B10: 【设计方法】等价类划分&数据组合
B11: 步骤1:等价类划分
B12: 等价类划分 | C12: 测试数据 | D12: 有效类 | E12: 无效类 | F12: 选取策略 | G12: 选取结果
C13: 名称 | D13: 1个字符 | E13: 0个字符 | F13: 数据名称和分类独立 | G13: 数据名称=名称;有效值=1个字符,31个字符,1-31任意个字符;无效值=0个字符,32个字符,空,已存在的任意名称
D14: 31个字符 | E14: 32个字符
D15: 1-31任意个字符 | E15: 空
E16: 已存在的任意名称
C17: 通道模式 | D17: 独享 | E17: 其他任意非法字符串 | F17: 数据名称和分类独立 | G17: 数据名称=通道模式;有效值=独享,共享;无效值=其他任意非法字符串,空,超长字符串
D18: 共享 | E18: 空
E19: 超长字符串
C20: 上行最大带宽 | D20: 0 | E20: 1 | F20: 数据名称和分类独立 | G20: 数据名称=上行最大带宽;有效值=0,60,200000000,60-200000000间任意值,最大带宽等于保障带宽;无效值=1,-1,59,200000001,上行最大带宽小于上行保障带宽,非数字,空
D21: 60 | E21: -1
D22: 200000000 | E22: 59
D23: 60-200000000间任意值 | E23: 200000001
D24: 最大带宽等于保障带宽 | E24: 上行最大带宽小于上行保障带宽
E25: 非数字
E26: 空
C27: 上行保障带宽 | D27: 0 | E27: 1 | F27: 数据名称和分类独立 | G27: 数据名称=上行保障带宽;有效值=0,60,200000000,60-200000000间任意值,保障带宽等于最大带宽;无效值=1,-1,59,200000000,上行保障带宽大于上行最大带宽,非数字,空
D28: 60 | E28: -1
D29: 200000000 | E29: 59
D30: 60-200000000间任意值 | E30: 200000000
D31: 保障带宽等于最大带宽 | E31: 上行保障带宽大于上行最大带宽
E32: 非数字
E33: 空
C34: 下行最大带宽 | D34: 0 | E34: 1 | F34: 数据名称和分类独立 | G34: 数据名称=下行最大带宽;有效值=0,60,200000000,60-200000000间任意值,最大带宽等于保障带宽;无效值=1,-1,59,200000001,下行最大带宽小于下行保障带宽,非数字,空
D35: 60 | E35: -1
D36: 200000000 | E36: 59
D37: 60-200000000间任意值 | E37: 200000001
D38: 最大带宽等于保障带宽 | E38: 下行最大带宽小于下行保障带宽
E39: 非数字
E40: 空
...

Sheet 策略配置
A1: 测试点汇总 | B1: 测试点 | C1: 测试设计方法 | D1: 适用场景 | E1: 用例规模（个） | F1: 测试数据
B2: 带宽策略增加测试 | C2: 等价类划分&数据组合 | E2: 13 | F2: 状态、名称、上行接口、下行接口、原地址、源地址组、目的地址、目的地址组、服务、服务组、时间对象、通道
B3: 带宽策略修改测试 | C3: 等价类划分&数据组合 | E3: 13 | F3: 状态、名称、上行接口、下行接口、原地址、源地址组、目的地址、目的地址组、服务、服务组、时间对象、通道
B4: 带宽策略删除和批量删除测试 | C4: 直接分析 | E4: 2
B5: 带宽策略查询和分页查询测试 | C5: 直接分析 | E5: 2
B6: 带宽策略批量启用和禁用测试 | C6: 直接分析 | E6: 1
B7: 带宽策略容量测试 | C7: 直接分析 | E7: 1
B8: 带宽策略Oplog测试 | C8: 直接分析 | E8: 1
B9: 带宽策略优先级调整测试 | C9: 直接分析 | E9: 2 | F9: 被调整ID、方式、目标ID
B10: 带宽策略优先级调整Oplog | C10: 直接分析 | E10: 1
B11: 带宽策略配置限制测试 | C11: 直接分析 | E11: 6 | F11: 带宽限制（带宽和），接口限制（物理接口,子接口、聚合口、bvi接口、隧道口）
B12: 策略与对象耦合测试 | C12: 直接分析 | E12: 6 | F12: 地址、地址组、服务、服务组、时间对象、安全域
B13: 策略优先级调整限制测试 | C13: 直接分析 | E13: 1 | F13: put
B14: 策略配置响应时间测试 | C14: 直接分析 | E14: 1
B15: 接口引用测试 | C15: 直接分析 | E15: 5 | F15: 物理口、子接口、bvi、聚合口、隧道口不支持
A16: 带宽策略增加测试 | B16: 【设计方法】等价类划分&数据组合
B17: 步骤1:等价类划分
B18: 等价类划分 | C18: 测试数据 | D18: 有效类 | E18: 无效类 | F18: 选取策略 | G18: 选取结果
C19: 状态 | D19: 启用 | E19: 其他任意非法字符串 | F19: 数据名称和分类独立 | G19: 数据名称=状态;有效值=启用,禁用;无效值=其他任意非法字符串,空,超长字符串
D20: 禁用 | E20: 空
E21: 超长字符串
C22: 策略名称 | D22: 1个字符 | E22: 0个字符 | F22: 数据名称和分类独立 | G22: 数据名称=名称;有效值=1个字符,31个字符,1-31任意个字符;无效值=0个字符,32个字符,空,名称已存在
D23: 31个字符 | E23: 32个字符
D24: 1-31任意个字符 | E24: 名称已存在
E25: 空
C26: 上行接口 | D26: 任意物理接口 | E26: 管理口 | F26: 数据名称和分类独立 | G26: 数据名称=上行接口;有效值=任意物理接口,任意聚合口,上行接口与下行接口相同;无效值=管理口,子接口,bvi口,隧道口,聚合口的成员口,任意不存在的接口名称,空
D27: 任意聚合口 | E27: 子接口
D28: 上行接口与下行接口相同 | E28: bvi口
E29: 隧道口
E30: 聚合口的成员口
E31: 任意不存在的接口名称
E32: 空
C33: 下行接口 | D33: 任意物理接口 | E33: 管理口 | F33: 数据名称和分类独立 | G33: 数据名称=下行接口;有效值=任意物理接口,任意聚合口,下行接口与上行接口相同;无效值=管理口,子接口,bvi口,隧道口,聚合口的成员口,任意不存在的接口名称,空
D34: 任意聚合口 | E34: 子接口
D35: 下行接口与上行接口相同 | E35: bvi口
E36: 隧道口
E37: 聚合口的成员口
E38: 任意不存在的接口名称
E39: 空
C40: 源地址 | D40: any | E40: 空 | F40: 数据名称和分类独立 | G40: 数据名称=源地址;有效值=any,已存在地址对象名称,多个地址对象共存;无效值=空,不存在的地址对象名称,any和单个对象同时存在,64字节字符串
...

Sheet 策略匹配
A1: 测试点汇总 | B1: 测试点 | C1: 测试设计方法 | D1: 适用场景 | E1: 用例规模（个） | F1: 测试数据
B2: 单策略单条件匹配测试 | C2: 等价类划分&数据组合 | E2: 10 | F2: 源接口、源安全域、源地址、目的接口、目的安全与、目的地址、服务、时间、应用、用户
B3: 单策略多条件匹配测试 | C3: 等价类划分&数据组合 | E3: 5 | F3: 源接口、源安全域、源地址、目的接口、目的安全与、目的地址、服务、时间、应用、用户
B4: 多策略单条件匹配测试 | C4: 等价类划分&数据组合 | E4: 4 | F4: 包含关系、交叉关系、冲突、半闭区间（上点匹配）、完全无包含关系
B5: 多策略多条件匹配测试 | C5: 等价类划分&数据组合 | E5: 4 | F5: 包含关系、交叉关系、冲突、半闭区间（上点匹配）、完全无包含关系
B6: 对象修改策略匹配生效测试 | C6: 直接分析 | E6: 6 | F6: 安全域、地址、地址组、服务、服务组、时间对象
B7: 策略匹配容量测试 | C7: 直接分析 | E7: 1
A8: Ipv4单策略单条件匹配测试 | B8: 【设计方法】等价类划分&数据组合
B9: 步骤1:等价类划分
B10: 等价类划分 | C10: 测试数据 | D10: 有效类 | E10: 无效类 | F10: 选取策略 | G10: 选取结果
C11: 匹配对象 | D11: 入接口 | F11: 选取数据不分类 | G11: 匹配对象=入接口,出接口,源地址,源地址组,目的地址,目的地址组,服务,服务组,用户,应用,时间对象
D12: 出接口
D13: 入安全域
D14: 出安全域
D15: 源地址
D16: 源地址组
D17: 目的地址
D18: 目的地址组
D19: 服务
D20: 服务组
D21: 用户
D22: 应用
D23: 时间对象
B24: 步骤2:数据组合
B25: 数据组合 | C25: 测试数据 | D25: 数据取值 | E25: 发生组合的数据 | F25: 约束条件&选取策略 | G25: 组合结果
C26: 所有数据不组合
B27: 步骤2:逻辑用例设计
B28: 逻辑用例编号 | C28: 测试用例描述 | F28: 覆盖的测试数据 | G28: 测试数据选取结果
B29: Qos.ipv4.match.1p1c.intf.same | C29: 验证IPv4带宽策略出入接口不同时策略匹配功能 | F29: 匹配对象 | G29: 匹配对象=入接口和出接口不同
B30: Qos.ipv4.match.1p1c.intf.different | C30: 验证IPv4带宽策略出入接口相同时策略匹配功能 | F30: 匹配对象 | G30: 匹配对象=入接口和出接口相同
B31: Qos.ipv4.match.1p1c.domain.same | C31: 验证IPv4带宽策略出入安全域不同时策略匹配功能 | F31: 匹配对象 | G31: 匹配对象=出入安全域相同
B32: Qos.ipv4.match.1p1c.domain.different | C32: 验证IPv4带宽策略出入安全域相同时策略匹配功能 | F32: 匹配对象 | G32: 匹配对象=出入安全域不相同
B33: Qos.ipv4.match.1p1c.intf.domain.norelative | C33: 验证IPv4带宽策略出入安全域不同时策略匹配功能 | F33: 匹配对象 | G33: 匹配对象=出入端分别为安全域和接口
B34: Qos.ipv4.match.1p1c.intf.domain.contain | C34: 验证IPv4带宽策略出入安全域相同时策略匹配功能 | F34: 匹配对象 | G34: 匹配对象=出入端分别为安全域和安全域包含的接口
B35: Qos.ipv4.match.1p1c.optional | C35: 验证IPv4带宽策略单策略匹配${匹配对象}功能 | F35: 匹配对象 | G35: 匹配对象=源地址,源地址组,目的地址,目的地址组,服务,服务组,时间对象
B36: 步骤3:物理用例设计
B37: 逻辑用例编号 | C37: 用例标题 | D37: 测试数据 | E37: 预置条件 | F37: 测试步骤 | G37: 预期结果
B38: Qos.ipv4.match.1p1c.intf.different | C38: 验证IPv4带宽策略${匹配对象}时策略匹配功能 | D38: 匹配对象=入接口和出接口不同 | E38: 1、网元正常启动 | F38: 1、在网元上选取任意两个以上的接口（记为port1，port2，port3）配置二层转发或者路由转发 2、在port1和port2上配置带宽策略，仅匹配接口其他参数均为any，引用Qos通道的上下行限制最大带宽。 3、在Port1和Port2之间双向发送五元组变化的流量，流量大于通道的最大带宽，观察流量。【check1】 4、在Port3与Port1之间双向发送大于通道最大带宽的流量。【check2】 5、在Port3与Port2之间双向发送大于通道最大带宽的流量。【check2】 | G38: 【check1】上行流量按照通道上行最大带宽通过，下行流量按照下行流量的最大带宽通过。 【check2】流量不受影响带宽通道的最大带宽限制。
B39: Qos.ipv4.match.1p1c.intf.same | C39: 验证IPv4带宽策略${匹配对象}时策略匹配功能 | D39: 匹配对象=入接口和出接口相同 | E39: 1、网元正常启动 | F39: 1、在网元上选取任意两个接口（记为port1，port2）配置路由转发，其中Port1上配置单臂路由转发 2、在port1配置带宽策略（出入接口均为port1），仅匹配接口其他参数均为any，引用Qos通道的上下行限制最大带宽。 3、在Port1上内双向发送流量形成单臂转发，流量大于通道的最大带宽，观察流量。【check1】 4、在Port1与Port2之间双向发送大于通道最大带宽的流量。【check2】 | G39: 【check1】上行流量按照通道上行最大带宽通过，下行流量按照下行流量的最大带宽通过。 【check2】流量不受影响带宽通道的最大带宽限制。
B40: Qos.ipv4.match.1p1c.domain.different | C40: 验证IPv4带宽策略${匹配对象}时策略匹配功能 | D40: 匹配对象=出入安全域不同 | E40: 1、网元正常启动 | F40: 1、在网元上选取任意1个或多个接口创建两个安全域（记为Domain1、Domain2和Domain3，三个域之间不包含相同的接口）并在安全域内的接口上配置二层转发或者路由转发。选取另外的接口配置安全域 2、在Domain1和Domain2上配置带宽策略，仅匹配接口其他参数均为any，引用Qos通道的上下行限制最大带宽。 3、在Domain1和Domain2之间双向发送五元组变化的流量，流量大于通道的最大带宽，观察流量。【check1】 4、在Domain3与Domain1之间双向发送大于通道最大带宽的流量。【check2】 5、在Domain3与Domain2之间双向发送大于通道最大带宽的流量。【check2】 | G40: 【check1】上行流量按照通道上行最大带宽通过，下行流量按照下行流量的最大带宽通过。 【check2】流量不受影响带宽通道的最大带宽限制。
...

Sheet 匹配优先级
A1: 测试点汇总 | B1: 测试点 | C1: 测试设计方法 | D1: 适用场景 | E1: 用例规模（个） | F1: 测试数据
B2: Qos策略匹配优先级测试 | C2: 直接分析 | E2: 2 | F2: 默认不匹配、按照顺序匹配
B3: Qos策略优先级调整测试 | C3: 直接分析 | E3: 4 | F3: 策略最前、指定ID之前、指定ID之后、策略最后
A4: Qos策略匹配优先级测试 | B4: 【设计方法】直接设计法
B5: 步骤1:逻辑用例设计
B6: 逻辑用例编号 | C6: 测试用例描述 | F6: 覆盖的测试数据 | G6: 测试数据选取结果
B7: Qos.match.pri | C7: 验证带宽策略顺序匹配功能 | F7: 匹配优先级 | G7: 匹配优先级=顺序匹配
B8: 步骤2:物理用例设计
B9: 逻辑用例编号 | C9: 用例标题 | D9: 测试数据 | E9: 预置条件 | F9: 测试步骤 | G9: 预期结果
B10: Qos.ipv4.match.pri | C10: 验证IPv4带宽策略从上往下顺序匹配功能 | D10: 匹配优先级=顺序匹配 | E10: 1、网元正常启动 2、在网元上选取任意两个接口（记为port1，port2）配置二层转发或者路由转发 | F10: 1、在网元上创建三个对象其中C1包含C2，C2包含C3。同时配置三条带宽通道，三条带宽通道的最大带宽均不相同。 2、在port1和port2上配置三条带宽策略，分别引用C1,C2和C3。其中带宽策略C1在最前面，C2在中间，C3在最后. 3、在Port1和Port2之间双向发送匹配C3的流量流量，流量大于通道的最大带宽，观察流量。【check1】 4、不停止流量禁用C1策略，观察流量。【check2】 5、不停止流量禁用C2策略，观察流量。【check3】 6、不停止流量禁用C3策略，观察流量。【check4】 | G10: 【check1】上下行流量按照C1引用的带宽通道的最大带宽通过。 【check2】上下行流量按照C2引用的带宽通道的最大带宽通过。 【check3】上下行流量按照C3引用的带宽通道的最大带宽通过。 【check4】流量不受影响带宽通道的最大带宽限制。
B11: Qos.ipv6.match.pri | C11: 验证IPv6带宽策略从上往下顺序匹配功能 | D11: 匹配优先级=顺序匹配 | E11: 1、网元正常启动 2、在网元上选取任意两个接口（记为port1，port2）配置二层转发或者路由转发 | F11: 1、在网元上创建三个对象其中C1包含C2，C2包含C3。同时配置三条带宽通道，三条带宽通道的最大带宽均不相同。 2、在port1和port2上配置三条带宽策略，分别引用C1,C2和C3。其中带宽策略C1在最前面，C2在中间，C3在最后. 3、在Port1和Port2之间双向发送匹配C3的流量流量，流量大于通道的最大带宽，观察流量。【check1】 4、不停止流量禁用C1策略，观察流量。【check2】 5、不停止流量禁用C2策略，观察流量。【check3】 6、不停止流量禁用C3策略，观察流量。【check4】 | G11: 【check1】上下行流量按照C1引用的带宽通道的最大带宽通过。 【check2】上下行流量按照C2引用的带宽通道的最大带宽通过。 【check3】上下行流量按照C3引用的带宽通道的最大带宽通过。 【check4】流量不受影响带宽通道的最大带宽限制。
A12: Qos策略优先级调整测试 | B12: 【设计方法】直接设计法
B13: 步骤1:逻辑用例设计
B14: 逻辑用例编号 | C14: 测试用例描述 | F14: 覆盖的测试数据 | G14: 测试数据选取结果
B15: Qos.match.pri.put | C15: 验证带宽策略优先级调整到${调整方式}的匹配功能 | F15: 调整方式 | G15: 调整方式=策略最前、指定ID之前、指定ID之后、策略最后
B16: 步骤2:物理用例设计
B17: 逻辑用例编号 | C17: 用例标题 | D17: 测试数据 | E17: 预置条件 | F17: 测试步骤 | G17: 预期结果
B18: Qos.IPv4.match.pri.put | C18: 验证IPv4带宽策略优先级调整到${调整方式}的匹配功能 | D18: 调整方式=策略最前,指定ID之前,指定ID之后,策略最后 | E18: 1、网元正常启动 2、在网元上选取任意两个接口（记为port1，port2）配置二层转发或者路由转发 | F18: 1、网元上配置超过10个带宽通道，通道的上下行最大带宽都不相同 2、在port1和port2上配置超过10条带宽策略，引用步骤1中配置的${调整方式}，他参数均为any，引用Qos通道的上下行限制最大带宽。 3、在Port1和Port2之间双向发送五元组变化的流量，流量大于通道的最大带宽，观察流量。【check1】 4、不停止流量修改带宽策略，使其不再匹配该流量，观察流量。【check2】 | G18: 【check1】上行流量按照通道上行最大带宽通过，下行流量按照下行流量的最大带宽通过。 【check2】流量不受影响带宽通道的最大带宽限制。
B19: Qos.IPv6.match.pri.put | C19: 验证IPv6带宽策略优先级调整到${调整方式}的匹配功能 | D19: 调整方式=策略最前,指定ID之前,指定ID之后,策略最后 | E19: 1、网元正常启动 2、在网元上选取任意两个接口（记为port1，port2）配置二层转发或者路由转发 | F19: 1、网元上配置超过10个带宽通道，通道的上下行最大带宽都不相同 2、在port1和port2上配置超过10条带宽策略，引用步骤1中配置的${调整方式}，他参数均为any，引用Qos通道的上下行限制最大带宽。 3、在Port1和Port2之间双向发送五元组变化的流量，流量大于通道的最大带宽，观察流量。【check1】 4、不停止流量修改带宽策略，使其不再匹配该流量，观察流量。【check2】 | G19: 【check1】上行流量按照通道上行最大带宽通过，下行流量按照下行流量的最大带宽通过。 【check2】流量不受影响带宽通道的最大带宽限制。

Sheet 策略分析
A1: 测试点汇总 | B1: 测试点 | C1: 测试设计方法 | D1: 适用场景 | E1: 用例规模（个） | F1: 测试数据
B2: 带宽策略分析测试 | C2: 直接分析 | E2: 7 | F2: 冲突策略、冗余策略、隐藏策略、可合并策略、空策略、过期策略、忽略策略
A3: 带宽策略分析测试 | B3: 【设计方法】直接设计法
B4: 步骤1:逻辑用例设计
B5: 逻辑用例编号 | C5: 测试用例描述 | F5: 覆盖的测试数据 | G5: 测试数据选取结果
B6: Qos.conf.analyze | C6: 验证带宽策略${数据名称}分析功能 | F6: 冲突策略、冗余策略、隐藏策略、可合并策略、空策略、过期策略、忽略策略、禁用策略和未命中策略 | G6: 测试数据=冲突策略,冗余策略,隐藏策略,可合并策略,空策略,过期策略,忽略策略,禁用策略,未命中策略
B7: 步骤2:物理用例设计
B8: 逻辑用例编号 | C8: 用例标题 | D8: 测试数据 | E8: 预置条件 | F8: 测试步骤 | G8: 预期结果
B9: ACL.conf.analy.004 | C9: 验证带宽策略${数据名称}分析功能 | D9: 数据名称=冲突策略,冗余策略,隐藏策略,可合并策略,空策略,过期策略,忽略策略,禁用策略,未命中策略 | E9: 网元正常启动 | F9: 1、在网元上添加多个带宽策略形成${数据名称}【check1】 2、打开策略分析开关，其余值为默认值【check2】 3、查看策略分析结果。【check3】 | G9: 【check1】添加成功 【check2】配置成功 【check3】查询结果返回${数据名称}与配置的相同

Sheet 带宽保障
A1: 测试点汇总 | B1: 测试点 | C1: 测试设计方法 | D1: 适用场景 | E1: 用例规模（个） | F1: 测试数据
B2: 独占通道保障带宽测试 | C2: 等价类划分&数据组合 | E2: 2 | F2: 上行、下行
B3: 共享通道保障带宽测试 | C3: 等价类划分&数据组合 | E3: 2 | F3: 上行、下行
B4: 独占和共享带宽共存时保障带宽测试 | C4: 等价类划分&数据组合 | E4: 3 | F4: 上行、下行
B5: 保障带宽定时启停功能测试 | C5: 直接分析 | E5: 1 | F5: 上行、下行
B6: 保障带宽阈值启停功能测试 | C6: 直接分析 | E6: 1 | F6: 上行、下行
B7: 保障带宽和最大带宽混合使用 | C7: 直接分析 | E7: 1
B8: 不同模式下下接口的匹配和限速 | C8: 直接分析 | E8: 3 | F8: 交换、路由、接口对、二层（带IP和不带IP）、接口对、IPv4
B9: 不同接口类型的带宽限制功能 | C9: 直接分析 | E9: 5 | F9: 物理接口、子接口、bvi接口、聚合口、隧道接口（封装和净荷报文计算）
B10: 拥塞时的协议报文转发 | C10: 直接分析 | E10: 6 | F10: ARP、ND、PPPoE、DHCP、DNS、管理报文（不支持）
B11: 丢弃报文不占用带宽 | C11: 直接分析 | E11: 2 | F11: 黑白名单、安全策略
B12: 出口拥塞测试 | C12: 直接分析 | E12: 2 | F12: 上行拥塞测试、下行拥塞测试(已覆盖)
B13: 带宽保障配置顺序测试 | C13: 直接分析 | E13: 2 | F13: 先配接口带宽、先配策略和通道
B14: 带宽限制精度测试 | C14: 直接分析 | E14: 2 | F14: 最小值，最大值
A15: IPv4独占通道保障带宽测试 | B15: 【设计方法】等价类划分&数据组合
B16: 步骤1:等价类划分
B17: 等价类划分 | C17: 测试数据 | D17: 有效类 | E17: 无效类 | F17: 选取策略 | G17: 选取结果
C18: 方向 | D18: 入接口到出接口 | F18: 选取数据不分类 | G18: 方向=入接口到出接口,出接口到入接口
D19: 出接口到入接口
B20: 步骤2:数据组合
B21: 数据组合 | C21: 测试数据 | D21: 数据取值 | E21: 发生组合的数据 | F21: 约束条件&选取策略 | G21: 组合结果
C22: 所有数据不组合
B23: 步骤2:逻辑用例设计
B24: 逻辑用例编号 | C24: 测试用例描述 | F24: 覆盖的测试数据 | G24: 测试数据选取结果
B25: Qos.ipv4.cir.sole.forward.intfs | C25: 验证IPv4独占通道不同接口间${方向}方向带宽保障功能 | F25: 方向 | G25: 方向=入接口到出接口
B26: Qos.ipv4.cir.sole.forward.intf | C26: 验证IPv4独占通道单臂路由${方向}方向带宽保障功能 | F26: 方向 | G26: 方向=入接口到出接口
B27: Qos.ipv4.cir.sole.reverse.intfs | C27: 验证IPv4独占通道不同接口间${方向}方向带宽保障功能 | F27: 方向 | G27: 方向=出接口到入接口
B28: Qos.ipv4.cir.sole.reverse.intf | C28: 验证IPv4独占通道单臂路由${方向}方向带宽保障功能 | F28: 方向 | G28: 方向=出接口到入接口
B29: 步骤3:物理用例设计
B30: 逻辑用例编号 | C30: 用例标题 | D30: 测试数据 | E30: 预置条件 | F30: 测试步骤 | G30: 预期结果
B31: Qos.ipv4.cir.sole.forward.intfs | C31: 验证IPv4独占通道不同接口间${方向}方向带宽保障功能 | D31: 方向=入接口到出接口 | E31: 1、网元正常启动 2、在网元上选取任意三个接口（记为port1，port2，port3）配置二层转发或者路由转发 | F31: 1、在port1（入）和port2（出）上配置带宽策略，匹配任意参数，引用Qos独占通道保障带宽大于接口带宽的50%。 2、从Port3向Port2发送线速带宽的背景流量。 3、从Port1向Port2发送线速带宽的流量，流量正向匹配带宽策略，观察流量通过情况。【check1】 4、不停止流量，禁用带宽策略，观察流量。【check2】 | G31: 【check1】该流通过的流量大于等于带宽策略引用通道的保障带宽。 【check2】从Port1到Port2的流量不再被保障
B32: Qos.ipv4.cir.sole.forward.intf | C32: 验证IPv4独占通道单臂路由${方向}方向带宽保障功能 | D32: 方向=入接口到出接口 | E32: 1、网元正常启动 2、在网元上选取任意三个接口（记为port1，port2）配置二层转发或者路由转发，其中Port1存在一跳单臂转发的路由 | F32: 1、在port1（出入接口均为Port1）上配置带宽策略，匹配任意参数，引用Qos独占通道保障带宽大于接口带宽的50%。 2、从Port2向Port1发送线速带宽的背景流量。 3、向Port1发送线速带宽的流量形成单臂转发，流量正向匹配带宽策略，观察流量通过情况。【check1】 4、不停止流量，禁用带宽策略，观察流量。【check2】 | G32: 【check1】该流通过的流量大于等于带宽策略引用通道的保障带宽。 【check2】Port1上单臂转发的流量不再被保障
B33: Qos.ipv4.cir.sole.reverse.intfs | C33: 验证IPv4独占通道不同接口间${方向}方向带宽保障功能 | D33: 方向=出接口到入接口 | E33: 1、网元正常启动 2、在网元上选取任意三个接口（记为port1，port2，port3）配置二层转发或者路由转发 | F33: 1、在port1（入）和port2（出）上配置带宽策略，匹配任意参数，引用Qos独占通道保障带宽大于接口带宽的50%。 2、从Port3向Port2发送线速带宽的背景流量。 3、从Port2向Port1发送线速带宽的流量，流量反向匹配带宽策略，观察流量通过情况。（此时无正向会话，必要时可以清除会话）【check2】 4、不停止流量，从Port1向Port2发送正向匹配带宽策略的流量，观察流量。（此时无正向会话，必要时可以清除会话）【check1】 5、不停止流量，禁用带宽策略，观察流量。【check3】 | G33: 【check1】该流通过的流量大于等于带宽策略引用通道的保障带宽。 【check2】从Port1到Port2的流量不再被保障
B34: Qos.ipv4.cir.sole.reverse.intf | C34: 验证IPv4独占通道单臂路由${方向}方向带宽保障功能 | D34: 方向=出接口到入接口 | E34: 1、网元正常启动 2、在网元上选取任意三个接口（记为port1，port2）配置二层转发或者路由转发，其中Port1存在一跳单臂转发的路由 | F34: 1、在port1（出入接口均为Port1）上配置带宽策略，匹配任意参数，引用Qos独占通道保障带宽大于接口带宽的50%。 2、从Port2向Port1发送线速带宽的背景流量。 3、向Port1发送线速带宽的流量形成单臂转发，流量反向匹配带宽策略，观察流量通过情况。【check2】 4、不停止流量，在Port1发送正向匹配带宽策略的流量，形成单臂转发。观察流量。【check1】 5、不停止流量，禁用带宽策略，观察流量。【check2】 | G34: 【check1】该流通过的流量大于等于带宽策略引用通道的保障带宽。 【check2】从Port1到Port2的流量不再被保障
A35: IPv6独占通道保障带宽测试 | B35: 【设计方法】等价类划分&数据组合
B36: 步骤1:等价类划分
B37: 等价类划分 | C37: 测试数据 | D37: 有效类 | E37: 无效类 | F37: 选取策略 | G37: 选取结果
C38: 方向 | D38: 入接口到出接口 | F38: 选取数据不分类 | G38: 方向=入接口到出接口,出接口到入接口
D39: 出接口到入接口
B40: 步骤2:数据组合
...

Sheet 带宽限制
A1: 测试点汇总 | B1: 测试点 | C1: 测试设计方法 | D1: 适用场景 | E1: 用例规模（个） | F1: 测试数据
B2: 独占通道最大带宽限制测试 | C2: 等价类划分&数据组合 | E2: 2 | F2: 上行、下行
B3: 共享通道最大带宽限制测试 | C3: 等价类划分&数据组合 | E3: 2 | F3: 上行、下行
B4: 独占和共享通道共存最大带宽限制测试 | C4: 等价类划分&数据组合 | E4: 3 | F4: 上行、下行
B5: 最大带宽限制启停测试 | C5: 直接分析 | E5: 1 | F5: 上行、下行
B6: 接口带宽限制功能 | C6: 直接分析 | E6: 2 | F6: 物理接口,聚合接口
B7: 最大带宽限制阈值启停测试 | C7: 直接分析 | E7: 1 | F7: 上行、下行（在带宽保障中已覆盖）
A8: 独占通道带宽限制测试 | B8: 【设计方法】等价类划分&数据组合
B9: 步骤1:等价类划分
B10: 等价类划分 | C10: 测试数据 | D10: 有效类 | E10: 无效类 | F10: 选取策略 | G10: 选取结果
C11: 方向 | D11: 入接口到出接口 | F11: 选取数据不分类 | G11: 方向=入接口到出接口,出接口到入接口
D12: 出接口到入接口
B13: 步骤2:数据组合
B14: 数据组合 | C14: 测试数据 | D14: 数据取值 | E14: 发生组合的数据 | F14: 约束条件&选取策略 | G14: 组合结果
C15: 所有数据不组合
B16: 步骤2:逻辑用例设计
B17: 逻辑用例编号 | C17: 测试用例描述 | F17: 覆盖的测试数据 | G17: 测试数据选取结果
B18: Qos.pir.sole.forward.intfs | C18: 验证独占通道不同接口间${方向}方向带宽限制功能 | F18: 方向 | G18: 方向=入接口到出接口
B19: Qos.pir.sole.forward.intf | C19: 验证独占通道单臂路由${方向}方向带宽限制功能 | F19: 方向 | G19: 方向=入接口到出接口
B20: Qos.pir.sole.reverse.intfs | C20: 验证独占通道不同接口间${方向}方向带宽限制功能 | F20: 方向 | G20: 方向=出接口到入接口
B21: Qos.pir.sole.reverse.intf | C21: 验证独占通道单臂路由${方向}方向带宽限制功能 | F21: 方向 | G21: 方向=出接口到入接口
B22: 步骤3:物理用例设计
B23: 逻辑用例编号 | C23: 用例标题 | D23: 测试数据 | E23: 预置条件 | F23: 测试步骤 | G23: 预期结果
B24: Qos.pir.sole.forward.intfs | C24: 验证独占通道不同接口间${方向}方向带宽限制功能 | D24: 方向=入接口到出接口 | E24: 1、网元正常启动 2、在网元上选取任意三个接口（记为port1，port2，port3）配置二层转发或者路由转发 | F24: 1、在port1（入）和port2（出）上配置带宽策略，匹配任意参数，引用Qos独占通道最大带宽小于接口带宽 2、从Port1向Port2发送线速带宽的流量，流量正向匹配带宽策略，观察流量通过情况。【check1】 3、不停止流量，禁用带宽策略，观察流量。【check2】 | G24: 【check1】该流通过的流量等于带宽策略引用通道的最大带宽。 【check2】从Port1到Port2的流量不被限制
B25: Qos.pir.sole.forward.intf | C25: 验证独占通道单臂路由${方向}方向带宽限制功能 | D25: 方向=入接口到出接口 | E25: 1、网元正常启动 2、在网元上选取任意三个接口（记为port1，port2）配置二层转发或者路由转发，其中Port1存在一跳单臂转发的路由 | F25: 1、在port1（出入接口均为Port1）上配置带宽策略，匹配任意参数，引用Qos独占通道最大带宽小于接口带宽 2、向Port1发送线速带宽的流量形成单臂转发，流量正向匹配带宽策略，观察流量通过情况。【check1】 3、不停止流量，禁用带宽策略，观察流量。【check2】 | G25: 【check1】该流通过的流量等于带宽策略引用通道的最大带宽。 【check2】Port1上单臂转发的流量不被限制
B26: Qos.pir.sole.reverse.intfs | C26: 验证独占通道不同接口间${方向}方向带宽限制功能 | D26: 方向=出接口到入接口 | E26: 1、网元正常启动 2、在网元上选取任意三个接口（记为port1，port2，port3）配置二层转发或者路由转发 | F26: 1、在port1（入）和port2（出）上配置带宽策略，匹配任意参数，引用Qos独占通道最大带宽小于接口带宽 2、从Port2向Port1发送线速带宽的流量，流量反向匹配带宽策略，观察流量通过情况。（此时无正向会话，必要时可以清除会话）【check2】 3、不停止流量，从Port1向Port2发送正向匹配带宽策略的流量，观察流量。（此时无正向会话，必要时可以清除会话）【check1】 4、不停止流量，禁用带宽策略，观察流量。【check3】 | G26: 【check1】该流通过的流量等于带宽策略引用通道的最大带宽。 【check2】从Port1到Port2的流量不被限制
B27: Qos.pir.sole.reverse.intf | C27: 验证独占通道单臂路由${方向}方向带宽限制功能 | D27: 方向=出接口到入接口 | E27: 1、网元正常启动 2、在网元上选取任意三个接口（记为port1，port2）配置二层转发或者路由转发，其中Port1存在一跳单臂转发的路由 | F27: 1、在port1（出入接口均为Port1）上配置带宽策略，匹配任意参数，引用Qos独占通道最大带宽小于接口带宽 2、向Port1发送线速带宽的流量形成单臂转发，流量反向匹配带宽策略，观察流量通过情况。【check2】 3、不停止流量，在Port1发送正向匹配带宽策略的流量，形成单臂转发。观察流量。【check1】 4、不停止流量，禁用带宽策略，观察流量。【check2】 | G27: 【check1】该流通过的流量等于带宽策略引用通道的最大带宽。 【check2】从Port1到Port2的流量不被限制
A28: IPv4共享通道带宽限制测试 | B28: 【设计方法】等价类划分&数据组合
B29: 步骤1:等价类划分
B30: 等价类划分 | C30: 测试数据 | D30: 有效类 | E30: 无效类 | F30: 选取策略 | G30: 选取结果
C31: 方向 | D31: 入接口到出接口 | F31: 选取数据不分类 | G31: 方向=入接口到出接口,出接口到入接口
D32: 出接口到入接口
B33: 步骤2:数据组合
B34: 数据组合 | C34: 测试数据 | D34: 数据取值 | E34: 发生组合的数据 | F34: 约束条件&选取策略 | G34: 组合结果
C35: 所有数据不组合
B36: 步骤2:逻辑用例设计
B37: 逻辑用例编号 | C37: 测试用例描述 | F37: 覆盖的测试数据 | G37: 测试数据选取结果
B38: Qos.IPv4.pir.share.forward.intfs | C38: 验证IPv4共享通道不同接口间${方向}方向带宽限制功能 | F38: 方向 | G38: 方向=入接口到出接口
B39: Qos.IPv4.pir.share.forward.intf | C39: 验证IPv4共享通道单臂路由${方向}方向带宽限制功能 | F39: 方向 | G39: 方向=入接口到出接口
B40: Qos.IPv4.pir.share.reverse.intfs | C40: 验证IPv4共享通道不同接口间${方向}方向带宽限制功能 | F40: 方向 | G40: 方向=出接口到入接口
...

Sheet 总额限制
A1: 测试点汇总 | B1: 测试点 | C1: 测试设计方法 | D1: 适用场景 | E1: 用例规模（个） | F1: 测试数据
B2: 独占通道总额限制测试 | C2: 等价类划分&数据组合 | E2: 2 | F2: 上行、下行
B3: 共享通道总额限制测试 | C3: 等价类划分&数据组合 | E3: 3 | F3: 上行、下行
B4: 独占和共享通道共存总额制测试 | C4: 等价类划分&数据组合 | E4: 2 | F4: 上行、下行
B5: 总额限制限制阈值启停测试 | C5: 直接分析 | E5: 1 | F5: 上行、下行
B6: 总额限制启停测试 | C6: 直接分析 | E6: 1 | F6: 上行、下行
B7: 总额限制限制数据清除条件测试 | C7: 直接分析 | E7: 4 | F7: 手动启停、定时启停、阈值启停、会话老化和会话清除不清除
B8: 逻辑口与物理口嵌套匹配后的总额限制和总额限制测试 | C8: 直接分析 | E8: 2 | F8: bvi口与bvi的成员口、隧道口与物理口（不支持逻辑口）
A9: 独占通道总额限制测试 | B9: 【设计方法】等价类划分&数据组合
B10: 步骤1:等价类划分
B11: 等价类划分 | C11: 测试数据 | D11: 有效类 | E11: 无效类 | F11: 选取策略 | G11: 选取结果
C12: 方向 | D12: 入接口到出接口 | F12: 选取数据不分类 | G12: 方向=入接口到出接口,出接口到入接口
D13: 出接口到入接口
B14: 步骤2:数据组合
B15: 数据组合 | C15: 测试数据 | D15: 数据取值 | E15: 发生组合的数据 | F15: 约束条件&选取策略 | G15: 组合结果
C16: 所有数据不组合
B17: 步骤2:逻辑用例设计
B18: 逻辑用例编号 | C18: 测试用例描述 | F18: 覆盖的测试数据 | G18: 测试数据选取结果
B19: Qos.total.sole.forward.intfs | C19: 验证独占通道不同接口间${方向}方向总额限制功能 | F19: 方向 | G19: 方向=入接口到出接口
B20: Qos.total.sole.forward.intf | C20: 验证独占通道单臂路由${方向}方向总额限制功能 | F20: 方向 | G20: 方向=入接口到出接口
B21: Qos.total.sole.reverse.intfs | C21: 验证独占通道不同接口间${方向}方向总额限制功能 | F21: 方向 | G21: 方向=出接口到入接口
B22: Qos.total.sole.reverse.intf | C22: 验证独占通道单臂路由${方向}方向总额限制功能 | F22: 方向 | G22: 方向=出接口到入接口
B23: 步骤3:物理用例设计
B24: 逻辑用例编号 | C24: 用例标题 | D24: 测试数据 | E24: 预置条件 | F24: 测试步骤 | G24: 预期结果
B25: Qos.total.sole.forward.intfs | C25: 验证独占通道不同接口间${方向}方向总额限制功能 | D25: 方向=入接口到出接口 | E25: 1、网元正常启动 2、在网元上选取任意三个接口（记为port1，port2，port3）配置二层转发或者路由转发 | F25: 1、在port1（入）和port2（出）上配置带宽策略，匹配任意参数，引用Qos独占通道配置总额限制 2、从Port1向Port2发送线速带宽的流量，流量正向匹配带宽策略，观察流量通过情况。【check1】 3、不停止流量，禁用带宽策略，观察流量。【check2】 | G25: 【check1】该流通过的流量超过总额限制后会被丢弃。通道记录通过的流量与总额相同。 【check2】从Port1到Port2的流量不被限制
B26: Qos.total.sole.forward.intf | C26: 验证独占通道单臂路由${方向}方向总额限制功能 | D26: 方向=入接口到出接口 | E26: 1、网元正常启动 2、在网元上选取任意三个接口（记为port1，port2）配置二层转发或者路由转发，其中Port1存在一跳单臂转发的路由 | F26: 1、在port1（出入接口均为Port1）上配置带宽策略，匹配任意参数，引用Qos独占通道配置总额限制 2、向Port1发送线速带宽的流量形成单臂转发，流量正向匹配带宽策略，观察流量通过情况。【check1】 3、不停止流量，禁用带宽策略，观察流量。【check2】 | G26: 【check1】该流通过的流量超过总额限制后会被丢弃。通道记录通过的流量与总额相同。 【check2】Port1上单臂转发的流量不被限制
B27: Qos.total.sole.reverse.intfs | C27: 验证独占通道不同接口间${方向}方向总额限制功能 | D27: 方向=出接口到入接口 | E27: 1、网元正常启动 2、在网元上选取任意三个接口（记为port1，port2，port3）配置二层转发或者路由转发 | F27: 1、在port1（入）和port2（出）上配置带宽策略，匹配任意参数，引用Qos独占通道配置总额限制 2、从Port2向Port1发送线速带宽的流量，流量反向匹配带宽策略，观察流量通过情况。（此时无正向会话，必要时可以清除会话）【check2】 3、不停止流量，从Port1向Port2发送正向匹配带宽策略的流量，观察流量。（此时无正向会话，必要时可以清除会话）【check1】 4、不停止流量，禁用带宽策略，观察流量。【check3】 | G27: 【check1】该流通过的流量超过总额限制后会被丢弃。通道记录通过的流量与总额相同。 【check2】从Port1到Port2的流量不被限制
B28: Qos.total.sole.reverse.intf | C28: 验证独占通道单臂路由${方向}方向总额限制功能 | D28: 方向=出接口到入接口 | E28: 1、网元正常启动 2、在网元上选取任意三个接口（记为port1，port2）配置二层转发或者路由转发，其中Port1存在一跳单臂转发的路由 | F28: 1、在port1（出入接口均为Port1）上配置带宽策略，匹配任意参数，引用Qos独占通道配置总额限制 2、向Port1发送线速带宽的流量形成单臂转发，流量反向匹配带宽策略，观察流量通过情况。【check2】 3、不停止流量，在Port1发送正向匹配带宽策略的流量，形成单臂转发。观察流量。【check1】 4、不停止流量，禁用带宽策略，观察流量。【check2】 | G28: 【check1】该流通过的流量超过总额限制后会被丢弃。通道记录通过的流量与总额相同。 【check2】从Port1到Port2的流量不被限制
A29: 共享通道总额限制测试 | B29: 【设计方法】等价类划分&数据组合
B30: 步骤1:等价类划分
B31: 等价类划分 | C31: 测试数据 | D31: 有效类 | E31: 无效类 | F31: 选取策略 | G31: 选取结果
C32: 方向 | D32: 入接口到出接口 | F32: 选取数据不分类 | G32: 方向=入接口到出接口,出接口到入接口
D33: 出接口到入接口
B34: 步骤2:数据组合
B35: 数据组合 | C35: 测试数据 | D35: 数据取值 | E35: 发生组合的数据 | F35: 约束条件&选取策略 | G35: 组合结果
C36: 所有数据不组合
B37: 步骤2:逻辑用例设计
B38: 逻辑用例编号 | C38: 测试用例描述 | F38: 覆盖的测试数据 | G38: 测试数据选取结果
B39: Qos.total.share.forward.intfs | C39: 验证共享通道不同接口间${方向}方向总额限制功能 | F39: 方向 | G39: 方向=入接口到出接口
B40: Qos.total.share.forward.intf | C40: 验证共享通道单臂路由${方向}方向总额限制功能 | F40: 方向 | G40: 方向=入接口到出接口
...

Sheet 连接数量
A1: 测试点汇总 | B1: 测试点 | C1: 测试设计方法 | D1: 适用场景 | E1: 用例规模（个） | F1: 测试数据
B2: 独占通道连接数量限制测试 | C2: 等价类划分&数据组合 | E2: 2 | F2: 上行、下行
B3: 共享通道连接数量限制测试 | C3: 等价类划分&数据组合 | E3: 2 | F3: 上行、下行
B4: 独占和共享通道共存连接数量限制测试 | C4: 等价类划分&数据组合 | E4: 3 | F4: 上行、下行
B5: 连接数量限制阈值启停测试 | C5: 直接分析 | E5: 1 | F5: 上行、下行
B6: 连接数量限制阈值启停测试 | C6: 直接分析 | E6: 1 | F6: 上行、下行
B7: 连接类型限制 | C7: 直接分析 | E7: 2 | F7: 半连接、全连接
B8: 带宽管理混合使用 | C8: 直接分析 | E8: 3 | F8: 连接限制、带宽限制、总额限制
B9: 不同接口模式的连接限制 | C9: 直接分析 | E9: 3 | F9: 交换、路由、接口对、连接数量、新建连接速度
B10: 不同接口类型的连接限制 | C10: 直接分析 | E10: 5 | F10: 物理接口、子接口、bvi接口、聚合口、隧道接口、连接数量、新建连接速度
B11: 连接限制配置顺序测试 | C11: 直接分析 | E11: 2 | F11: 先配qos策略再配接口阈值启停、现配接口阈值启停再配Qos策略
A12: IPv4独占通道连接总数限制测试 | B12: 【设计方法】等价类划分&数据组合
B13: 步骤1:等价类划分
B14: 等价类划分 | C14: 测试数据 | D14: 有效类 | E14: 无效类 | F14: 选取策略 | G14: 选取结果
C15: 方向 | D15: 入接口到出接口 | F15: 选取数据不分类 | G15: 方向=入接口到出接口,出接口到入接口
D16: 出接口到入接口
B17: 步骤2:数据组合
B18: 数据组合 | C18: 测试数据 | D18: 数据取值 | E18: 发生组合的数据 | F18: 约束条件&选取策略 | G18: 组合结果
C19: 所有数据不组合
B20: 步骤2:逻辑用例设计
B21: 逻辑用例编号 | C21: 测试用例描述 | F21: 覆盖的测试数据 | G21: 测试数据选取结果
B22: Qos.IPv4.con.sole.forward.intfs | C22: 验证IPv4独占通道不同接口间${方向}方向连接总数限制功能 | F22: 方向 | G22: 方向=入接口到出接口
B23: Qos.IPv4.con.sole.forward.intf | C23: 验证IPv4独占通道单臂路由${方向}方向连接总数限制功能 | F23: 方向 | G23: 方向=入接口到出接口
B24: Qos.IPv4.con.sole.reverse.intfs | C24: 验证IPv4独占通道不同接口间${方向}方向连接总数限制功能 | F24: 方向 | G24: 方向=出接口到入接口
B25: Qos.IPv4.con.sole.reverse.intf | C25: 验证IPv4独占通道单臂路由${方向}方向连接总数限制功能 | F25: 方向 | G25: 方向=出接口到入接口
B26: 步骤3:物理用例设计
B27: 逻辑用例编号 | C27: 用例标题 | D27: 测试数据 | E27: 预置条件 | F27: 测试步骤 | G27: 预期结果
B28: Qos.IPv4.con.sole.forward.intfs | C28: 验证IPv4独占通道不同接口间${方向}方向连接总数限制功能 | D28: 方向=入接口到出接口 | E28: 1、网元正常启动 2、在网元上选取任意三个接口（记为port1，port2，port3）配置二层转发或者路由转发 | F28: 1、在port1（入）和port2（出）上配置带宽策略，匹配任意参数，引用Qos独占通道配置连接总数限制 2、从Port1向Port2发送线速带宽的流量，流量正向匹配带宽策略，观察流量通过情况。【check1】 3、不停止流量，禁用带宽策略，观察流量。【check2】 | G28: 【check1】该流通过的流量超过连接总数限制后会被丢弃。 【check2】从Port1到Port2的连接总数不被限制
B29: Qos.IPv4.con.sole.forward.intf | C29: 验证IPv4独占通道单臂路由${方向}方向连接总数限制功能 | D29: 方向=入接口到出接口 | E29: 1、网元正常启动 2、在网元上选取任意三个接口（记为port1，port2）配置二层转发或者路由转发，其中Port1存在一跳单臂转发的路由 | F29: 1、在port1（出入接口均为Port1）上配置带宽策略，匹配任意参数，引用Qos独占通道配置连接总数限制 2、向Port1发送线速带宽的流量形成单臂转发，流量正向匹配带宽策略，观察流量通过情况。【check1】 3、不停止流量，禁用带宽策略，观察流量。【check2】 | G29: 【check1】该流通过的流量超过连接总数限制后会被丢弃。 【check2】Port1上单臂转发的连接总数不被限制
B30: Qos.IPv4.con.sole.reverse.intfs | C30: 验证IPv4独占通道不同接口间${方向}方向连接总数限制功能 | D30: 方向=出接口到入接口 | E30: 1、网元正常启动 2、在网元上选取任意三个接口（记为port1，port2，port3）配置二层转发或者路由转发 | F30: 1、在port1（入）和port2（出）上配置带宽策略，匹配任意参数，引用Qos独占通道配置连接总数限制 2、从Port2向Port1发送线速带宽的流量，流量反向匹配带宽策略，观察流量通过情况。（此时无正向会话，必要时可以清除会话）【check2】 3、不停止流量，从Port1向Port2发送正向匹配带宽策略的流量，观察流量。（此时无正向会话，必要时可以清除会话）【check1】 4、不停止流量，禁用带宽策略，观察流量。【check3】 | G30: 【check1】该流通过的流量超过连接总数限制后会被丢弃。 【check2】从Port1到Port2的连接总数不被限制
B31: Qos.IPv4.con.sole.reverse.intf | C31: 验证IPv4独占通道单臂路由${方向}方向连接总数限制功能 | D31: 方向=出接口到入接口 | E31: 1、网元正常启动 2、在网元上选取任意三个接口（记为port1，port2）配置二层转发或者路由转发，其中Port1存在一跳单臂转发的路由 | F31: 1、在port1（出入接口均为Port1）上配置带宽策略，匹配任意参数，引用Qos独占通道配置连接总数限制 2、向Port1发送线速带宽的流量形成单臂转发，流量反向匹配带宽策略，观察流量通过情况。【check2】 3、不停止流量，在Port1发送正向匹配带宽策略的流量，形成单臂转发。观察流量。【check1】 4、不停止流量，禁用带宽策略，观察流量。【check2】 | G31: 【check1】该流通过的流量超过连接总数限制后会被丢弃。 【check2】从Port1到Port2的连接总数不被限制
A32: IPv6独占通道连接总数限制测试 | B32: 【设计方法】等价类划分&数据组合
B33: 步骤1:等价类划分
B34: 等价类划分 | C34: 测试数据 | D34: 有效类 | E34: 无效类 | F34: 选取策略 | G34: 选取结果
C35: 方向 | D35: 入接口到出接口 | F35: 选取数据不分类 | G35: 方向=入接口到出接口,出接口到入接口
D36: 出接口到入接口
B37: 步骤2:数据组合
B38: 数据组合 | C38: 测试数据 | D38: 数据取值 | E38: 发生组合的数据 | F38: 约束条件&选取策略 | G38: 组合结果
C39: 所有数据不组合
B40: 步骤2:逻辑用例设计
...

Sheet 新建速率
A1: 测试点汇总 | B1: 测试点 | C1: 测试设计方法 | D1: 适用场景 | E1: 用例规模（个） | F1: 测试数据
B2: 独占通道新建连接速度限制测试 | C2: 等价类划分&数据组合 | E2: 2 | F2: 上行、下行
B3: 共享通道新建连接速度限制测试 | C3: 等价类划分&数据组合 | E3: 2 | F3: 上行、下行
B4: 独占和共享通道共存新建连接速度限制测试 | C4: 等价类划分&数据组合 | E4: 2 | F4: 上行、下行
B5: 建连接速度限制阈值启停测试 | C5: 直接分析 | E5: 1 | F5: 上行、下行
B6: 建连接速度限制阈值启停测试 | C6: 直接分析 | E6: 1 | F6: 上行、下行
A7: 独占通道新建连接速率限制测试 | B7: 【设计方法】等价类划分&数据组合
B8: 步骤1:等价类划分
B9: 等价类划分 | C9: 测试数据 | D9: 有效类 | E9: 无效类 | F9: 选取策略 | G9: 选取结果
C10: 方向 | D10: 入接口到出接口 | F10: 选取数据不分类 | G10: 方向=入接口到出接口,出接口到入接口
D11: 出接口到入接口
B12: 步骤2:数据组合
B13: 数据组合 | C13: 测试数据 | D13: 数据取值 | E13: 发生组合的数据 | F13: 约束条件&选取策略 | G13: 组合结果
C14: 所有数据不组合
B15: 步骤2:逻辑用例设计
B16: 逻辑用例编号 | C16: 测试用例描述 | F16: 覆盖的测试数据 | G16: 测试数据选取结果
B17: Qos.con.new.sole.forward.intfs | C17: 验证独占通道不同接口间${方向}方向新建连接速率限制功能 | F17: 方向 | G17: 方向=入接口到出接口
B18: Qos.con.new.sole.forward.intf | C18: 验证独占通道单臂路由${方向}方向新建连接速率限制功能 | F18: 方向 | G18: 方向=入接口到出接口
B19: Qos.con.new.sole.reverse.intfs | C19: 验证独占通道不同接口间${方向}方向新建连接速率限制功能 | F19: 方向 | G19: 方向=出接口到入接口
B20: Qos.con.new.sole.reverse.intf | C20: 验证独占通道单臂路由${方向}方向新建连接速率限制功能 | F20: 方向 | G20: 方向=出接口到入接口
B21: 步骤3:物理用例设计
B22: 逻辑用例编号 | C22: 用例标题 | D22: 测试数据 | E22: 预置条件 | F22: 测试步骤 | G22: 预期结果
B23: Qos.con.new.sole.forward.intfs | C23: 验证独占通道不同接口间${方向}方向新建连接速率限制功能 | D23: 方向=入接口到出接口 | E23: 1、网元正常启动 2、在网元上选取任意三个接口（记为port1，port2，port3）配置二层转发或者路由转发 | F23: 1、在port1（入）和port2（出）上配置带宽策略，匹配任意参数，引用Qos独占通道配置新建连接速率限制 2、从Port1向Port2发送线速带宽的流量，流量正向匹配带宽策略，观察流量通过情况。【check1】 3、不停止流量，禁用带宽策略，观察流量。【check2】 | G23: 【check1】该流通过的流量超过新建连接速率限制后会被丢弃。 【check2】从Port1到Port2的新建连接速率不被限制
B24: Qos.con.new.sole.forward.intf | C24: 验证独占通道单臂路由${方向}方向新建连接速率限制功能 | D24: 方向=入接口到出接口 | E24: 1、网元正常启动 2、在网元上选取任意三个接口（记为port1，port2）配置二层转发或者路由转发，其中Port1存在一跳单臂转发的路由 | F24: 1、在port1（出入接口均为Port1）上配置带宽策略，匹配任意参数，引用Qos独占通道配置新建连接速率限制 2、向Port1发送线速带宽的流量形成单臂转发，流量正向匹配带宽策略，观察流量通过情况。【check1】 3、不停止流量，禁用带宽策略，观察流量。【check2】 | G24: 【check1】该流通过的流量超过新建连接速率限制后会被丢弃。 【check2】Port1上单臂转发的新建连接速率不被限制
B25: Qos.con.new.sole.reverse.intfs | C25: 验证独占通道不同接口间${方向}方向新建连接速率限制功能 | D25: 方向=出接口到入接口 | E25: 1、网元正常启动 2、在网元上选取任意三个接口（记为port1，port2，port3）配置二层转发或者路由转发 | F25: 1、在port1（入）和port2（出）上配置带宽策略，匹配任意参数，引用Qos独占通道配置新建连接速率限制 2、从Port2向Port1发送线速带宽的流量，流量反向匹配带宽策略，观察流量通过情况。（此时无正向会话，必要时可以清除会话）【check2】 3、不停止流量，从Port1向Port2发送正向匹配带宽策略的流量，观察流量。（此时无正向会话，必要时可以清除会话）【check1】 4、不停止流量，禁用带宽策略，观察流量。【check3】 | G25: 【check1】该流通过的流量超过新建连接速率限制后会被丢弃。 【check2】从Port1到Port2的新建连接速率不被限制
B26: Qos.con.new.sole.reverse.intf | C26: 验证独占通道单臂路由${方向}方向新建连接速率限制功能 | D26: 方向=出接口到入接口 | E26: 1、网元正常启动 2、在网元上选取任意三个接口（记为port1，port2）配置二层转发或者路由转发，其中Port1存在一跳单臂转发的路由 | F26: 1、在port1（出入接口均为Port1）上配置带宽策略，匹配任意参数，引用Qos独占通道配置新建连接速率限制 2、向Port1发送线速带宽的流量形成单臂转发，流量反向匹配带宽策略，观察流量通过情况。【check2】 3、不停止流量，在Port1发送正向匹配带宽策略的流量，形成单臂转发。观察流量。【check1】 4、不停止流量，禁用带宽策略，观察流量。【check2】 | G26: 【check1】该流通过的流量超过新建连接速率限制后会被丢弃。 【check2】从Port1到Port2的新建连接速率不被限制
A27: IPv4共享通道新建连接速率限制测试 | B27: 【设计方法】等价类划分&数据组合
B28: 步骤1:等价类划分
B29: 等价类划分 | C29: 测试数据 | D29: 有效类 | E29: 无效类 | F29: 选取策略 | G29: 选取结果
C30: 方向 | D30: 入接口到出接口 | F30: 选取数据不分类 | G30: 方向=入接口到出接口,出接口到入接口
D31: 出接口到入接口
B32: 步骤2:数据组合
B33: 数据组合 | C33: 测试数据 | D33: 数据取值 | E33: 发生组合的数据 | F33: 约束条件&选取策略 | G33: 组合结果
C34: 所有数据不组合
B35: 步骤2:逻辑用例设计
B36: 逻辑用例编号 | C36: 测试用例描述 | F36: 覆盖的测试数据 | G36: 测试数据选取结果
B37: Qos.IPv4.con.new.share.forward.intfs | C37: 验证IPv4共享通道不同接口间${方向}方向新建连接速率限制功能 | F37: 方向 | G37: 方向=入接口到出接口
B38: Qos.IPv4.con.new.share.forward.intf | C38: 验证IPv4共享通道单臂路由${方向}方向新建连接速率限制功能 | F38: 方向 | G38: 方向=入接口到出接口
B39: Qos.IPv4.con.new.share.reverse.intfs | C39: 验证IPv4共享通道不同接口间${方向}方向新建连接速率限制功能 | F39: 方向 | G39: 方向=出接口到入接口
B40: Qos.IPv4.con.new.share.reverse.intf | C40: 验证IPv4共享通道单臂路由${方向}方向新建连接速率限制功能 | F40: 方向 | G40: 方向=出接口到入接口
...

Sheet DFS
A1: 测试点汇总 | B1: 测试点 | C1: 测试设计方法 | D1: 适用场景 | E1: 用例规模（个） | F1: 测试数据
B2: Qos升级测试 | C2: 直接分析 | E2: 3 | F2: Qos匹配、带宽和总额限制、连接限制
A3: 升级测试 | B3: 【设计方法】直接设计法
B4: 步骤1:逻辑用例设计
B5: 逻辑用例编号 | C5: 测试用例描述 | F5: 覆盖的测试数据 | G5: 测试数据选取结果
B6: qos.dfs.update | C6: 验证带宽管理升级测试 | F6: 升级 | G6: 升级
B7: 步骤2:物理用例设计
B8: 逻辑用例编号 | C8: 用例标题 | D8: 测试数据 | E8: 预置条件 | F8: 测试步骤 | G8: 预期结果
B9: qos.dfs.update | C9: 验证带宽管理升级测试 | D9: 升级=配置,业务 | E9: 1、网元正常启动 2、配置默认转发策略为允许 | F9: 1、配置物理接口和聚合口上的接口带宽，配置独占通道和共享通道，配置匹配物理接口和物理接口的带宽策略 2、发送背景流量的同时向设备发送匹配带宽策略的流量，观察报文流量【check1】 2、对设备进行升级。升级后观察配置【check2】 3、发送背景流量，同时向设备发送匹配带宽策略的流量，观察报文流量【check1】 4、发送流量同时，在设备增删和修改带宽策略，通道，接口带宽。【check1】 | G9: 【check1】带宽管理的保障带宽，最大带宽，带宽总额，连接总数和新建连接数量与配置值相同。 【check2】升级前后配置相同，且设备无异常
A10: 带宽通道监控测试 | B10: 【设计方法】直接设计法
B11: 步骤1:逻辑用例设计
B12: 逻辑用例编号 | C12: 测试用例描述 | F12: 覆盖的测试数据 | G12: 测试数据选取结果
B13: qos.dfs.mon | C13: 验证带宽管理升级测试 | F13: 升级 | G13: 升级
B14: 步骤2:物理用例设计
B15: 逻辑用例编号 | C15: 用例标题 | D15: 测试数据 | E15: 预置条件 | F15: 测试步骤 | G15: 预期结果
B16: qos.dfs.share.mon | C16: 验证带宽管理${通道类型}${连接类型}的监控功能 | D16: 监控对象=速率,流量,连接数,连接速率,转发报文数,丢包数量;连接类型=全连接,半连接,全连接和半连接混合;通道类型=共享通道 | E16: 1、网元正常启动 2、配置默认转发策略为允许 | F16: 1、配置物理接口和聚合口上的接口带宽，配置${通道类型}，配置匹配物理接口和物理接口的带宽策略 2、发送${连接类型}的流量，观察$[监控对象]【check1】 | G16: 【check1】监控数据与发送的数据相同
B17: qos.dfs.solo.mon | C17: 验证带宽管理${通道类型}${连接类型}的监控功能 | D17: 监控对象=速率,流量,连接数,连接速率,转发报文数,丢包数量;连接类型=全连接,半连接,全连接和半连接混合;通道类型=独占通道 | E17: 1、网元正常启动 2、配置默认转发策略为允许 | F17: 1、配置物理接口和聚合口上的接口带宽，配置${通道类型}，配置匹配物理接口和物理接口的带宽策略 2、发送${连接类型}的流量，观察$[监控对象]【check1】 | G17: 【check1】监控数据与发送的数据相同

Sheet DFR
A1: 测试点汇总 | B1: 测试点 | C1: 测试设计方法 | D1: 适用场景 | E1: 用例规模（个） | F1: 测试数据
B2: Qos可靠性测试 | C2: 直接分析 | E2: 7 | F2: 策略启停、接口带宽、带宽策略、通道配置增删修改、接口Updown、反复修改阈值、反复调整优先级
B3: Qos配置恢复测试 | C3: 直接分析 | E3: 2 | F3: 配置导入导出、重启复位
B4: Qos主备切换测试 | C4: 直接分析 | E4: 3 | F4: 配置同步、带宽限制主备切换、连接限制主备切换
B5: Qos控制会话测试 | C5: 直接分析 | E5: 4 | F5: qos放行、Qos丢弃、策略启停、自动启停
B6: Qos与Nat耦合 | C6: 直接分析 | E6: 2 | F6: snat,dnat
B7: Qos性能测试 | C7: 直接分析 | E7: 2 | F7: 大流量时的吞吐量、大会话量时的吞吐量
B8: 带宽和连接限制接口操作可靠性 | C8: 直接分析 | E8: 4 | F8: 子接口、bvi口、聚合口、隧道口（不支持）
A9: Qos可靠性测试 | B9: 【设计方法】直接设计法
B10: 步骤1:逻辑用例设计
B11: 逻辑用例编号 | C11: 测试用例描述 | F11: 覆盖的测试数据 | G11: 测试数据选取结果
B12: Qos.dfr.operate | C12: 验证带宽管理功能在${操作}后功能正常 | F12: 操作 | G12: 操作=反复启停带宽策略,反复修改接口带宽和阈值,反复修改和增删带宽策略,反复修改引用、修改和增删带宽通道,反复启用禁用接口,反复拔插接口网线或光纤,反复调整带宽策略优先级,反复命令复位重启,反复掉电重启
B13: 步骤2:物理用例设计
B14: 逻辑用例编号 | C14: 用例标题 | D14: 测试数据 | E14: 预置条件 | F14: 测试步骤 | G14: 预期结果
B15: Qos.dfr.operate | C15: 验证带宽管理功能在${操作}后功能正常 | D15: 操作=反复启停带宽策略,反复修改接口带宽和阈值,反复修改和增删带宽策略,反复修改引用、修改和增删带宽通道,反复启用禁用接口,反复拔插接口网线或光纤,反复调整带宽策略优先级,反复命令复位重启,反复掉电重启 | E15: 1、网元正常启动 | F15: 1、选取任意物理口或者聚合口，配置带宽策略和通道，并配置业务 2、在设备发送背景流量的同时发起大量的连接，观察流量和连接。【check1】 3、不停止流量${操作}，观察流量和连接。【check1】 | G15: 【check1】保障带宽、最大带宽、带宽总额、连接总数、新建连接速度限制正常
A16: Qos配置恢复测试 | B16: 【设计方法】直接设计法
B17: 步骤1:逻辑用例设计
B18: 逻辑用例编号 | C18: 测试用例描述 | F18: 覆盖的测试数据 | G18: 测试数据选取结果
B19: Qos.dfr.recover | C19: 验证带宽管理配置导入导出功能 | F19: 操作 | G19: 操作=配置导入导出
B20: 步骤2:物理用例设计
B21: 逻辑用例编号 | C21: 用例标题 | D21: 测试数据 | E21: 预置条件 | F21: 测试步骤 | G21: 预期结果
B22: Qos.dfr.recover | C22: 验证带宽管理配置导入导出功能 | D22: 操作=配置导入导出 | E22: 1、网元正常启动 | F22: 1、配置物理接口和聚合口上的接口带宽，配置独占通道和共享通道，配置匹配物理接口和物理接口的带宽策略 2、发送背景流量的同时向设备发送匹配带宽策略的流量，观察报文流量【check1】 3、对设备进行配置导出。【check2】 4、在设备修改任意带宽管理配置。 4、将步骤2导出的配置导入设备中【check3】【check1】 5、在设备修改任意带宽管理配置。【check1】 | G22: 【check1】保障带宽、最大带宽、带宽总额、连接总数、新建连接速度限制正常 【check2】配置导出成功，检查配置文件符合规范 【check3】配置导入成功，设备的配置如导入的配置完全相同
A23: Qos主备切换测试 | B23: 【设计方法】直接设计法
B24: 步骤1:逻辑用例设计
B25: 逻辑用例编号 | C25: 测试用例描述 | F25: 覆盖的测试数据 | G25: 测试数据选取结果
B26: Qos.dfr.ha.syn | C26: 带宽管理主备同步测试 | F26: 操作 | G26: 操作=配置同步
B27: Qos.dfr.ha.switch | C27: 带宽管理主备业务切换和回切测试 | F27: 操作 | G27: 操作=切换,回切
B28: 步骤2:物理用例设计
B29: 逻辑用例编号 | C29: 用例标题 | D29: 测试数据 | E29: 预置条件 | F29: 测试步骤 | G29: 预期结果
B30: Qos.dfr.ha.syn | C30: 带宽管理主备同步测试 | D30: 操作=配置同步 | E30: 1、网元正常启动 | F30: 1、选取任意物理口或者聚合口，配置接口带宽，带宽通道（1k+）和带宽策略（1K+），并配置业务 2、配置HA，观察主备配置。【check1】【check3】 3、在主机上增删和修改带宽管理配置，观察主备配置。【check2】【check3】 4、触发主备切换，在备升主的设备上增删和修改带宽管理配置。【check2】【check3】 | G30: 【check1】主备之间配置同步正常进行，主备设备间配置完全一致。 【check2】主备间配置正常同步 【check3】etcd查看Qos配置同步成功./etcdctl get / --keys-only --prefix | grep qos 中qos策略，通道和接口带宽均完成同步
B31: Qos.dfr.ha.switch | C31: 带宽管理主备业务切换和回切测试 | D31: 操作=切换,回切 | E31: 1、网元正常启动 | F31: 1、选取任意物理口或者聚合口，配置接口带宽，带宽通道和带宽策略，并配置业务 2、配置HA 3、在设备发送背景流量的同时发起大量的连接，观察流量和连接。【check1】【check2】 4、触发主备切换， 5、在备升主的设备上修改带宽管理的配置。【check1】【check2】 6、触发主备回切。【check1】 | G31: 【check1】保障带宽、最大带宽、带宽总额、连接总数、新建连接速度限制正常 【check2】主备设备间配置正常同步
A32: Qos配置会话控制 | B32: 【设计方法】直接设计法
B33: 步骤1:逻辑用例设计
B34: 逻辑用例编号 | C34: 测试用例描述 | F34: 覆盖的测试数据 | G34: 测试数据选取结果
B35: Qos.dfr.session | C35: 验证带宽管理${操作}会话信息限制正确 | F35: 操作 | G35: 操作=带宽限制,总额限制,连接限制
B36: 步骤2:物理用例设计
B37: 逻辑用例编号 | C37: 用例标题 | D37: 测试数据 | E37: 预置条件 | F37: 测试步骤 | G37: 预期结果
B38: Qos.dfr.session | C38: 验证带宽管理${操作}会话信息限制正确 | D38: 操作=带宽限制,总额限制,连接限制 | E38: 1、网元正常启动 | F38: 1、配置物理接口和聚合口上的接口带宽，配置独占通道和共享通道，配置匹配物理接口和物理接口的带宽策略 2、发送背景流量的同时向设备发送匹配带宽策略的流量，观察报文流量【check1】 3、发送流量使${操作}导致流量丢弃 | G38: 【check1】带宽管理通过的流量，会话显示正常 【check1】${操作}丢弃的流量，会话显示正常
A39: Qos与Nat耦合 | B39: 【设计方法】直接设计法
B40: 步骤1:逻辑用例设计
...

Sheet 用例全集
A1: 一级目录 | B1: 二级目录 | C1: 三级目录 | D1: 四级目录 | E1: 五级目录 | F1: 用例名称* | G1: 用例编号 | H1: 用例ID* | I1: 用例级别* | J1: 组网描述* | K1: 组网约束 | L1: 预置条件 | M1: 测试步骤* | N1: 预期结果* | O1: 适用版本* | P1: 设备类型* | Q1: 单板类型 | R1: 关键词 | S1: 测试类型* | T1: 是否自动化* | U1: 需求编号 | V1: 备注 | W1: 是否完成自动化 | AH1: P1 | AI1: P2 | AJ1: P3 | AK1: P4 | AP1: 接口测试 | AQ1: 功能测试 | AR1: 可靠性测试 | AS1: 性能测试 | AT1: 耦合测试 | AU1: 安装部署 | AV1: 配置相关 | AW1: 安全相关
A2: 高可靠性
B3: 服务质量
C4: 带宽管理
D5: 配置管理
E6: 接口配置
F7: 验证添加QOS接口带宽时接口有效值和无效值测试 | G7: Qos.cfg.intf.post.ptc0 | H7: 2210101 | I7: P1 | L7: 网元正常启动 | M7: 1、使用/api/v1/qosintf接口添加接口带宽时，配置接口为任意物理接口，其他参数为任意有效值,查询接口带宽配置【check1】 2、使用/api/v1/qosintf接口添加接口带宽时，配置接口为任意聚合口，其他参数为任意有效值,查询接口带宽配置【check1】 3、添加接口带宽时，配置接口为管理口，其他参数为任意有效值,查询接口带宽配置【check2】 4、添加接口带宽时，配置接口为子接口，其他参数为任意有效值,查询接口带宽配置【check2】 5、添加接口带宽时，配置接口为bvi口，其他参数为任意有效值,查询接口带宽配置【check2】 6、添加接口带宽时，配置接口为隧道口，其他参数为任意有效值,查询接口带宽配置【check2】 7、添加接口带宽时，配置接口为聚合口的成员口，其他参数为任意有效值,查询接口带宽配置【check2】 8、添加接口带宽时，配置接口为任意不存在的接口名称，其他参数为任意有效值,查询接口带宽配置【check2】 9、添加接口带宽时，配置接口为空，其他参数为任意有效值,查询接口带宽配置【check2】 | N7: 【check1】配置成功，使用restful查询接口带宽配置与下发的配置相同。使用etcd查询接口带宽配置，查询的值与配置的值相同 【check2】配置失败，网元无异常。使用etcd查询接口带宽配置与配置前相同 | O7: NGFW_V60R1C00 | P7: J1900,C236,EP | S7: 接口测试 | T7: 是
F8: 验证添加QOS接口带宽时总带宽有效值和无效值测试 | G8: Qos.cfg.intf.post.ptc1 | H8: 2210102 | I8: P1 | L8: 网元正常启动 | M8: 1、使用/api/v1/qosintf接口添加接口带宽时，配置总带宽为10，其他参数为任意有效值,查询接口带宽配置【check1】 2、使用/api/v1/qosintf接口添加接口带宽时，配置总带宽为20000，其他参数为任意有效值,查询接口带宽配置【check1】 3、使用/api/v1/qosintf接口添加接口带宽时，配置总带宽为10-20000间任意10的整数倍，其他参数为任意有效值,查询接口带宽配置【check1】 4、添加接口带宽时，配置总带宽为9，其他参数为任意有效值,查询接口带宽配置【check2】 5、添加接口带宽时，配置总带宽为20001，其他参数为任意有效值,查询接口带宽配置【check2】 6、添加接口带宽时，配置总带宽为空，其他参数为任意有效值,查询接口带宽配置【check2】 7、添加接口带宽时，配置总带宽为超长字符串，其他参数为任意有效值,查询接口带宽配置【check2】 8、添加接口带宽时，配置总带宽为其他任意非法字符串，其他参数为任意有效值,查询接口带宽配置【check2】 9、添加接口带宽时，配置总带宽为非数字，其他参数为任意有效值,查询接口带宽配置【check2】 | N8: 【check1】配置成功，使用restful查询接口带宽配置与下发的配置相同。使用etcd查询接口带宽配置，查询的值与配置的值相同 【check2】配置失败，网元无异常。使用etcd查询接口带宽配置与配置前相同 | O8: NGFW_V60R1C00 | P8: J1900,C236,EP | S8: 接口测试 | T8: 是
F9: 验证添加QOS接口带宽时繁忙阈值有效值和无效值测试 | G9: Qos.cfg.intf.post.ptc2 | H9: 2210103 | I9: P1 | L9: 网元正常启动 | M9: 1、使用/api/v1/qosintf接口添加接口带宽时，配置繁忙阈值为20，其他参数为任意有效值,查询接口带宽配置【check1】 2、使用/api/v1/qosintf接口添加接口带宽时，配置繁忙阈值为90，其他参数为任意有效值,查询接口带宽配置【check1】 3、使用/api/v1/qosintf接口添加接口带宽时，配置繁忙阈值为20-90间任意10的整数倍，其他参数为任意有效值,查询接口带宽配置【check1】 4、添加接口带宽时，配置繁忙阈值为10，其他参数为任意有效值,查询接口带宽配置【check2】 5、添加接口带宽时，配置繁忙阈值为100，其他参数为任意有效值,查询接口带宽配置【check2】 6、添加接口带宽时，配置繁忙阈值为繁忙阈值小于空闲阈值，其他参数为任意有效值,查询接口带宽配置【check2】 7、添加接口带宽时，配置繁忙阈值为繁忙阈值等于空闲阈值，其他参数为任意有效值,查询接口带宽配置【check2】 8、添加接口带宽时，配置繁忙阈值为20-90间任意非10的整数倍，其他参数为任意有效值,查询接口带宽配置【check2】 9、添加接口带宽时，配置繁忙阈值为空，其他参数为任意有效值,查询接口带宽配置【check2】 10、添加接口带宽时，配置繁忙阈值为非数字，其他参数为任意有效值,查询接口带宽配置【check2】 | N9: 【check1】配置成功，使用restful查询接口带宽配置与下发的配置相同。使用etcd查询接口带宽配置，查询的值与配置的值相同 【check2】配置失败，网元无异常。使用etcd查询接口带宽配置与配置前相同 | O9: NGFW_V60R1C00 | P9: J1900,C236,EP | S9: 接口测试 | T9: 是
F10: 验证添加QOS接口带宽时空闲阈值有效值和无效值测试 | G10: Qos.cfg.intf.post.ptc3 | H10: 2210104 | I10: P1 | L10: 网元正常启动 | M10: 1、使用/api/v1/qosintf接口添加接口带宽时，配置空闲阈值为10，其他参数为任意有效值,查询接口带宽配置【check1】 2、使用/api/v1/qosintf接口添加接口带宽时，配置空闲阈值为80，其他参数为任意有效值,查询接口带宽配置【check1】 3、使用/api/v1/qosintf接口添加接口带宽时，配置空闲阈值为10-80间任意10的整数倍，其他参数为任意有效值,查询接口带宽配置【check1】 4、添加接口带宽时，配置空闲阈值为0，其他参数为任意有效值,查询接口带宽配置【check2】 5、添加接口带宽时，配置空闲阈值为90，其他参数为任意有效值,查询接口带宽配置【check2】 6、添加接口带宽时，配置空闲阈值为空闲阈值大于繁忙阈值，其他参数为任意有效值,查询接口带宽配置【check2】 7、添加接口带宽时，配置空闲阈值为空闲阈值等于于繁忙阈值，其他参数为任意有效值,查询接口带宽配置【check2】 8、添加接口带宽时，配置空闲阈值为10-80间任意非10的整数倍，其他参数为任意有效值,查询接口带宽配置【check2】 9、添加接口带宽时，配置空闲阈值为空，其他参数为任意有效值,查询接口带宽配置【check2】 10、添加接口带宽时，配置空闲阈值为非数字，其他参数为任意有效值,查询接口带宽配置【check2】 | N10: 【check1】配置成功，使用restful查询接口带宽配置与下发的配置相同。使用etcd查询接口带宽配置，查询的值与配置的值相同 【check2】配置失败，网元无异常。使用etcd查询接口带宽配置与配置前相同 | O10: NGFW_V60R1C00 | P10: J1900,C236,EP | S10: 接口测试 | T10: 是
F11: 验证修改QOS接口带宽时ID有效值和无效值测试 | G11: Qos.cfg.intf.put.ptc0 | H11: 2210105 | I11: P1 | L11: 网元正常启动 | M11: 1、使用/api/v1/qosintf接口修改接口带宽时，配置ID为1，其他参数为任意有效值,查询接口带宽配置【check1】 2、使用/api/v1/qosintf接口修改接口带宽时，配置ID为存在的任意ID，其他参数为任意有效值,查询接口带宽配置【check2】 3、修改接口带宽时，配置ID为空，其他参数为任意有效值,查询接口带宽配置【check2】 4、修改接口带宽时，配置ID为0，其他参数为任意有效值,查询接口带宽配置【check2】 5、修改接口带宽时，配置ID为不存在的ID，其他参数为任意有效值,查询接口带宽配置【check2】 6、修改接口带宽时，配置ID为其他任意非法字符串，其他参数为任意有效值,查询接口带宽配置【check2】 | N11: 【check1】配置成功，使用restful查询接口带宽配置与下发的配置相同。使用etcd查询接口带宽配置，查询的值与配置的值相同 【check2】配置失败，网元无异常。使用rest接口和etcd查询接口带宽配置与配置前相同 | O11: NGFW_V60R1C00 | P11: J1900,C236,EP | S11: 接口测试 | T11: 是
F12: 验证修改QOS接口带宽时接口有效值和无效值测试 | G12: Qos.cfg.intf.put.ptc1 | H12: 2210106 | I12: P1 | L12: 网元正常启动 | M12: 1、使用/api/v1/qosintf接口修改接口带宽时，配置接口为任意物理接口，其他参数为任意有效值,查询接口带宽配置【check1】 2、使用/api/v1/qosintf接口修改接口带宽时，配置接口为任意聚合口，其他参数为任意有效值,查询接口带宽配置【check1】 3、修改接口带宽时，配置接口为管理口，其他参数为任意有效值,查询接口带宽配置【check2】 4、修改接口带宽时，配置接口为子接口，其他参数为任意有效值,查询接口带宽配置【check2】 5、修改接口带宽时，配置接口为bvi口，其他参数为任意有效值,查询接口带宽配置【check2】 6、修改接口带宽时，配置接口为隧道口，其他参数为任意有效值,查询接口带宽配置【check2】 7、修改接口带宽时，配置接口为聚合口的成员口，其他参数为任意有效值,查询接口带宽配置【check2】 8、修改接口带宽时，配置接口为任意不存在的接口名称，其他参数为任意有效值,查询接口带宽配置【check2】 9、修改接口带宽时，配置接口为空，其他参数为任意有效值,查询接口带宽配置【check2】 | N12: 【check1】配置成功，使用restful查询接口带宽配置与下发的配置相同。使用etcd查询接口带宽配置，查询的值与配置的值相同 【check2】配置失败，网元无异常。使用rest接口和etcd查询接口带宽配置与配置前相同 | O12: NGFW_V60R1C00 | P12: J1900,C236,EP | S12: 接口测试 | T12: 是
F13: 验证修改QOS接口带宽时总带宽有效值和无效值测试 | G13: Qos.cfg.intf.put.ptc2 | H13: 2210107 | I13: P1 | L13: 网元正常启动 | M13: 1、使用/api/v1/qosintf接口修改接口带宽时，配置总带宽为10，其他参数为任意有效值,查询接口带宽配置【check1】 2、使用/api/v1/qosintf接口修改接口带宽时，配置总带宽为20000，其他参数为任意有效值,查询接口带宽配置【check1】 3、使用/api/v1/qosintf接口修改接口带宽时，配置总带宽为10-20000间任意10的整数倍，其他参数为任意有效值,查询接口带宽配置【check1】 4、修改接口带宽时，配置总带宽为9，其他参数为任意有效值,查询接口带宽配置【check2】 5、修改接口带宽时，配置总带宽为20001，其他参数为任意有效值,查询接口带宽配置【check2】 6、修改接口带宽时，配置总带宽为空，其他参数为任意有效值,查询接口带宽配置【check2】 7、修改接口带宽时，配置总带宽为超长字符串，其他参数为任意有效值,查询接口带宽配置【check2】 8、修改接口带宽时，配置总带宽为其他任意非法字符串，其他参数为任意有效值,查询接口带宽配置【check2】 9、修改接口带宽时，配置总带宽为非数字，其他参数为任意有效值,查询接口带宽配置【check2】 | N13: 【check1】配置成功，使用restful查询接口带宽配置与下发的配置相同。使用etcd查询接口带宽配置，查询的值与配置的值相同 【check2】配置失败，网元无异常。使用rest接口和etcd查询接口带宽配置与配置前相同 | O13: NGFW_V60R1C00 | P13: J1900,C236,EP | S13: 接口测试 | T13: 是
F14: 验证修改QOS接口带宽时繁忙阈值有效值和无效值测试 | G14: Qos.cfg.intf.put.ptc3 | H14: 2210108 | I14: P1 | L14: 网元正常启动 | M14: 1、使用/api/v1/qosintf接口修改接口带宽时，配置繁忙阈值为20，其他参数为任意有效值,查询接口带宽配置【check1】 2、使用/api/v1/qosintf接口修改接口带宽时，配置繁忙阈值为90，其他参数为任意有效值,查询接口带宽配置【check1】 3、使用/api/v1/qosintf接口修改接口带宽时，配置繁忙阈值为20-90间任意10的整数倍，其他参数为任意有效值,查询接口带宽配置【check1】 4、修改接口带宽时，配置繁忙阈值为10，其他参数为任意有效值,查询接口带宽配置【check2】 5、修改接口带宽时，配置繁忙阈值为100，其他参数为任意有效值,查询接口带宽配置【check2】 6、修改接口带宽时，配置繁忙阈值为繁忙阈值小于空闲阈值，其他参数为任意有效值,查询接口带宽配置【check2】 7、修改接口带宽时，配置繁忙阈值为繁忙阈值等于空闲阈值，其他参数为任意有效值,查询接口带宽配置【check2】 8、修改接口带宽时，配置繁忙阈值为20-90间任意非10的整数倍，其他参数为任意有效值,查询接口带宽配置【check2】 9、修改接口带宽时，配置繁忙阈值为空，其他参数为任意有效值,查询接口带宽配置【check2】 10、修改接口带宽时，配置繁忙阈值为非数字，其他参数为任意有效值,查询接口带宽配置【check2】 | N14: 【check1】配置成功，使用restful查询接口带宽配置与下发的配置相同。使用etcd查询接口带宽配置，查询的值与配置的值相同 【check2】配置失败，网元无异常。使用rest接口和etcd查询接口带宽配置与配置前相同 | O14: NGFW_V60R1C00 | P14: J1900,C236,EP | S14: 接口测试 | T14: 是
F15: 验证修改QOS接口带宽时空闲阈值有效值和无效值测试 | G15: Qos.cfg.intf.put.ptc4 | H15: 2210109 | I15: P1 | L15: 网元正常启动 | M15: 1、使用/api/v1/qosintf接口修改接口带宽时，配置空闲阈值为10，其他参数为任意有效值,查询接口带宽配置【check1】 2、使用/api/v1/qosintf接口修改接口带宽时，配置空闲阈值为80，其他参数为任意有效值,查询接口带宽配置【check1】 3、使用/api/v1/qosintf接口修改接口带宽时，配置空闲阈值为10-80间任意10的整数倍，其他参数为任意有效值,查询接口带宽配置【check1】 4、修改接口带宽时，配置空闲阈值为0，其他参数为任意有效值,查询接口带宽配置【check2】 5、修改接口带宽时，配置空闲阈值为90，其他参数为任意有效值,查询接口带宽配置【check2】 6、修改接口带宽时，配置空闲阈值为空闲阈值大于繁忙阈值，其他参数为任意有效值,查询接口带宽配置【check2】 7、修改接口带宽时，配置空闲阈值为空闲阈值等于于繁忙阈值，其他参数为任意有效值,查询接口带宽配置【check2】 8、修改接口带宽时，配置空闲阈值为10-80间任意非10的整数倍，其他参数为任意有效值,查询接口带宽配置【check2】 9、修改接口带宽时，配置空闲阈值为空，其他参数为任意有效值,查询接口带宽配置【check2】 10、修改接口带宽时，配置空闲阈值为非数字，其他参数为任意有效值,查询接口带宽配置【check2】 | N15: 【check1】配置成功，使用restful查询接口带宽配置与下发的配置相同。使用etcd查询接口带宽配置，查询的值与配置的值相同 【check2】配置失败，网元无异常。使用rest接口和etcd查询接口带宽配置与配置前相同 | O15: NGFW_V60R1C00 | P15: J1900,C236,EP | S15: 接口测试 | T15: 是
F16: 验证Qos接口带宽删除和批量删除 | G16: Qos.cfg.intf.delete.ptc0 | H16: 2210110 | I16: P1 | L16: 1、网元正常启动 | M16: 1、配置大于3条Qos接口带宽。 2、使用/api/v1/qosintf?id=<id>删除接口带宽。【check1】【check2】【check3】 3、使用/api/v1/qosintf?id=<id>删除不存在的接口带宽id。【check4】 4、使用/api/v1/batch接口删除不存在的Qos接口带宽id。【check5】 5、使用/api/v1/batch接口删除部分存在部分不存在的QOS接口带宽【check5】 6、使用/api/v1/batch接口删除大于两条存在QoS接口带宽。【check1】【check2】【check3】 | N16: 【check1】删除成功，Qos接口带宽配置表中配置被删除。 【check2】使用restful查询Qos接口带宽，对应的接口带宽不存在 【check3】使用etcd查询Qos接口带宽，接口带宽被删除 【check4】删除失败，提示信息正确。查询Qos接口带宽表与删除前完全一致（无误删）。 【check5】返回删除失败，其中有效的ID被删除。查看Qos接口带宽配置中不包含在有效ID中的接口带宽不会被删除 | O16: NGFW_V60R1C00 | P16: J1900,C236,EP | S16: 接口测试 | T16: 是
F17: 验证Qos多接口配置功能 | G17: Qos.cfg.intfs.ptc0 | H17: 2210111 | I17: P1 | L17: 1、网元正常启动 | M17: 1、配置大于3条Qos接口带宽。【check1】 2、删除其中一条Qos接口带宽，观察qos配置。【check2】 3、再次增删其他接口，观察Qos配置。【check1】 | N17: 【check1】配置成功，show interface GE2 features查看接口的qos节点正常 【check2】删除的接口QOS节点被删除 | O17: NGFW_V60R1C00 | P17: J1900,C236,EP | S17: 接口测试 | T17: 是
F18: 验证配置Qos接口带宽查询有效值和无效值 | G18: Qos.cfg.intf.get.ptc0 | H18: 2210112 | I18: P1 | L18: 1、网元正常启动 | M18: 1、使用/api/v1/qosintf接口查询Qos接口带宽，不传入page和size参数【check1】 2、使用/api/v1/qosintf接口查询Qos接口带宽，传入page和size为0【check1】 3、使用/api/v1/qosintf接口查询Qos接口带宽，传入page和size为任意非0值【check1】 4、使用/api/v1/qosintf接口查询Qos接口带宽，传入page和size为最大值【check1】 5、使用/api/v1/qosintf接口查询Qos接口带宽，传入page和size为任意非数字【check1】 | N18: 【check1】查询成功 | O18: NGFW_V60R1C00 | P18: J1900,C236,EP | S18: 接口测试 | T18: 是
... F21: 验证Qos接口带宽与bvi接口的配置限制功能 | G21: Qos.cfg.intf.limit.ptc1 | H21: 2210116 | I21: P1 | L21: 网元正常启动 | M21: 1、在设备上配置bvi接口 2、在bvi成员上配置接口带宽【check1】 3、删除bvi接口【check1】 4、增删成员接口【check1】 5、在Bvi口上配置接口带宽【check2】 | N21: 【check1】配置成功，查询qos接口带宽与配置值相同 【check2】配置失败，查询配置不变化 | O21: NGFW_V60R1C00 | P21: J1900,C236,EP | S21: 接口测试 | T21: 是
E22: 通道配置
F23: 验证添加QOS通道时名称有效值和无效值测试 | G23: Qos.cfg.chl.post.ptc0 | H23: 2210201 | I23: P1 | L23: 网元正常启动 | M23: 1、使用/api/v1/qoschannel接口添加Qos通道时，配置名称为1个字符，其他参数为任意有效值,查询通道配置【check1】 2、使用/api/v1/qoschannel接口添加Qos通道时，配置名称为31个字符，其他参数为任意有效值,查询通道配置【check1】 3、使用/api/v1/qoschannel接口添加Qos通道时，配置名称为1-31任意个字符，其他参数为任意有效值,查询通道配置【check1】 4、添加Qos通道时，配置名称为0个字符，其他参数为任意有效值,查询通道配置【check2】 5、添加Qos通道时，配置名称为32个字符，其他参数为任意有效值,查询通道配置【check2】 6、添加Qos通道时，配置名称为空，其他参数为任意有效值,查询通道配置【check2】 6、添加Qos通道时，配置名称为已存在的名称，其他参数为任意有效值,查询通道配置【check2】 | N23: 【check1】配置成功，使用restful查询通道配置与下发的配置相同。使用etcd查询通道配置，查询的值与配置的值相同 【check2】配置失败，网元无异常。使用rest接口和etcd查询通道配置与配置前相同 | O23: NGFW_V60R1C00 | P23: J1900,C236,EP | S23: 接口测试 | T23: 是
F24: 验证添加QOS通道时通道模式有效值和无效值测试 | G24: Qos.cfg.chl.post.ptc1 | H24: 2210202 | I24: P1 | L24: 网元正常启动 | M24: 1、使用/api/v1/qoschannel接口添加Qos通道时，配置通道模式为独享，其他参数为任意有效值,查询通道配置【check1】 2、使用/api/v1/qoschannel接口添加Qos通道时，配置通道模式为共享，其他参数为任意有效值,查询通道配置【check1】 3、添加Qos通道时，配置通道模式为其他任意非法字符串，其他参数为任意有效值,查询通道配置【check2】 4、添加Qos通道时，配置通道模式为空，其他参数为任意有效值,查询通道配置【check2】 5、添加Qos通道时，配置通道模式为超长字符串，其他参数为任意有效值,查询通道配置【check2】 | N24: 【check1】配置成功，使用restful查询通道配置与下发的配置相同。使用etcd查询通道配置，查询的值与配置的值相同 【check2】配置失败，网元无异常。使用rest接口和etcd查询通道配置与配置前相同 | O24: NGFW_V60R1C00 | P24: J1900,C236,EP | S24: 接口测试 | T24: 是
F25: 验证添加QOS通道时上行最大带宽有效值和无效值测试 | G25: Qos.cfg.chl.post.ptc2 | H25: 2210203 | I25: P1 | L25: 网元正常启动 | M25: 1、使用/api/v1/qoschannel接口添加Qos通道时，配置上行最大带宽为0，其他参数为任意有效值,查询通道配置【check1】 2、使用/api/v1/qoschannel接口添加Qos通道时，配置上行最大带宽为60，其他参数为任意有效值,查询通道配置【check1】 3、使用/api/v1/qoschannel接口添加Qos通道时，配置上行最大带宽为200000000，其他参数为任意有效值,查询通道配置【check1】 4、使用/api/v1/qoschannel接口添加Qos通道时，配置上行最大带宽为60-200000000间任意值，其他参数为任意有效值,查询通道配置【check1】 5、使用/api/v1/qoschannel接口添加Qos通道时，配置上行最大带宽为最大带宽等于保障带宽，其他参数为任意有效值,查询通道配置【check1】 6、添加Qos通道时，配置上行最大带宽为1，其他参数为任意有效值,查询通道配置【check2】 7、添加Qos通道时，配置上行最大带宽为-1，其他参数为任意有效值,查询通道配置【check2】 8、添加Qos通道时，配置上行最大带宽为59，其他参数为任意有效值,查询通道配置【check2】 9、添加Qos通道时，配置上行最大带宽为200000001，其他参数为任意有效值,查询通道配置【check2】 10、添加Qos通道时，配置上行最大带宽为上行最大带宽小于上行保障带宽，其他参数为任意有效值,查询通道配置【check2】 11、添加Qos通道时，配置上行最大带宽为非数字，其他参数为任意有效值,查询通道配置【check2】 12、添加Qos通道时，配置上行最大带宽为空，其他参数为任意有效值,查询通道配置【check2】 | N25: 【check1】配置成功，使用restful查询通道配置与下发的配置相同。使用etcd查询通道配置，查询的值与配置的值相同 【check2】配置失败，网元无异常。使用rest接口和etcd查询通道配置与配置前相同 | O25: NGFW_V60R1C00 | P25: J1900,C236,EP | S25: 接口测试 | T25: 是
F26: 验证添加QOS通道时上行保障带宽有效值和无效值测试 | G26: Qos.cfg.chl.post.ptc3 | H26: 2210204 | I26: P1 | L26: 网元正常启动 | M26: 1、使用/api/v1/qoschannel接口添加Qos通道时，配置上行保障带宽为0，其他参数为任意有效值,查询通道配置【check2】 2、使用/api/v1/qoschannel接口添加Qos通道时，配置上行保障带宽为60，其他参数为任意有效值,查询通道配置【check1】 3、使用/api/v1/qoschannel接口添加Qos通道时，配置上行保障带宽为200000000，其他参数为任意有效值,查询通道配置【check1】 4、使用/api/v1/qoschannel接口添加Qos通道时，配置上行保障带宽为60-200000000间任意值，其他参数为任意有效值,查询通道配置【check1】 5、使用/api/v1/qoschannel接口添加Qos通道时，配置上行保障带宽为保障带宽等于最大带宽，其他参数为任意有效值,查询通道配置【check1】 6、添加Qos通道时，配置上行保障带宽为1，其他参数为任意有效值,查询通道配置【check2】 7、添加Qos通道时，配置上行保障带宽为-1，其他参数为任意有效值,查询通道配置【check2】 8、添加Qos通道时，配置上行保障带宽为59，其他参数为任意有效值,查询通道配置【check2】 9、添加Qos通道时，配置上行保障带宽为200000000，其他参数为任意有效值,查询通道配置【check2】 10、添加Qos通道时，配置上行保障带宽为上行保障带宽大于上行最大带宽，其他参数为任意有效值,查询通道配置【check2】 11、添加Qos通道时，配置上行保障带宽为非数字，其他参数为任意有效值,查询通道配置【check2】 12、添加Qos通道时，配置上行保障带宽为空，其他参数为任意有效值,查询通道配置【check2】 | N26: 【check1】配置成功，使用restful查询通道配置与下发的配置相同。使用etcd查询通道配置，查询的值与配置的值相同 【check2】配置失败，网元无异常。使用rest接口和etcd查询通道配置与配置前相同 | O26: NGFW_V60R1C00 | P26: J1900,C236,EP | S26: 接口测试 | T26: 是
F27: 验证添加QOS通道时下行最大带宽有效值和无效值测试 | G27: Qos.cfg.chl.post.ptc4 | H27: 2210205 | I27: P1 | L27: 网元正常启动 | M27: 1、使用/api/v1/qoschannel接口添加Qos通道时，配置下行最大带宽为0，其他参数为任意有效值,查询通道配置【check1】 2、使用/api/v1/qoschannel接口添加Qos通道时，配置下行最大带宽为60，其他参数为任意有效值,查询通道配置【check1】 3、使用/api/v1/qoschannel接口添加Qos通道时，配置下行最大带宽为200000000，其他参数为任意有效值,查询通道配置【check1】 4、使用/api/v1/qoschannel接口添加Qos通道时，配置下行最大带宽为60-200000000间任意值，其他参数为任意有效值,查询通道配置【check1】 5、使用/api/v1/qoschannel接口添加Qos通道时，配置下行最大带宽为最大带宽等于保障带宽，其他参数为任意有效值,查询通道配置【check1】 6、添加Qos通道时，配置下行最大带宽为1，其他参数为任意有效值,查询通道配置【check2】 7、添加Qos通道时，配置下行最大带宽为-1，其他参数为任意有效值,查询通道配置【check2】 8、添加Qos通道时，配置下行最大带宽为59，其他参数为任意有效值,查询通道配置【check2】 9、添加Qos通道时，配置下行最大带宽为200000001，其他参数为任意有效值,查询通道配置【check2】 10、添加Qos通道时，配置下行最大带宽为下行最大带宽小于下行保障带宽，其他参数为任意有效值,查询通道配置【check2】 11、添加Qos通道时，配置下行最大带宽为非数字，其他参数为任意有效值,查询通道配置【check2】 12、添加Qos通道时，配置下行最大带宽为空，其他参数为任意有效值,查询通道配置【check2】 | N27: 【check1】配置成功，使用restful查询通道配置与下发的配置相同。使用etcd查询通道配置，查询的值与配置的值相同 【check2】配置失败，网元无异常。使用rest接口和etcd查询通道配置与配置前相同 | O27: NGFW_V60R1C00 | P27: J1900,C236,EP | S27: 接口测试 | T27: 是
F28: 验证添加QOS通道时下行保障带宽有效值和无效值测试 | G28: Qos.cfg.chl.post.ptc5 | H28: 2210206 | I28: P1 | L28: 网元正常启动 | M28: 1、使用/api/v1/qoschannel接口添加Qos通道时，配置下行保障带宽为0，其他参数为任意有效值,查询通道配置【check2】 2、使用/api/v1/qoschannel接口添加Qos通道时，配置下行保障带宽为60，其他参数为任意有效值,查询通道配置【check1】 3、使用/api/v1/qoschannel接口添加Qos通道时，配置下行保障带宽为200000000，其他参数为任意有效值,查询通道配置【check1】 4、使用/api/v1/qoschannel接口添加Qos通道时，配置下行保障带宽为60-200000000间任意值，其他参数为任意有效值,查询通道配置【check1】 5、使用/api/v1/qoschannel接口添加Qos通道时，配置下行保障带宽为保障带宽等于最大带宽，其他参数为任意有效值,查询通道配置【check1】 6、添加Qos通道时，配置下行保障带宽为1，其他参数为任意有效值,查询通道配置【check2】 7、添加Qos通道时，配置下行保障带宽为-1，其他参数为任意有效值,查询通道配置【check2】 8、添加Qos通道时，配置下行保障带宽为59，其他参数为任意有效值,查询通道配置【check2】 9、添加Qos通道时，配置下行保障带宽为200000001，其他参数为任意有效值,查询通道配置【check2】 10、添加Qos通道时，配置下行保障带宽为下行保障带宽大于下行最大带宽，其他参数为任意有效值,查询通道配置【check2】 11、添加Qos通道时，配置下行保障带宽为非数字，其他参数为任意有效值,查询通道配置【check2】 12、添加Qos通道时，配置下行保障带宽为空，其他参数为任意有效值,查询通道配置【check2】 | N28: 【check1】配置成功，使用restful查询通道配置与下发的配置相同。使用etcd查询通道配置，查询的值与配置的值相同 【check2】配置失败，网元无异常。使用rest接口和etcd查询通道配置与配置前相同 | O28: NGFW_V60R1C00 | P28: J1900,C236,EP | S28: 接口测试 | T28: 是
F29: 验证添加QOS通道时上行总额有效值和无效值测试 | G29: Qos.cfg.chl.post.ptc6 | H29: 2210207 | I29: P1 | L29: 网元正常启动 | M29: 1、使用/api/v1/qoschannel接口添加Qos通道时，配置上行总额为0，其他参数为任意有效值,查询通道配置【check1】 2、使用/api/v1/qoschannel接口添加Qos通道时，配置上行总额为10，其他参数为任意有效值,查询通道配置【check1】 3、使用/api/v1/qoschannel接口添加Qos通道时，配置上行总额为100000000，其他参数为任意有效值,查询通道配置【check1】 4、使用/api/v1/qoschannel接口添加Qos通道时，配置上行总额为10-100000000间任意值，其他参数为任意有效值,查询通道配置【check1】 5、添加Qos通道时，配置上行总额为1，其他参数为任意有效值,查询通道配置【check2】 6、添加Qos通道时，配置上行总额为-1，其他参数为任意有效值,查询通道配置【check2】 7、添加Qos通道时，配置上行总额为9，其他参数为任意有效值,查询通道配置【check2】 8、添加Qos通道时，配置上行总额为100000001，其他参数为任意有效值,查询通道配置【check2】 9、添加Qos通道时，配置上行总额为非数字，其他参数为任意有效值,查询通道配置【check2】 10、添加Qos通道时，配置上行总额为空，其他参数为任意有效值,查询通道配置【check2】 | N29: 【check1】配置成功，使用restful查询通道配置与下发的配置相同。使用etcd查询通道配置，查询的值与配置的值相同 【check2】配置失败，网元无异常。使用rest接口和etcd查询通道配置与配置前相同 | O29: NGFW_V60R1C00 | P29: J1900,C236,EP | S29: 接口测试 | T29: 是
F30: 验证添加QOS通道时下行总额有效值和无效值测试 | G30: Qos.cfg.chl.post.ptc7 | H30: 2210208 | I30: P1 | L30: 网元正常启动 | M30: 1、使用/api/v1/qoschannel接口添加Qos通道时，配置下行总额为0，其他参数为任意有效值,查询通道配置【check1】 2、使用/api/v1/qoschannel接口添加Qos通道时，配置下行总额为10，其他参数为任意有效值,查询通道配置【check1】 3、使用/api/v1/qoschannel接口添加Qos通道时，配置下行总额为100000000，其他参数为任意有效值,查询通道配置【check1】 4、使用/api/v1/qoschannel接口添加Qos通道时，配置下行总额为10-100000000间任意值，其他参数为任意有效值,查询通道配置【check1】 5、添加Qos通道时，配置下行总额为1，其他参数为任意有效值,查询通道配置【check2】 6、添加Qos通道时，配置下行总额为-1，其他参数为任意有效值,查询通道配置【check2】 7、添加Qos通道时，配置下行总额为9，其他参数为任意有效值,查询通道配置【check2】 8、添加Qos通道时，配置下行总额为100000001，其他参数为任意有效值,查询通道配置【check2】 9、添加Qos通道时，配置下行总额为非数字，其他参数为任意有效值,查询通道配置【check2】 10、添加Qos通道时，配置下行总额为空，其他参数为任意有效值,查询通道配置【check2】 | N30: 【check1】配置成功，使用restful查询通道配置与下发的配置相同。使用etcd查询通道配置，查询的值与配置的值相同 【check2】配置失败，网元无异常。使用rest接口和etcd查询通道配置与配置前相同 | O30: NGFW_V60R1C00 | P30: J1900,C236,EP | S30: 接口测试 | T30: 是
F31: 验证添加QOS通道时最大连接数有效值和无效值测试 | G31: Qos.cfg.chl.post.ptc8 | H31: 2210209 | I31: P1 | L31: 网元正常启动 | M31: 1、使用/api/v1/qoschannel接口添加Qos通道时，配置最大连接数为0，其他参数为任意有效值,查询通道配置【check1】 2、使用/api/v1/qoschannel接口添加Qos通道时，配置最大连接数为1，其他参数为任意有效值,查询通道配置【check1】 3、使用/api/v1/qoschannel接口添加Qos通道时，配置最大连接数为6000000 ，其他参数为任意有效值,查询通道配置【check1】 4、使用/api/v1/qoschannel接口添加Qos通道时，配置最大连接数为1-6000000间任意值，其他参数为任意有效值,查询通道配置【check1】 5、添加Qos通道时，配置最大连接数为-1，其他参数为任意有效值,查询通道配置【check2】 6、添加Qos通道时，配置最大连接数为6000001，其他参数为任意有效值,查询通道配置【check2】 7、添加Qos通道时，配置最大连接数为非数字，其他参数为任意有效值,查询通道配置【check2】 8、添加Qos通道时，配置最大连接数为空，其他参数为任意有效值,查询通道配置【check2】 | N31: 【check1】配置成功，使用restful查询通道配置与下发的配置相同。使用etcd查询通道配置，查询的值与配置的值相同 【check2】配置失败，网元无异常。使用rest接口和etcd查询通道配置与配置前相同 | O31: NGFW_V60R1C00 | P31: J1900,C236,EP | S31: 接口测试 | T31: 是
F32: 验证添加QOS通道时新建连接速率有效值和无效值测试 | G32: Qos.cfg.chl.post.ptc9 | H32: 2210210 | I32: P1 | L32: 网元正常启动 | M32: 1、使用/api/v1/qoschannel接口添加Qos通道时，配置新建连接速率为0，其他参数为任意有效值,查询通道配置【check1】 2、使用/api/v1/qoschannel接口添加Qos通道时，配置新建连接速率为1，其他参数为任意有效值,查询通道配置【check1】 3、使用/api/v1/qoschannel接口添加Qos通道时，配置新建连接速率为500000，其他参数为任意有效值,查询通道配置【check1】 4、使用/api/v1/qoschannel接口添加Qos通道时，配置新建连接速率为1-500000间任意值，其他参数为任意有效值,查询通道配置【check1】 5、添加Qos通道时，配置新建连接速率为-1，其他参数为任意有效值,查询通道配置【check2】 6、添加Qos通道时，配置新建连接速率为500001，其他参数为任意有效值,查询通道配置【check2】 7、添加Qos通道时，配置新建连接速率为非数字，其他参数为任意有效值,查询通道配置【check2】 8、添加Qos通道时，配置新建连接速率为空，其他参数为任意有效值,查询通道配置【check2】 | N32: 【check1】配置成功，使用restful查询通道配置与下发的配置相同。使用etcd查询通道配置，查询的值与配置的值相同 【check2】配置失败，网元无异常。使用rest接口和etcd查询通道配置与配置前相同 | O32: NGFW_V60R1C00 | P32: J1900,C236,EP | S32: 接口测试 | T32: 是
F33: 验证添加QOS通道时限流对象有效值和无效值测试 | G33: Qos.cfg.chl.post.ptc10 | H33: 2210211 | I33: P1 | L33: 网元正常启动 | M33: 1、使用/api/v1/qoschannel接口添加Qos通道时，配置限流对象为每IP，其他参数为任意有效值,查询通道配置【check1】 2、使用/api/v1/qoschannel接口添加Qos通道时，配置限流对象为每用户，其他参数为任意有效值,查询通道配置【check1】 3、添加Qos通道时，配置限流对象为其他任意非法字符串，其他参数为任意有效值,查询通道配置【check2】 4、添加Qos通道时，配置限流对象为空，其他参数为任意有效值,查询通道配置【check2】 5、添加Qos通道时，配置限流对象为超长字符串，其他参数为任意有效值,查询通道配置【check2】 | N33: 【check1】配置成功，使用restful查询通道配置与下发的配置相同。使用etcd查询通道配置，查询的值与配置的值相同 【check2】配置失败，网元无异常。使用rest接口和etcd查询通道配置与配置前相同 | O33: NGFW_V60R1C00 | P33: J1900,C236,EP | S33: 接口测试 | T33: 是
F34: 验证添加QOS通道时用户上行最大带宽有效值和无效值测试 | G34: Qos.cfg.chl.post.ptc11 | H34: 2210212 | I34: P1 | L34: 网元正常启动 | M34: 1、使用/api/v1/qoschannel接口添加Qos通道时，配置用户上行最大带宽为0，其他参数为任意有效值,查询通道配置【check1】 2、使用/api/v1/qoschannel接口添加Qos通道时，配置用户上行最大带宽为60，其他参数为任意有效值,查询通道配置【check1】 3、使用/api/v1/qoschannel接口添加Qos通道时，配置用户上行最大带宽为200000000，其他参数为任意有效值,查询通道配置【check1】 4、使用/api/v1/qoschannel接口添加Qos通道时，配置用户上行最大带宽为60-200000000间任意值，其他参数为任意有效值,查询通道配置【check1】 5、使用/api/v1/qoschannel接口添加Qos通道时，配置用户上行最大带宽为用户最大带宽等于用户保障带宽，其他参数为任意有效值,查询通道配置【check1】 6、添加Qos通道时，配置用户上行最大带宽为1，其他参数为任意有效值,查询通道配置【check2】 7、添加Qos通道时，配置用户上行最大带宽为-1，其他参数为任意有效值,查询通道配置【check2】 8、添加Qos通道时，配置用户上行最大带宽为59，其他参数为任意有效值,查询通道配置【check2】 9、添加Qos通道时，配置用户上行最大带宽为200000001，其他参数为任意有效值,查询通道配置【check2】 10、添加Qos通道时，配置用户上行最大带宽为用户上行最大带宽小于用户上行保障带宽，其他参数为任意有效值,查询通道配置【check2】 11、添加Qos通道时，配置用户上行最大带宽为非数字，其他参数为任意有效值,查询通道配置【check2】 12、添加Qos通道时，配置用户上行最大带宽为用户上行最大带宽大于通道上行最大带宽，其他参数为任意有效值,查询通道配置【check2】 13、添加Qos通道时，配置用户上行最大带宽为空，其他参数为任意有效值,查询通道配置【check2】 | N34: 【check1】配置成功，使用restful查询通道配置与下发的配置相同。使用etcd查询通道配置，查询的值与配置的值相同 【check2】配置失败，网元无异常。使用rest接口和etcd查询通道配置与配置前相同 | O34: NGFW_V60R1C00 | P34: J1900,C236,EP | S34: 接口测试 | T34: 是
... F66: 验证配置Qos独占通道配置限制测试 | G66: Qos.cfg.chl.private.limit.ptc0 | H66: 2210245 | I66: P1 | L66: 1、网元正常启动 | M66: 1、配置的Qos通道，通道类型未独占通道【check1】 2、配置1条Qos策略引用该通道【check2】 3、再配置一跳Qos策略引用该通道。【check3】 4、修改通道配置。【check3】 5、删除该通道。【check3】 6、取消Qos策略应用通道后，修改该通道。【check2】 7、删除该通道。【check2】 | N66: 【check1】配置成功，查询配置参与与实际配置参数一致。 【check2】配置成功 【check3】配置失败 | O66: NGFW_V60R1C00 | P66: J1900,C236,EP | S66: 接口测试 | T66: 是
E67: IPv4策略配置
F68: 验证添加IPv4带宽策略时状态有效值和无效值测试 | G68: Qos.cfg.policy.post.ptc0 | H68: 2210301 | I68: P1 | L68: 网元正常启动 | M68: 1、使用/api/v1/qospolicer接口添加IPv4带宽策略时，配置状态为启用，其他参数为任意有效值,查询IPv4带宽策略配置【check1】 2、使用/api/v1/qospolicer接口添加IPv4带宽策略时，配置状态为禁用，其他参数为任意有效值,查询IPv4带宽策略配置【check1】 3、添加IPv4带宽策略时，配置状态为其他任意非法字符串，其他参数为任意有效值,查询IPv4带宽策略配置【check2】 4、添加IPv4带宽策略时，配置状态为空，其他参数为任意有效值,查询IPv4带宽策略配置【check2】 5、添加IPv4带宽策略时，配置状态为超长字符串，其他参数为任意有效值,查询IPv4带宽策略配置【check2】 | N68: 【check1】配置成功，使用restful查询带宽策略配置与下发的配置相同。使用etcd查询带宽策略配置，查询的值与配置的值相同 【check2】配置失败，网元无异常。使用etcd查询带宽策略配置与配置前相同 | O68: NGFW_V60R1C00 | P68: J1900,C236,EP | S68: 接口测试 | T68: 是
F69: 验证添加IPv4带宽策略时策略名称有效值和无效值测试 | G69: Qos.cfg.policy.post.ptc1 | H69: 2210302 | I69: P1 | L69: 网元正常启动 | M69: 1、使用/api/v1/qospolicer接口添加IPv4QOSIPv4带宽策略时，配置名称为1个字符，其他参数为任意有效值,查询通道配置【check1】 2、添加IPv4带宽策略时，配置名称为31个字符，其他参数为任意有效值,查询通道配置【check1】 3、添加IPv4带宽策略时，配置名称为1-31任意个字符，其他参数为任意有效值,查询通道配置【check1】 4、添加IPv4带宽策略时，配置名称为0个字符，其他参数为任意有效值,查询通道配置【check2】 5、添加IPv4带宽策略时，配置名称为32个字符，其他参数为任意有效值,查询通道配置【check2】 6、添加IPv4带宽策略时，配置名称为空，其他参数为任意有效值,查询通道配置【check2】 6、添加IPv4带宽策略时，配置名称为已存在的策略名称，其他参数为任意有效值,查询通道配置【check2】 | N69: 【check1】配置成功，使用restful查询带宽策略配置与下发的配置相同。使用etcd查询带宽策略配置，查询的值与配置的值相同 【check2】配置失败，网元无异常。使用etcd查询带宽策略配置与配置前相同 | O69: NGFW_V60R1C00 | P69: J1900,C236,EP | S69: 接口测试 | T69: 是
F70: 验证添加IPv4带宽策略时上行接口有效值和无效值测试 | G70: Qos.cfg.policy.post.ptc2 | H70: 2210303 | I70: P1 | L70: 网元正常启动 | M70: 1、使用/api/v1/qospolicer接口添加IPv4带宽策略时，配置上行接口为任意物理接口，其他参数为任意有效值,查询IPv4带宽策略配置【check1】 2、使用/api/v1/qospolicer接口添加IPv4带宽策略时，配置上行接口为任意聚合口，其他参数为任意有效值,查询IPv4带宽策略配置【check1】 3、使用/api/v1/qospolicer接口添加IPv4带宽策略时，配置上行接口为上行接口与下行接口相同，其他参数为任意有效值,查询IPv4带宽策略配置【check1】 4、添加IPv4带宽策略时，配置上行接口为管理口，其他参数为任意有效值,查询IPv4带宽策略配置【check2】 5、添加IPv4带宽策略时，配置上行接口为子接口，其他参数为任意有效值,查询IPv4带宽策略配置【check2】 6、添加IPv4带宽策略时，配置上行接口为bvi口，其他参数为任意有效值,查询IPv4带宽策略配置【check2】 7、添加IPv4带宽策略时，配置上行接口为隧道口，其他参数为任意有效值,查询IPv4带宽策略配置【check2】 8、添加IPv4带宽策略时，配置上行接口为聚合口的成员口，其他参数为任意有效值,查询IPv4带宽策略配置【check2】 9、添加IPv4带宽策略时，配置上行接口为任意不存在的接口名称，其他参数为任意有效值,查询IPv4带宽策略配置【check2】 10、添加IPv4带宽策略时，配置上行接口为空，其他参数为任意有效值,查询IPv4带宽策略配置【check2】 | N70: 【check1】配置成功，使用restful查询带宽策略配置与下发的配置相同。使用etcd查询带宽策略配置，查询的值与配置的值相同 【check2】配置失败，网元无异常。使用etcd查询带宽策略配置与配置前相同 | O70: NGFW_V60R1C00 | P70: J1900,C236,EP | S70: 接口测试 | T70: 是
